Workbook

Sheet Workbook Guide
A1: Circularo Internal Price Book — Workbook Guide
A2: Start here. This workbook is an internal pricing governance tool generated from the unified variant-level pricing book.
A4: Audience | B4: Commercial Operations, Finance, Sales leadership, and approved AI agents using the internal partner pricing model.
A5: Primary source | B5: SKU-level rows, Odoo costs, and maintained floor prices are imported from catalog/unified-catalog/unified-pricing-book.csv.
A6: Important caution | B6: Partner buy prices, commercial floors, approval thresholds, and price-realization KPIs are internal only. Do not send this workbook to customers or partners unless an approved external version is created.
A7: How to navigate | B7: Use the linked sheet directory below. Start with MSRP Catalog for imported list prices, Price Book for governance controls, Partner Buy Price Matrix for tier prices, and Price Realization for Finance KPIs.
A10: Sheet | B10: Purpose | C10: Use this when | D10: Open
A11: Price Book | B11: Master SKU-level pricing and governance controls. | C11: Review standard partner buy price, floor controls, approvals, status, and notes. | D11: Open sheet
A12: Definitions | B12: Data dictionary for workbook fields. | C12: Understand what each term means and who owns it. | D12: Open sheet
A13: Formulas | B13: Formula reference for calculations. | C13: Audit pricing and price-realization logic. | D13: Open sheet
A14: Partner Tiers | B14: Partner tier settings and plan permissions. | C14: Confirm Authorized, Advanced, and Strategic partner margin ceilings. | D14: Open sheet
A15: Special Pricing Matrix | B15: Special-pricing treatment by customer discount band. | C15: Check when special pricing or escalation is required. | D15: Open sheet
A16: MSRP Catalog | B16: Imported Odoo SKU catalog and MSRP source inputs. | C16: Validate list prices, currency, status, effective dates, and imported notes. | D16: Open sheet
A17: Partner Buy Price Matrix | B17: Tier-specific partner buy prices generated from the master Price Book. | C17: Quote internal buy prices by partner tier. | D17: Open sheet
A18: Discount Approval Matrix | B18: Customer discount approval governance. | C18: Check approval level and deal-registration requirements. | D18: Open sheet
A19: Price Book History | B19: Version, approval, and change-history log. | C19: Track workbook releases and approvals. | D19: Open sheet
A20: Price Realization | B20: Circularo Price Realization KPI view. | C20: Review row-level and weighted Partner Buy Price ÷ MSRP metrics. | D20: Open sheet

Sheet Price Book
A1: Circularo Internal Price Book
A2: One master row per SKU. Green formulas link to another worksheet; blue/yellow cells are editable inputs; black cells are calculations.
A4: Price Book Version | B4: SKU | C4: Product | D4: Plan | E4: Product Family | F4: Unit | G4: Price Basis | H4: Pack Quantity | I4: MSRP | J4: Target Customer Discount | K4: Target Customer Sell Price | L4: Standard Partner Buy Price | M4: Commercial Floor Price | N4: Customer Sell Price Approval Threshold | O4: Max Customer Discount | P4: Target Realized Partner Margin | Q4: Standard Circularo Price Realization | R4: Floor Circularo Price Realization | S4: Standard Approval | T4: Floor Approval | U4: Below Floor | V4: Above Discount Authority | W4: Above Partner Margin Ceiling | X4: Low Price Realization | Y4: Independent Partner Quote | Z4: Ultimate Independent Quote | AA4: Special Pricing Applied | AB4: Deal Registration ID | AC4: Special Pricing Without Deal Registration | AD4: Effective To | AE4: Expired Price Book Version | AF4: Status | AG4: Notes
A5: ='MSRP Catalog'!A5 | B5: ='MSRP Catalog'!B5 | C5: ='MSRP Catalog'!C5 | D5: ='MSRP Catalog'!D5 | E5: ='MSRP Catalog'!E5 | F5: ='MSRP Catalog'!F5 | G5: ='MSRP Catalog'!G5 | H5: ='MSRP Catalog'!H5 | I5: ='MSRP Catalog'!I5 | J5: 0.1 | K5: =IFERROR(I5*(1-J5),"") | L5: =IFERROR(K5*(1-P5),"") | N5: =IFERROR(I5*(1-O5),"") | O5: 0.35 | P5: 0.2 | Q5: =IFERROR(L5/I5,"") | R5: =IF(OR(M5="",I5=0),"",M5/I5) | S5: Automatic | T5: CSO | U5: =IF(M5="","REVIEW",IF(L5<M5,"BLOCK","OK")) | V5: =IF(J5>O5,"BLOCK","OK") | W5: =IF(P5>IF(D5="Start",10%,IF(D5="Pro",15%,IF(OR(D5="Business",D5="Enterprise"),20%,30%))),"BLOCK","OK") | X5: =IF(OR(M5="",R5=""),"REVIEW",IF(Q5<R5,"BLOCK","OK")) | Y5: No | Z5: =IF(AND(D5="Ultimate",Y5="Yes"),"BLOCK","OK") | AA5: No | AC5: =IF(AND(AA5="Yes",AB5=""),"BLOCK","OK") | AD5: ='MSRP Catalog'!M5 | AE5: =IF(AD5="","REVIEW",IF(AD5<TODAY(),"BLOCK","OK")) | AF5: ='MSRP Catalog'!K5 | AG5: ='MSRP Catalog'!N5
A6: ='MSRP Catalog'!A6 | B6: ='MSRP Catalog'!B6 | C6: ='MSRP Catalog'!C6 | D6: ='MSRP Catalog'!D6 | E6: ='MSRP Catalog'!E6 | F6: ='MSRP Catalog'!F6 | G6: ='MSRP Catalog'!G6 | H6: ='MSRP Catalog'!H6 | I6: ='MSRP Catalog'!I6 | J6: 0.1 | K6: =IFERROR(I6*(1-J6),"") | L6: =IFERROR(K6*(1-P6),"") | N6: =IFERROR(I6*(1-O6),"") | O6: 0.35 | P6: 0.2 | Q6: =IFERROR(L6/I6,"") | R6: =IF(OR(M6="",I6=0),"",M6/I6) | S6: Automatic | T6: CSO | U6: =IF(M6="","REVIEW",IF(L6<M6,"BLOCK","OK")) | V6: =IF(J6>O6,"BLOCK","OK") | W6: =IF(P6>IF(D6="Start",10%,IF(D6="Pro",15%,IF(OR(D6="Business",D6="Enterprise"),20%,30%))),"BLOCK","OK") | X6: =IF(OR(M6="",R6=""),"REVIEW",IF(Q6<R6,"BLOCK","OK")) | Y6: No | Z6: =IF(AND(D6="Ultimate",Y6="Yes"),"BLOCK","OK") | AA6: No | AC6: =IF(AND(AA6="Yes",AB6=""),"BLOCK","OK") | AD6: ='MSRP Catalog'!M6 | AE6: =IF(AD6="","REVIEW",IF(AD6<TODAY(),"BLOCK","OK")) | AF6: ='MSRP Catalog'!K6 | AG6: ='MSRP Catalog'!N6
A7: ='MSRP Catalog'!A7 | B7: ='MSRP Catalog'!B7 | C7: ='MSRP Catalog'!C7 | D7: ='MSRP Catalog'!D7 | E7: ='MSRP Catalog'!E7 | F7: ='MSRP Catalog'!F7 | G7: ='MSRP Catalog'!G7 | H7: ='MSRP Catalog'!H7 | I7: ='MSRP Catalog'!I7 | J7: 0.1 | K7: =IFERROR(I7*(1-J7),"") | L7: =IFERROR(K7*(1-P7),"") | N7: =IFERROR(I7*(1-O7),"") | O7: 0.35 | P7: 0.2 | Q7: =IFERROR(L7/I7,"") | R7: =IF(OR(M7="",I7=0),"",M7/I7) | S7: Automatic | T7: CSO | U7: =IF(M7="","REVIEW",IF(L7<M7,"BLOCK","OK")) | V7: =IF(J7>O7,"BLOCK","OK") | W7: =IF(P7>IF(D7="Start",10%,IF(D7="Pro",15%,IF(OR(D7="Business",D7="Enterprise"),20%,30%))),"BLOCK","OK") | X7: =IF(OR(M7="",R7=""),"REVIEW",IF(Q7<R7,"BLOCK","OK")) | Y7: No | Z7: =IF(AND(D7="Ultimate",Y7="Yes"),"BLOCK","OK") | AA7: No | AC7: =IF(AND(AA7="Yes",AB7=""),"BLOCK","OK") | AD7: ='MSRP Catalog'!M7 | AE7: =IF(AD7="","REVIEW",IF(AD7<TODAY(),"BLOCK","OK")) | AF7: ='MSRP Catalog'!K7 | AG7: ='MSRP Catalog'!N7
A8: ='MSRP Catalog'!A8 | B8: ='MSRP Catalog'!B8 | C8: ='MSRP Catalog'!C8 | D8: ='MSRP Catalog'!D8 | E8: ='MSRP Catalog'!E8 | F8: ='MSRP Catalog'!F8 | G8: ='MSRP Catalog'!G8 | H8: ='MSRP Catalog'!H8 | I8: ='MSRP Catalog'!I8 | J8: 0.1 | K8: =IFERROR(I8*(1-J8),"") | L8: =IFERROR(K8*(1-P8),"") | N8: =IFERROR(I8*(1-O8),"") | O8: 0.35 | P8: 0.2 | Q8: =IFERROR(L8/I8,"") | R8: =IF(OR(M8="",I8=0),"",M8/I8) | S8: Automatic | T8: CSO | U8: =IF(M8="","REVIEW",IF(L8<M8,"BLOCK","OK")) | V8: =IF(J8>O8,"BLOCK","OK") | W8: =IF(P8>IF(D8="Start",10%,IF(D8="Pro",15%,IF(OR(D8="Business",D8="Enterprise"),20%,30%))),"BLOCK","OK") | X8: =IF(OR(M8="",R8=""),"REVIEW",IF(Q8<R8,"BLOCK","OK")) | Y8: No | Z8: =IF(AND(D8="Ultimate",Y8="Yes"),"BLOCK","OK") | AA8: No | AC8: =IF(AND(AA8="Yes",AB8=""),"BLOCK","OK") | AD8: ='MSRP Catalog'!M8 | AE8: =IF(AD8="","REVIEW",IF(AD8<TODAY(),"BLOCK","OK")) | AF8: ='MSRP Catalog'!K8 | AG8: ='MSRP Catalog'!N8
A9: ='MSRP Catalog'!A9 | B9: ='MSRP Catalog'!B9 | C9: ='MSRP Catalog'!C9 | D9: ='MSRP Catalog'!D9 | E9: ='MSRP Catalog'!E9 | F9: ='MSRP Catalog'!F9 | G9: ='MSRP Catalog'!G9 | H9: ='MSRP Catalog'!H9 | I9: ='MSRP Catalog'!I9 | J9: 0.1 | K9: =IFERROR(I9*(1-J9),"") | L9: =IFERROR(K9*(1-P9),"") | N9: =IFERROR(I9*(1-O9),"") | O9: 0.35 | P9: 0.2 | Q9: =IFERROR(L9/I9,"") | R9: =IF(OR(M9="",I9=0),"",M9/I9) | S9: Automatic | T9: CSO | U9: =IF(M9="","REVIEW",IF(L9<M9,"BLOCK","OK")) | V9: =IF(J9>O9,"BLOCK","OK") | W9: =IF(P9>IF(D9="Start",10%,IF(D9="Pro",15%,IF(OR(D9="Business",D9="Enterprise"),20%,30%))),"BLOCK","OK") | X9: =IF(OR(M9="",R9=""),"REVIEW",IF(Q9<R9,"BLOCK","OK")) | Y9: No | Z9: =IF(AND(D9="Ultimate",Y9="Yes"),"BLOCK","OK") | AA9: No | AC9: =IF(AND(AA9="Yes",AB9=""),"BLOCK","OK") | AD9: ='MSRP Catalog'!M9 | AE9: =IF(AD9="","REVIEW",IF(AD9<TODAY(),"BLOCK","OK")) | AF9: ='MSRP Catalog'!K9 | AG9: ='MSRP Catalog'!N9
A10: ='MSRP Catalog'!A10 | B10: ='MSRP Catalog'!B10 | C10: ='MSRP Catalog'!C10 | D10: ='MSRP Catalog'!D10 | E10: ='MSRP Catalog'!E10 | F10: ='MSRP Catalog'!F10 | G10: ='MSRP Catalog'!G10 | H10: ='MSRP Catalog'!H10 | I10: ='MSRP Catalog'!I10 | J10: 0.1 | K10: =IFERROR(I10*(1-J10),"") | L10: =IFERROR(K10*(1-P10),"") | N10: =IFERROR(I10*(1-O10),"") | O10: 0.35 | P10: 0.2 | Q10: =IFERROR(L10/I10,"") | R10: =IF(OR(M10="",I10=0),"",M10/I10) | S10: Automatic | T10: CSO | U10: =IF(M10="","REVIEW",IF(L10<M10,"BLOCK","OK")) | V10: =IF(J10>O10,"BLOCK","OK") | W10: =IF(P10>IF(D10="Start",10%,IF(D10="Pro",15%,IF(OR(D10="Business",D10="Enterprise"),20%,30%))),"BLOCK","OK") | X10: =IF(OR(M10="",R10=""),"REVIEW",IF(Q10<R10,"BLOCK","OK")) | Y10: No | Z10: =IF(AND(D10="Ultimate",Y10="Yes"),"BLOCK","OK") | AA10: No | AC10: =IF(AND(AA10="Yes",AB10=""),"BLOCK","OK") | AD10: ='MSRP Catalog'!M10 | AE10: =IF(AD10="","REVIEW",IF(AD10<TODAY(),"BLOCK","OK")) | AF10: ='MSRP Catalog'!K10 | AG10: ='MSRP Catalog'!N10
A11: ='MSRP Catalog'!A11 | B11: ='MSRP Catalog'!B11 | C11: ='MSRP Catalog'!C11 | D11: ='MSRP Catalog'!D11 | E11: ='MSRP Catalog'!E11 | F11: ='MSRP Catalog'!F11 | G11: ='MSRP Catalog'!G11 | H11: ='MSRP Catalog'!H11 | I11: ='MSRP Catalog'!I11 | J11: 0.1 | K11: =IFERROR(I11*(1-J11),"") | L11: =IFERROR(K11*(1-P11),"") | N11: =IFERROR(I11*(1-O11),"") | O11: 0.35 | P11: 0.2 | Q11: =IFERROR(L11/I11,"") | R11: =IF(OR(M11="",I11=0),"",M11/I11) | S11: Automatic | T11: CSO | U11: =IF(M11="","REVIEW",IF(L11<M11,"BLOCK","OK")) | V11: =IF(J11>O11,"BLOCK","OK") | W11: =IF(P11>IF(D11="Start",10%,IF(D11="Pro",15%,IF(OR(D11="Business",D11="Enterprise"),20%,30%))),"BLOCK","OK") | X11: =IF(OR(M11="",R11=""),"REVIEW",IF(Q11<R11,"BLOCK","OK")) | Y11: No | Z11: =IF(AND(D11="Ultimate",Y11="Yes"),"BLOCK","OK") | AA11: No | AC11: =IF(AND(AA11="Yes",AB11=""),"BLOCK","OK") | AD11: ='MSRP Catalog'!M11 | AE11: =IF(AD11="","REVIEW",IF(AD11<TODAY(),"BLOCK","OK")) | AF11: ='MSRP Catalog'!K11 | AG11: ='MSRP Catalog'!N11
A12: ='MSRP Catalog'!A12 | B12: ='MSRP Catalog'!B12 | C12: ='MSRP Catalog'!C12 | D12: ='MSRP Catalog'!D12 | E12: ='MSRP Catalog'!E12 | F12: ='MSRP Catalog'!F12 | G12: ='MSRP Catalog'!G12 | H12: ='MSRP Catalog'!H12 | I12: ='MSRP Catalog'!I12 | J12: 0.1 | K12: =IFERROR(I12*(1-J12),"") | L12: =IFERROR(K12*(1-P12),"") | N12: =IFERROR(I12*(1-O12),"") | O12: 0.35 | P12: 0.2 | Q12: =IFERROR(L12/I12,"") | R12: =IF(OR(M12="",I12=0),"",M12/I12) | S12: Automatic | T12: CSO | U12: =IF(M12="","REVIEW",IF(L12<M12,"BLOCK","OK")) | V12: =IF(J12>O12,"BLOCK","OK") | W12: =IF(P12>IF(D12="Start",10%,IF(D12="Pro",15%,IF(OR(D12="Business",D12="Enterprise"),20%,30%))),"BLOCK","OK") | X12: =IF(OR(M12="",R12=""),"REVIEW",IF(Q12<R12,"BLOCK","OK")) | Y12: No | Z12: =IF(AND(D12="Ultimate",Y12="Yes"),"BLOCK","OK") | AA12: No | AC12: =IF(AND(AA12="Yes",AB12=""),"BLOCK","OK") | AD12: ='MSRP Catalog'!M12 | AE12: =IF(AD12="","REVIEW",IF(AD12<TODAY(),"BLOCK","OK")) | AF12: ='MSRP Catalog'!K12 | AG12: ='MSRP Catalog'!N12
A13: ='MSRP Catalog'!A13 | B13: ='MSRP Catalog'!B13 | C13: ='MSRP Catalog'!C13 | D13: ='MSRP Catalog'!D13 | E13: ='MSRP Catalog'!E13 | F13: ='MSRP Catalog'!F13 | G13: ='MSRP Catalog'!G13 | H13: ='MSRP Catalog'!H13 | I13: ='MSRP Catalog'!I13 | J13: 0.1 | K13: =IFERROR(I13*(1-J13),"") | L13: =IFERROR(K13*(1-P13),"") | N13: =IFERROR(I13*(1-O13),"") | O13: 0.35 | P13: 0.2 | Q13: =IFERROR(L13/I13,"") | R13: =IF(OR(M13="",I13=0),"",M13/I13) | S13: Automatic | T13: CSO | U13: =IF(M13="","REVIEW",IF(L13<M13,"BLOCK","OK")) | V13: =IF(J13>O13,"BLOCK","OK") | W13: =IF(P13>IF(D13="Start",10%,IF(D13="Pro",15%,IF(OR(D13="Business",D13="Enterprise"),20%,30%))),"BLOCK","OK") | X13: =IF(OR(M13="",R13=""),"REVIEW",IF(Q13<R13,"BLOCK","OK")) | Y13: No | Z13: =IF(AND(D13="Ultimate",Y13="Yes"),"BLOCK","OK") | AA13: No | AC13: =IF(AND(AA13="Yes",AB13=""),"BLOCK","OK") | AD13: ='MSRP Catalog'!M13 | AE13: =IF(AD13="","REVIEW",IF(AD13<TODAY(),"BLOCK","OK")) | AF13: ='MSRP Catalog'!K13 | AG13: ='MSRP Catalog'!N13
A14: ='MSRP Catalog'!A14 | B14: ='MSRP Catalog'!B14 | C14: ='MSRP Catalog'!C14 | D14: ='MSRP Catalog'!D14 | E14: ='MSRP Catalog'!E14 | F14: ='MSRP Catalog'!F14 | G14: ='MSRP Catalog'!G14 | H14: ='MSRP Catalog'!H14 | I14: ='MSRP Catalog'!I14 | J14: 0.1 | K14: =IFERROR(I14*(1-J14),"") | L14: =IFERROR(K14*(1-P14),"") | N14: =IFERROR(I14*(1-O14),"") | O14: 0.35 | P14: 0.2 | Q14: =IFERROR(L14/I14,"") | R14: =IF(OR(M14="",I14=0),"",M14/I14) | S14: Automatic | T14: CSO | U14: =IF(M14="","REVIEW",IF(L14<M14,"BLOCK","OK")) | V14: =IF(J14>O14,"BLOCK","OK") | W14: =IF(P14>IF(D14="Start",10%,IF(D14="Pro",15%,IF(OR(D14="Business",D14="Enterprise"),20%,30%))),"BLOCK","OK") | X14: =IF(OR(M14="",R14=""),"REVIEW",IF(Q14<R14,"BLOCK","OK")) | Y14: No | Z14: =IF(AND(D14="Ultimate",Y14="Yes"),"BLOCK","OK") | AA14: No | AC14: =IF(AND(AA14="Yes",AB14=""),"BLOCK","OK") | AD14: ='MSRP Catalog'!M14 | AE14: =IF(AD14="","REVIEW",IF(AD14<TODAY(),"BLOCK","OK")) | AF14: ='MSRP Catalog'!K14 | AG14: ='MSRP Catalog'!N14
A15: ='MSRP Catalog'!A15 | B15: ='MSRP Catalog'!B15 | C15: ='MSRP Catalog'!C15 | D15: ='MSRP Catalog'!D15 | E15: ='MSRP Catalog'!E15 | F15: ='MSRP Catalog'!F15 | G15: ='MSRP Catalog'!G15 | H15: ='MSRP Catalog'!H15 | I15: ='MSRP Catalog'!I15 | J15: 0.1 | K15: =IFERROR(I15*(1-J15),"") | L15: =IFERROR(K15*(1-P15),"") | N15: =IFERROR(I15*(1-O15),"") | O15: 0.35 | P15: 0.2 | Q15: =IFERROR(L15/I15,"") | R15: =IF(OR(M15="",I15=0),"",M15/I15) | S15: Automatic | T15: CSO | U15: =IF(M15="","REVIEW",IF(L15<M15,"BLOCK","OK")) | V15: =IF(J15>O15,"BLOCK","OK") | W15: =IF(P15>IF(D15="Start",10%,IF(D15="Pro",15%,IF(OR(D15="Business",D15="Enterprise"),20%,30%))),"BLOCK","OK") | X15: =IF(OR(M15="",R15=""),"REVIEW",IF(Q15<R15,"BLOCK","OK")) | Y15: No | Z15: =IF(AND(D15="Ultimate",Y15="Yes"),"BLOCK","OK") | AA15: No | AC15: =IF(AND(AA15="Yes",AB15=""),"BLOCK","OK") | AD15: ='MSRP Catalog'!M15 | AE15: =IF(AD15="","REVIEW",IF(AD15<TODAY(),"BLOCK","OK")) | AF15: ='MSRP Catalog'!K15 | AG15: ='MSRP Catalog'!N15
A16: ='MSRP Catalog'!A16 | B16: ='MSRP Catalog'!B16 | C16: ='MSRP Catalog'!C16 | D16: ='MSRP Catalog'!D16 | E16: ='MSRP Catalog'!E16 | F16: ='MSRP Catalog'!F16 | G16: ='MSRP Catalog'!G16 | H16: ='MSRP Catalog'!H16 | I16: ='MSRP Catalog'!I16 | J16: 0.1 | K16: =IFERROR(I16*(1-J16),"") | L16: =IFERROR(K16*(1-P16),"") | N16: =IFERROR(I16*(1-O16),"") | O16: 0.35 | P16: 0.2 | Q16: =IFERROR(L16/I16,"") | R16: =IF(OR(M16="",I16=0),"",M16/I16) | S16: Automatic | T16: CSO | U16: =IF(M16="","REVIEW",IF(L16<M16,"BLOCK","OK")) | V16: =IF(J16>O16,"BLOCK","OK") | W16: =IF(P16>IF(D16="Start",10%,IF(D16="Pro",15%,IF(OR(D16="Business",D16="Enterprise"),20%,30%))),"BLOCK","OK") | X16: =IF(OR(M16="",R16=""),"REVIEW",IF(Q16<R16,"BLOCK","OK")) | Y16: No | Z16: =IF(AND(D16="Ultimate",Y16="Yes"),"BLOCK","OK") | AA16: No | AC16: =IF(AND(AA16="Yes",AB16=""),"BLOCK","OK") | AD16: ='MSRP Catalog'!M16 | AE16: =IF(AD16="","REVIEW",IF(AD16<TODAY(),"BLOCK","OK")) | AF16: ='MSRP Catalog'!K16 | AG16: ='MSRP Catalog'!N16
... A114: ='MSRP Catalog'!A114 | B114: ='MSRP Catalog'!B114 | C114: ='MSRP Catalog'!C114 | D114: ='MSRP Catalog'!D114 | E114: ='MSRP Catalog'!E114 | F114: ='MSRP Catalog'!F114 | G114: ='MSRP Catalog'!G114 | H114: ='MSRP Catalog'!H114 | I114: ='MSRP Catalog'!I114 | J114: 0.1 | K114: =IFERROR(I114*(1-J114),"") | L114: =IFERROR(K114*(1-P114),"") | N114: =IFERROR(I114*(1-O114),"") | O114: 0.35 | P114: 0.3 | Q114: =IFERROR(L114/I114,"") | R114: =IF(OR(M114="",I114=0),"",M114/I114) | S114: Automatic | T114: CSO | U114: =IF(M114="","REVIEW",IF(L114<M114,"BLOCK","OK")) | V114: =IF(J114>O114,"BLOCK","OK") | W114: =IF(P114>IF(D114="Start",10%,IF(D114="Pro",15%,IF(OR(D114="Business",D114="Enterprise"),20%,30%))),"BLOCK","OK") | X114: =IF(OR(M114="",R114=""),"REVIEW",IF(Q114<R114,"BLOCK","OK")) | Y114: No | Z114: =IF(AND(D114="Ultimate",Y114="Yes"),"BLOCK","OK") | AA114: No | AC114: =IF(AND(AA114="Yes",AB114=""),"BLOCK","OK") | AD114: ='MSRP Catalog'!M114 | AE114: =IF(AD114="","REVIEW",IF(AD114<TODAY(),"BLOCK","OK")) | AF114: ='MSRP Catalog'!K114 | AG114: ='MSRP Catalog'!N114

Sheet Definitions
A1: Definitions
A2: Data dictionary and commercial conventions for the internal price book.
A4: Field | B4: Definition | C4: Example | D4: Owner
A5: Price Book Version | B5: Version identifier controlling effective pricing. | C5: FY2027-Q1 | D5: Commercial Operations
A6: SKU | B6: Unique commercial product identifier. | C6: CB-BUS-USER | D6: Product Operations
A7: Product | B7: Approved commercial product name. | C7: Business Regular User | D7: Product
A8: Plan | B8: Applicable Circularo plan. | C8: Business | D8: Product
A9: Product Family | B9: Commercial grouping used for reporting. | C9: Subscription | D9: Product
A10: Unit | B10: Commercial quantity to which MSRP applies. | C10: User / year | D10: Product
A11: Price Basis | B11: Annual, Per Event, Per Pack, or One-Time. | C11: Annual | D11: Commercial Operations
A12: Pack Quantity | B12: Number of events included when Price Basis is Per Pack. | C12: 100 | D12: Product
A13: MSRP | B13: Published list price before discount. Annual for subscription entitlements; otherwise applies to the stated event or pack. | C13: $600.00 | D13: Commercial Operations
A14: Target Customer Discount | B14: Expected standard customer discount, normally 10%. | C14: 10% | D14: Sales
A15: Target Customer Sell Price | B15: Expected market selling price after target discount. | C15: $540.00 | D15: Calculated
... A30: Circularo Price Realization | B30: Partner Buy Price divided by MSRP. Portfolio results must be value-weighted. | C30: 72% | D30: Finance

Sheet Formulas
A1: Formula Reference
A2: Auditable formula definitions. All workbook calculations should follow these patterns.
A4: Formula Name | B4: Formula | C4: Description
A5: Target Customer Sell Price | B5: MSRP × (1 − Target Customer Discount) | C5: Expected customer price after target discount.
A6: Standard Partner Buy Price | B6: Target Customer Sell Price × (1 − Target Realized Partner Margin) | C6: Default Circularo sell-in price.
A7: Customer Discount | B7: (MSRP − Customer Sell Price) ÷ MSRP | C7: Actual discount to list price.
A8: Realized Partner Gross Margin | B8: (Customer Sell Price − Partner Buy Price) ÷ Customer Sell Price | C8: Partner gross margin at actual customer price.
A9: Customer Sell Price Approval Threshold | B9: MSRP × (1 − Max Customer Discount) | C9: Internal approval benchmark, not a prescribed resale price.
A10: Standard Circularo Price Realization | B10: Standard Partner Buy Price ÷ MSRP | C10: MSRP retained by Circularo at standard price.
A11: Floor Circularo Price Realization | B11: Commercial Floor Price ÷ MSRP | C11: MSRP retained at the manually maintained floor.
A12: Weighted Portfolio Price Realization | B12: Total Partner Buy Price Value ÷ Total MSRP Value | C12: Value-weighted portfolio KPI; never average row percentages.

Sheet Partner Tiers
A1: Partner Tiers
A2: Standard tier and plan permissions. Ultimate is always a joint Circularo engagement.
A4: Partner Tier | B4: Target Role | C4: Standard Realized Margin Ceiling | D4: Start Margin Ceiling | E4: Pro Margin Ceiling | F4: Business Margin Ceiling | G4: Enterprise Margin Ceiling | H4: Can Quote Start | I4: Can Quote Pro | J4: Can Quote Business | K4: Can Quote Enterprise | L4: Can Quote Ultimate | M4: Max User-Based Quote | N4: Max Transaction-Based Quote | O4: Requires Deal Registration | P4: Notes
A5: Authorized | B5: Entry reseller | C5: 0.15 | D5: 0.1 | E5: 0.15 | F5: 0.15 | G5: 0.15 | H5: Yes | I5: Yes | J5: Yes | K5: Yes | L5: No | M5: TBC | N5: TBC | O5: Yes | P5: Standard entry-level reseller permissions.
A6: Advanced | B6: Developed reseller | C6: 0.2 | D6: 0.1 | E6: 0.15 | F6: 0.2 | G6: 0.2 | H6: Yes | I6: Yes | J6: Yes | K6: Yes | L6: No | M6: TBC | N6: TBC | O6: Yes | P6: Expanded commercial capability.
A7: Strategic | B7: Strategic growth partner | C7: 0.3 | D7: 0.1 | E7: 0.15 | F7: 0.3 | G7: 0.3 | H7: Yes | I7: Yes | J7: Yes | K7: Yes | L7: No | M7: TBC | N7: TBC | O7: Yes | P7: Up to 40% first-year margin only under the approved strategic exception.

Sheet Special Pricing Matrix
A1: Special Pricing Matrix
A2: Approval thresholds. Customer discount approval does not automatically increase partner margin.
A4: Customer Discount Band | B4: Treatment | C4: Required Approval | D4: Deal Registration Required | E4: Special Pricing Required | F4: Notes
A5: 0–10% | B5: Partner discretion | C5: Automatic | D5: No | E5: No | F5: Standard authority.
A6: >10–20% | B6: Normal commercial band | C6: Reported and tracked | D6: Recommended | E6: No | F6: Track realized economics.
A7: >20–35% | B7: Special pricing | C7: Sales leadership | D7: Yes | E7: Yes | F7: Opportunity-specific approval.
A8: >35–50% | B8: Exceptional strategic approval | C8: CSO | D8: Yes | E8: Yes | F8: Exceptional only.
A9: >50% | B9: Outside standard program | C9: CEO or prohibited | D9: Yes | E9: Exceptional only | F9: Not part of the standard partner program.
A10: Strategic exception | B10: Up to 40% first-year realized partner margin | C10: CSO | D10: Yes | E10: Yes | F10: Strategic Partner; new registered customer; Business or Enterprise; renewal returns to standard unless separately approved.

Sheet MSRP Catalog
A1: MSRP Catalog
A2: Source catalogue for published list prices. Yellow cells are editable inputs; zero MSRP means price confirmation is required.
A4: Price Book Version | B4: SKU | C4: Product | D4: Plan | E4: Product Family | F4: Unit | G4: Price Basis | H4: Pack Quantity | I4: MSRP | J4: Currency | K4: Status | L4: Effective From | M4: Effective To | N4: Notes
A5: FY2027-Q1 | B5: CX-RESTAPI-BUS | C5: ADD-ON | REST API Access | D5: Business | E5: Add-On | F5: 100 events | G5: Per Pack | H5: 100 | I5: 1500 | J5: USD | K5: Draft | L5: 46388 | M5: 46477 | N5: Imported from catalog/unified-catalog/unified-pricing-book.csv. Odoo cost: 0.00 USD.
A6: FY2027-Q1 | B6: CX-ADD-AIDOC | C6: ADD-ON | AI Document Assistant | D6: Business; Enterprise; Ultimate | E6: Add-On | F6: Organization / year | G6: Annual | I6: 1250 | J6: USD | K6: Draft | L6: 46388 | M6: 46477 | N6: Imported from catalog/unified-catalog/unified-pricing-book.csv. Odoo cost: 0.00 USD.
A7: FY2027-Q1 | B7: CX-ADD-REPORTS | C7: ADD-ON | Advanced Reporting | D7: Business; Enterprise; Ultimate | E7: Add-On | F7: Organization / year | G7: Annual | I7: 1500 | J7: USD | K7: Draft | L7: 46388 | M7: 46477 | N7: Imported from catalog/unified-catalog/unified-pricing-book.csv. Odoo cost: 0.00 USD.
A8: FY2027-Q1 | B8: CX-ADD-LIMIT80 | C8: ADD-ON | Boost eSign Transaction Limit to 80 MB | D8: Business; Enterprise; Ultimate | E8: Add-On | F8: Event | G8: Annual | I8: 1500 | J8: USD | K8: Draft | L8: 46388 | M8: 46477 | N8: Imported from catalog/unified-catalog/unified-pricing-book.csv. Odoo cost: 0.00 USD.
A9: FY2027-Q1 | B9: CX-ADD-BRANDING-PACK | C9: ADD-ON | Branded Experience Bundle | D9: Business; Enterprise; Ultimate | E9: Add-On | F9: Organization / year | G9: Annual | I9: 960 | J9: USD | K9: Draft | L9: 46388 | M9: 46477 | N9: Imported from catalog/unified-catalog/unified-pricing-book.csv. Odoo cost: 500.00 USD.
A10: FY2027-Q1 | B10: CX-ADD-BULKSIGN | C10: ADD-ON | Bulk Signing Transactions | D10: Business; Enterprise; Ultimate | E10: Add-On | F10: Event | G10: Annual | I10: 1.85 | J10: USD | K10: Draft | L10: 46388 | M10: 46477 | N10: Imported from catalog/unified-catalog/unified-pricing-book.csv. Odoo cost: 0.00 USD.
A11: FY2027-Q1 | B11: CX-ADD-CDOCS | C11: ADD-ON | Collabora Integration – cDocs | D11: Business; Enterprise; Ultimate | E11: Add-On | F11: Organization / year | G11: Annual | I11: 30 | J11: USD | K11: Draft | L11: 46388 | M11: 46477 | N11: Imported from catalog/unified-catalog/unified-pricing-book.csv. Odoo cost: 0.00 USD.
A12: FY2027-Q1 | B12: CX-ADD-CONTRACT | C12: ADD-ON | Contract Deadlines & Renewals | D12: Business; Enterprise; Ultimate | E12: Add-On | F12: Organization / year | G12: Annual | I12: 1250 | J12: USD | K12: Draft | L12: 46388 | M12: 46477 | N12: Imported from catalog/unified-catalog/unified-pricing-book.csv. Odoo cost: 0.00 USD.
A13: FY2027-Q1 | B13: CX-ADD-SKIN | C13: ADD-ON | Custom Branding and Styling | D13: Business; Enterprise; Ultimate | E13: Add-On | F13: Organization / year | G13: Annual | I13: 550 | J13: USD | K13: Draft | L13: 46388 | M13: 46477 | N13: Imported from catalog/unified-catalog/unified-pricing-book.csv. Odoo cost: 0.00 USD.
A14: FY2027-Q1 | B14: CX-ADD-DOMAIN | C14: ADD-ON | Custom Domain | D14: Business; Enterprise; Ultimate | E14: Add-On | F14: Organization / year | G14: Annual | I14: 950 | J14: USD | K14: Draft | L14: 46388 | M14: 46477 | N14: Imported from catalog/unified-catalog/unified-pricing-book.csv. Odoo cost: 0.00 USD.
A15: FY2027-Q1 | B15: CX-ADD-EMAILID | C15: ADD-ON | Custom Email Identity | D15: Business; Enterprise; Ultimate | E15: Add-On | F15: Organization / year | G15: Annual | I15: 1250 | J15: USD | K15: Draft | L15: 46388 | M15: 46477 | N15: Imported from catalog/unified-catalog/unified-pricing-book.csv. Odoo cost: 0.00 USD.
A16: FY2027-Q1 | B16: CX-ADD-EMAILTXT | C16: ADD-ON | Custom Email Notifications | D16: Business; Enterprise; Ultimate | E16: Add-On | F16: Organization / year | G16: Annual | I16: 1500 | J16: USD | K16: Draft | L16: 46388 | M16: 46477 | N16: Imported from catalog/unified-catalog/unified-pricing-book.csv. Odoo cost: 0.00 USD.
A17: FY2027-Q1 | B17: CX-ADD-CERUSR | C17: ADD-ON | Custom Employee Level Electronic Signing Certificate (500 signatures per year) | D17: Business; Enterprise; Ultimate | E17: Add-On | F17: Organization / year | G17: Annual | I17: 250 | J17: USD | K17: Draft | L17: 46388 | M17: 46477 | N17: Imported from catalog/unified-catalog/unified-pricing-book.csv. Odoo cost: 0.00 USD.
A18: FY2027-Q1 | B18: CX-ADD-DESC | C18: ADD-ON | DESC eSeal Certificate (3-year) | D18: Business; Enterprise; Ultimate | E18: Add-On | F18: Organization / year | G18: Annual | I18: 4500 | J18: USD | K18: Draft | L18: 46388 | M18: 46477 | N18: Imported from catalog/unified-catalog/unified-pricing-book.csv. Odoo cost: 0.00 USD.
A19: FY2027-Q1 | B19: CX-ADD-DMS | C19: ADD-ON | Document Management & Archiving | D19: Business; Enterprise; Ultimate | E19: Add-On | F19: 100 events | G19: Annual | H19: 100 | I19: 1500 | J19: USD | K19: Draft | L19: 46388 | M19: 46477 | N19: Imported from catalog/unified-catalog/unified-pricing-book.csv. Odoo cost: 0.00 USD.
A20: FY2027-Q1 | B20: CX-ADD-STG | C20: ADD-ON | Extra Archiving Storage (100) | D20: Business; Enterprise; Ultimate | E20: Add-On | F20: 100 GB / year | G20: Annual | H20: 100 | I20: 65 | J20: USD | K20: Draft | L20: 46388 | M20: 46477 | N20: Imported from catalog/unified-catalog/unified-pricing-book.csv. Odoo cost: 35.00 USD.
A21: FY2027-Q1 | B21: CX-ADD-KYC-IDVERIFY1 | C21: ADD-ON | Identomat ID Verification | D21: Business; Enterprise; Ultimate | E21: Add-On | F21: Event | G21: Per Event | I21: 1.45 | J21: USD | K21: Draft | L21: 46388 | M21: 46477 | N21: Imported from catalog/unified-catalog/unified-pricing-book.csv. Odoo cost: 0.45 USD.
A22: FY2027-Q1 | B22: CX-ADD-KYC-LIVENESS1 | C22: ADD-ON | Identomat Liveness Verification | D22: Business; Enterprise; Ultimate | E22: Add-On | F22: Event | G22: Per Event | I22: 0.45 | J22: USD | K22: Draft | L22: 46388 | M22: 46477 | N22: Imported from catalog/unified-catalog/unified-pricing-book.csv. Odoo cost: 0.15 USD.
A23: FY2027-Q1 | B23: CX-ADD-CERORG2 | C23: ADD-ON | Organizational Signing & Sealing Certificate (AATL – DESC) | D23: Business; Enterprise; Ultimate | E23: Add-On | F23: Organization / year | G23: Annual | I23: 550 | J23: USD | K23: Draft | L23: 46388 | M23: 46477 | N23: Imported from catalog/unified-catalog/unified-pricing-book.csv. Odoo cost: 0.00 USD.
A24: FY2027-Q1 | B24: CX-ADD-CERORG1 | C24: ADD-ON | Organizational Signing & Sealing Certificate (AATL – I.CA) | D24: Business; Enterprise; Ultimate | E24: Add-On | F24: Organization / year | G24: Annual | I24: 550 | J24: USD | K24: Draft | L24: 46388 | M24: 46477 | N24: Imported from catalog/unified-catalog/unified-pricing-book.csv. Odoo cost: 0.00 USD.
A25: FY2027-Q1 | B25: CX-ADD-FREC | C25: ADD-ON | PDF Form Fields Recognition | D25: Business; Enterprise; Ultimate | E25: Add-On | F25: Organization / year | G25: Annual | I25: 475 | J25: USD | K25: Draft | L25: 46388 | M25: 46477 | N25: Imported from catalog/unified-catalog/unified-pricing-book.csv. Odoo cost: 0.00 USD.
A26: FY2027-Q1 | B26: CX-ADD-DATAPREFILL | C26: ADD-ON | Pre-Fill Documents with External Data | D26: Business; Enterprise; Ultimate | E26: Add-On | F26: Organization / year | G26: Annual | I26: 550 | J26: USD | K26: Draft | L26: 46388 | M26: 46477 | N26: Imported from catalog/unified-catalog/unified-pricing-book.csv. Odoo cost: 0.00 USD.
A27: FY2027-Q1 | B27: CX-ADD-PS-MD | C27: ADD-ON | Professional Services (1 MD) | D27: Business; Enterprise; Ultimate | E27: Add-On | F27: Man-day | G27: One-Time | I27: 850 | J27: USD | K27: Draft | L27: 46388 | M27: 46477 | N27: Imported from catalog/unified-catalog/unified-pricing-book.csv. Odoo cost: 0.00 USD.
A28: FY2027-Q1 | B28: CX-ADD-QUICK | C28: ADD-ON | Quick Document Processing | D28: Business; Enterprise; Ultimate | E28: Add-On | F28: Organization / year | G28: Annual | I28: 2500 | J28: USD | K28: Draft | L28: 46388 | M28: 46477 | N28: Imported from catalog/unified-catalog/unified-pricing-book.csv. Odoo cost: 0.00 USD.
A29: FY2027-Q1 | B29: CX-ADD-API-MD | C29: ADD-ON | REST API Integration Assistance (1 MD) | D29: Business; Enterprise; Ultimate | E29: Add-On | F29: Man-day | G29: One-Time | I29: 850 | J29: USD | K29: Draft | L29: 46388 | M29: 46477 | N29: Imported from catalog/unified-catalog/unified-pricing-book.csv. Odoo cost: 0.00 USD.
A30: FY2027-Q1 | B30: CX-ADD-SAML | C30: ADD-ON | SAML 2.0 SSO | D30: Business; Enterprise; Ultimate | E30: Add-On | F30: Organization / year | G30: Annual | I30: 1350 | J30: USD | K30: Draft | L30: 46388 | M30: 46477 | N30: Imported from catalog/unified-catalog/unified-pricing-book.csv. Odoo cost: 0.00 USD.
A31: FY2027-Q1 | B31: CX-ADD-SMSCREDIT | C31: ADD-ON | SMS Credits (100) | D31: Business; Enterprise; Ultimate | E31: Add-On | F31: 100 SMS | G31: Per Pack | H31: 100 | I31: 25 | J31: USD | K31: Draft | L31: 46388 | M31: 46477 | N31: Imported from catalog/unified-catalog/unified-pricing-book.csv. Odoo cost: 18.00 USD.
A32: FY2027-Q1 | B32: CX-ADD-SMSOTP | C32: ADD-ON | SMS OTP Verification | D32: Business; Enterprise; Ultimate | E32: Add-On | F32: Event | G32: Annual | I32: 380 | J32: USD | K32: Draft | L32: 46388 | M32: 46477 | N32: Imported from catalog/unified-catalog/unified-pricing-book.csv. Odoo cost: 0.00 USD.
A33: FY2027-Q1 | B33: CX-ADD-SMSREM | C33: ADD-ON | SMS Reminders | D33: Business; Enterprise; Ultimate | E33: Add-On | F33: Organization / year | G33: Annual | I33: 250 | J33: USD | K33: Draft | L33: 46388 | M33: 46477 | N33: Imported from catalog/unified-catalog/unified-pricing-book.csv. Odoo cost: 0.00 USD.
A34: FY2027-Q1 | B34: CX-ADD-SGPROVIDER | C34: ADD-ON | Select Signature Provider | D34: Business; Enterprise; Ultimate | E34: Add-On | F34: Organization / year | G34: Annual | I34: 450 | J34: USD | K34: Draft | L34: 46388 | M34: 46477 | N34: Imported from catalog/unified-catalog/unified-pricing-book.csv. Odoo cost: 0.00 USD.
A35: FY2027-Q1 | B35: CX-ADD-MSAC | C35: ADD-ON | Sharepoint Connector | D35: Business; Enterprise; Ultimate | E35: Add-On | F35: Organization / year | G35: Annual | I35: 1150 | J35: USD | K35: Draft | L35: 46388 | M35: 46477 | N35: Imported from catalog/unified-catalog/unified-pricing-book.csv. Odoo cost: 0.00 USD.
A36: FY2027-Q1 | B36: CX-ADD-SIGNMODE | C36: ADD-ON | Signature Mode Selection | D36: Business; Enterprise; Ultimate | E36: Add-On | F36: Organization / year | G36: Annual | I36: 245 | J36: USD | K36: Draft | L36: 46388 | M36: 46477 | N36: Imported from catalog/unified-catalog/unified-pricing-book.csv. Odoo cost: 0.00 USD.
A37: FY2027-Q1 | B37: CX-ADD-CONTROLLER | C37: ADD-ON | Transaction Controller | D37: Business; Enterprise; Ultimate | E37: Add-On | F37: Event | G37: Annual | I37: 325 | J37: USD | K37: Draft | L37: 46388 | M37: 46477 | N37: Imported from catalog/unified-catalog/unified-pricing-book.csv. Odoo cost: 0.00 USD.
A38: FY2027-Q1 | B38: CX-ADD-VERIFY | C38: ADD-ON | Verification Request (100) | D38: Business; Enterprise; Ultimate | E38: Add-On | F38: 100 verification requests | G38: Per Pack | H38: 100 | I38: 100 | J38: USD | K38: Draft | L38: 46388 | M38: 46477 | N38: Imported from catalog/unified-catalog/unified-pricing-book.csv. Odoo cost: 0.00 USD.
A39: FY2027-Q1 | B39: CX-ADD-QSEAL-1 | C39: ADD-ON | eIDAS Qualified Seal (DataSure) | D39: Business; Enterprise; Ultimate | E39: Add-On | F39: Organization / year | G39: Annual | I39: 45 | J39: USD | K39: Draft | L39: 46388 | M39: 46477 | N39: Imported from catalog/unified-catalog/unified-pricing-book.csv. Odoo cost: 0.00 USD.
A40: FY2027-Q1 | B40: CX-ADD-ESEAL-API | C40: ADD-ON | eSeal API Transaction | D40: Business; Enterprise; Ultimate | E40: Add-On | F40: Event | G40: Per Event | I40: 1.5 | J40: USD | K40: Draft | L40: 46388 | M40: 46477 | N40: Imported from catalog/unified-catalog/unified-pricing-book.csv. Odoo cost: 0.00 USD.
A41: FY2027-Q1 | B41: CX-ADD-ESIGN-API | C41: ADD-ON | eSign API Transaction | D41: Business; Enterprise; Ultimate | E41: Add-On | F41: Event | G41: Per Event | I41: 2.85 | J41: USD | K41: Draft | L41: 46388 | M41: 46477 | N41: Imported from catalog/unified-catalog/unified-pricing-book.csv. Odoo cost: 0.00 USD.
...

Sheet Partner Buy Price Matrix
A1: Partner Buy Price Matrix
A2: Tier-specific prices generated from the single-SKU master Price Book.
A4: Price Book Version | B4: SKU | C4: Product | D4: Plan | E4: Price Basis | F4: MSRP | G4: Target Customer Discount | H4: Target Customer Sell Price | I4: Authorized Buy Price | J4: Advanced Buy Price | K4: Strategic Buy Price | L4: Authorized Margin | M4: Advanced Margin | N4: Strategic Margin | O4: Commercial Floor Price | P4: Customer Sell Price Approval Threshold | Q4: Max Customer Discount | R4: Authorized Circularo Price Realization | S4: Advanced Circularo Price Realization | T4: Strategic Circularo Price Realization | U4: Floor Circularo Price Realization | V4: Notes
A5: ='Price Book'!A5 | B5: ='Price Book'!B5 | C5: ='Price Book'!C5 | D5: ='Price Book'!D5 | E5: ='Price Book'!G5 | F5: ='Price Book'!I5 | G5: ='Price Book'!J5 | H5: ='Price Book'!K5 | I5: =IFERROR(H5*(1-L5),"") | J5: =IFERROR(H5*(1-M5),"") | K5: =IFERROR(H5*(1-N5),"") | L5: =IF(D5="Start",'Partner Tiers'!$D$5,IF(D5="Pro",'Partner Tiers'!$E$5,IF(D5="Business",'Partner Tiers'!$F$5,IF(D5="Enterprise",'Partner Tiers'!$G$5,"")))) | M5: =IF(D5="Start",'Partner Tiers'!$D$6,IF(D5="Pro",'Partner Tiers'!$E$6,IF(D5="Business",'Partner Tiers'!$F$6,IF(D5="Enterprise",'Partner Tiers'!$G$6,"")))) | N5: =IF(D5="Start",'Partner Tiers'!$D$7,IF(D5="Pro",'Partner Tiers'!$E$7,IF(D5="Business",'Partner Tiers'!$F$7,IF(D5="Enterprise",'Partner Tiers'!$G$7,"")))) | O5: ='Price Book'!M5 | P5: ='Price Book'!N5 | Q5: ='Price Book'!O5 | R5: =IFERROR(I5/F5,"") | S5: =IFERROR(J5/F5,"") | T5: =IFERROR(K5/F5,"") | U5: ='Price Book'!R5 | V5: ='Price Book'!AG5
A6: ='Price Book'!A6 | B6: ='Price Book'!B6 | C6: ='Price Book'!C6 | D6: ='Price Book'!D6 | E6: ='Price Book'!G6 | F6: ='Price Book'!I6 | G6: ='Price Book'!J6 | H6: ='Price Book'!K6 | I6: =IFERROR(H6*(1-L6),"") | J6: =IFERROR(H6*(1-M6),"") | K6: =IFERROR(H6*(1-N6),"") | L6: =IF(D6="Start",'Partner Tiers'!$D$5,IF(D6="Pro",'Partner Tiers'!$E$5,IF(D6="Business",'Partner Tiers'!$F$5,IF(D6="Enterprise",'Partner Tiers'!$G$5,"")))) | M6: =IF(D6="Start",'Partner Tiers'!$D$6,IF(D6="Pro",'Partner Tiers'!$E$6,IF(D6="Business",'Partner Tiers'!$F$6,IF(D6="Enterprise",'Partner Tiers'!$G$6,"")))) | N6: =IF(D6="Start",'Partner Tiers'!$D$7,IF(D6="Pro",'Partner Tiers'!$E$7,IF(D6="Business",'Partner Tiers'!$F$7,IF(D6="Enterprise",'Partner Tiers'!$G$7,"")))) | O6: ='Price Book'!M6 | P6: ='Price Book'!N6 | Q6: ='Price Book'!O6 | R6: =IFERROR(I6/F6,"") | S6: =IFERROR(J6/F6,"") | T6: =IFERROR(K6/F6,"") | U6: ='Price Book'!R6 | V6: ='Price Book'!AG6
A7: ='Price Book'!A7 | B7: ='Price Book'!B7 | C7: ='Price Book'!C7 | D7: ='Price Book'!D7 | E7: ='Price Book'!G7 | F7: ='Price Book'!I7 | G7: ='Price Book'!J7 | H7: ='Price Book'!K7 | I7: =IFERROR(H7*(1-L7),"") | J7: =IFERROR(H7*(1-M7),"") | K7: =IFERROR(H7*(1-N7),"") | L7: =IF(D7="Start",'Partner Tiers'!$D$5,IF(D7="Pro",'Partner Tiers'!$E$5,IF(D7="Business",'Partner Tiers'!$F$5,IF(D7="Enterprise",'Partner Tiers'!$G$5,"")))) | M7: =IF(D7="Start",'Partner Tiers'!$D$6,IF(D7="Pro",'Partner Tiers'!$E$6,IF(D7="Business",'Partner Tiers'!$F$6,IF(D7="Enterprise",'Partner Tiers'!$G$6,"")))) | N7: =IF(D7="Start",'Partner Tiers'!$D$7,IF(D7="Pro",'Partner Tiers'!$E$7,IF(D7="Business",'Partner Tiers'!$F$7,IF(D7="Enterprise",'Partner Tiers'!$G$7,"")))) | O7: ='Price Book'!M7 | P7: ='Price Book'!N7 | Q7: ='Price Book'!O7 | R7: =IFERROR(I7/F7,"") | S7: =IFERROR(J7/F7,"") | T7: =IFERROR(K7/F7,"") | U7: ='Price Book'!R7 | V7: ='Price Book'!AG7
A8: ='Price Book'!A8 | B8: ='Price Book'!B8 | C8: ='Price Book'!C8 | D8: ='Price Book'!D8 | E8: ='Price Book'!G8 | F8: ='Price Book'!I8 | G8: ='Price Book'!J8 | H8: ='Price Book'!K8 | I8: =IFERROR(H8*(1-L8),"") | J8: =IFERROR(H8*(1-M8),"") | K8: =IFERROR(H8*(1-N8),"") | L8: =IF(D8="Start",'Partner Tiers'!$D$5,IF(D8="Pro",'Partner Tiers'!$E$5,IF(D8="Business",'Partner Tiers'!$F$5,IF(D8="Enterprise",'Partner Tiers'!$G$5,"")))) | M8: =IF(D8="Start",'Partner Tiers'!$D$6,IF(D8="Pro",'Partner Tiers'!$E$6,IF(D8="Business",'Partner Tiers'!$F$6,IF(D8="Enterprise",'Partner Tiers'!$G$6,"")))) | N8: =IF(D8="Start",'Partner Tiers'!$D$7,IF(D8="Pro",'Partner Tiers'!$E$7,IF(D8="Business",'Partner Tiers'!$F$7,IF(D8="Enterprise",'Partner Tiers'!$G$7,"")))) | O8: ='Price Book'!M8 | P8: ='Price Book'!N8 | Q8: ='Price Book'!O8 | R8: =IFERROR(I8/F8,"") | S8: =IFERROR(J8/F8,"") | T8: =IFERROR(K8/F8,"") | U8: ='Price Book'!R8 | V8: ='Price Book'!AG8
A9: ='Price Book'!A9 | B9: ='Price Book'!B9 | C9: ='Price Book'!C9 | D9: ='Price Book'!D9 | E9: ='Price Book'!G9 | F9: ='Price Book'!I9 | G9: ='Price Book'!J9 | H9: ='Price Book'!K9 | I9: =IFERROR(H9*(1-L9),"") | J9: =IFERROR(H9*(1-M9),"") | K9: =IFERROR(H9*(1-N9),"") | L9: =IF(D9="Start",'Partner Tiers'!$D$5,IF(D9="Pro",'Partner Tiers'!$E$5,IF(D9="Business",'Partner Tiers'!$F$5,IF(D9="Enterprise",'Partner Tiers'!$G$5,"")))) | M9: =IF(D9="Start",'Partner Tiers'!$D$6,IF(D9="Pro",'Partner Tiers'!$E$6,IF(D9="Business",'Partner Tiers'!$F$6,IF(D9="Enterprise",'Partner Tiers'!$G$6,"")))) | N9: =IF(D9="Start",'Partner Tiers'!$D$7,IF(D9="Pro",'Partner Tiers'!$E$7,IF(D9="Business",'Partner Tiers'!$F$7,IF(D9="Enterprise",'Partner Tiers'!$G$7,"")))) | O9: ='Price Book'!M9 | P9: ='Price Book'!N9 | Q9: ='Price Book'!O9 | R9: =IFERROR(I9/F9,"") | S9: =IFERROR(J9/F9,"") | T9: =IFERROR(K9/F9,"") | U9: ='Price Book'!R9 | V9: ='Price Book'!AG9
A10: ='Price Book'!A10 | B10: ='Price Book'!B10 | C10: ='Price Book'!C10 | D10: ='Price Book'!D10 | E10: ='Price Book'!G10 | F10: ='Price Book'!I10 | G10: ='Price Book'!J10 | H10: ='Price Book'!K10 | I10: =IFERROR(H10*(1-L10),"") | J10: =IFERROR(H10*(1-M10),"") | K10: =IFERROR(H10*(1-N10),"") | L10: =IF(D10="Start",'Partner Tiers'!$D$5,IF(D10="Pro",'Partner Tiers'!$E$5,IF(D10="Business",'Partner Tiers'!$F$5,IF(D10="Enterprise",'Partner Tiers'!$G$5,"")))) | M10: =IF(D10="Start",'Partner Tiers'!$D$6,IF(D10="Pro",'Partner Tiers'!$E$6,IF(D10="Business",'Partner Tiers'!$F$6,IF(D10="Enterprise",'Partner Tiers'!$G$6,"")))) | N10: =IF(D10="Start",'Partner Tiers'!$D$7,IF(D10="Pro",'Partner Tiers'!$E$7,IF(D10="Business",'Partner Tiers'!$F$7,IF(D10="Enterprise",'Partner Tiers'!$G$7,"")))) | O10: ='Price Book'!M10 | P10: ='Price Book'!N10 | Q10: ='Price Book'!O10 | R10: =IFERROR(I10/F10,"") | S10: =IFERROR(J10/F10,"") | T10: =IFERROR(K10/F10,"") | U10: ='Price Book'!R10 | V10: ='Price Book'!AG10
A11: ='Price Book'!A11 | B11: ='Price Book'!B11 | C11: ='Price Book'!C11 | D11: ='Price Book'!D11 | E11: ='Price Book'!G11 | F11: ='Price Book'!I11 | G11: ='Price Book'!J11 | H11: ='Price Book'!K11 | I11: =IFERROR(H11*(1-L11),"") | J11: =IFERROR(H11*(1-M11),"") | K11: =IFERROR(H11*(1-N11),"") | L11: =IF(D11="Start",'Partner Tiers'!$D$5,IF(D11="Pro",'Partner Tiers'!$E$5,IF(D11="Business",'Partner Tiers'!$F$5,IF(D11="Enterprise",'Partner Tiers'!$G$5,"")))) | M11: =IF(D11="Start",'Partner Tiers'!$D$6,IF(D11="Pro",'Partner Tiers'!$E$6,IF(D11="Business",'Partner Tiers'!$F$6,IF(D11="Enterprise",'Partner Tiers'!$G$6,"")))) | N11: =IF(D11="Start",'Partner Tiers'!$D$7,IF(D11="Pro",'Partner Tiers'!$E$7,IF(D11="Business",'Partner Tiers'!$F$7,IF(D11="Enterprise",'Partner Tiers'!$G$7,"")))) | O11: ='Price Book'!M11 | P11: ='Price Book'!N11 | Q11: ='Price Book'!O11 | R11: =IFERROR(I11/F11,"") | S11: =IFERROR(J11/F11,"") | T11: =IFERROR(K11/F11,"") | U11: ='Price Book'!R11 | V11: ='Price Book'!AG11
A12: ='Price Book'!A12 | B12: ='Price Book'!B12 | C12: ='Price Book'!C12 | D12: ='Price Book'!D12 | E12: ='Price Book'!G12 | F12: ='Price Book'!I12 | G12: ='Price Book'!J12 | H12: ='Price Book'!K12 | I12: =IFERROR(H12*(1-L12),"") | J12: =IFERROR(H12*(1-M12),"") | K12: =IFERROR(H12*(1-N12),"") | L12: =IF(D12="Start",'Partner Tiers'!$D$5,IF(D12="Pro",'Partner Tiers'!$E$5,IF(D12="Business",'Partner Tiers'!$F$5,IF(D12="Enterprise",'Partner Tiers'!$G$5,"")))) | M12: =IF(D12="Start",'Partner Tiers'!$D$6,IF(D12="Pro",'Partner Tiers'!$E$6,IF(D12="Business",'Partner Tiers'!$F$6,IF(D12="Enterprise",'Partner Tiers'!$G$6,"")))) | N12: =IF(D12="Start",'Partner Tiers'!$D$7,IF(D12="Pro",'Partner Tiers'!$E$7,IF(D12="Business",'Partner Tiers'!$F$7,IF(D12="Enterprise",'Partner Tiers'!$G$7,"")))) | O12: ='Price Book'!M12 | P12: ='Price Book'!N12 | Q12: ='Price Book'!O12 | R12: =IFERROR(I12/F12,"") | S12: =IFERROR(J12/F12,"") | T12: =IFERROR(K12/F12,"") | U12: ='Price Book'!R12 | V12: ='Price Book'!AG12
A13: ='Price Book'!A13 | B13: ='Price Book'!B13 | C13: ='Price Book'!C13 | D13: ='Price Book'!D13 | E13: ='Price Book'!G13 | F13: ='Price Book'!I13 | G13: ='Price Book'!J13 | H13: ='Price Book'!K13 | I13: =IFERROR(H13*(1-L13),"") | J13: =IFERROR(H13*(1-M13),"") | K13: =IFERROR(H13*(1-N13),"") | L13: =IF(D13="Start",'Partner Tiers'!$D$5,IF(D13="Pro",'Partner Tiers'!$E$5,IF(D13="Business",'Partner Tiers'!$F$5,IF(D13="Enterprise",'Partner Tiers'!$G$5,"")))) | M13: =IF(D13="Start",'Partner Tiers'!$D$6,IF(D13="Pro",'Partner Tiers'!$E$6,IF(D13="Business",'Partner Tiers'!$F$6,IF(D13="Enterprise",'Partner Tiers'!$G$6,"")))) | N13: =IF(D13="Start",'Partner Tiers'!$D$7,IF(D13="Pro",'Partner Tiers'!$E$7,IF(D13="Business",'Partner Tiers'!$F$7,IF(D13="Enterprise",'Partner Tiers'!$G$7,"")))) | O13: ='Price Book'!M13 | P13: ='Price Book'!N13 | Q13: ='Price Book'!O13 | R13: =IFERROR(I13/F13,"") | S13: =IFERROR(J13/F13,"") | T13: =IFERROR(K13/F13,"") | U13: ='Price Book'!R13 | V13: ='Price Book'!AG13
A14: ='Price Book'!A14 | B14: ='Price Book'!B14 | C14: ='Price Book'!C14 | D14: ='Price Book'!D14 | E14: ='Price Book'!G14 | F14: ='Price Book'!I14 | G14: ='Price Book'!J14 | H14: ='Price Book'!K14 | I14: =IFERROR(H14*(1-L14),"") | J14: =IFERROR(H14*(1-M14),"") | K14: =IFERROR(H14*(1-N14),"") | L14: =IF(D14="Start",'Partner Tiers'!$D$5,IF(D14="Pro",'Partner Tiers'!$E$5,IF(D14="Business",'Partner Tiers'!$F$5,IF(D14="Enterprise",'Partner Tiers'!$G$5,"")))) | M14: =IF(D14="Start",'Partner Tiers'!$D$6,IF(D14="Pro",'Partner Tiers'!$E$6,IF(D14="Business",'Partner Tiers'!$F$6,IF(D14="Enterprise",'Partner Tiers'!$G$6,"")))) | N14: =IF(D14="Start",'Partner Tiers'!$D$7,IF(D14="Pro",'Partner Tiers'!$E$7,IF(D14="Business",'Partner Tiers'!$F$7,IF(D14="Enterprise",'Partner Tiers'!$G$7,"")))) | O14: ='Price Book'!M14 | P14: ='Price Book'!N14 | Q14: ='Price Book'!O14 | R14: =IFERROR(I14/F14,"") | S14: =IFERROR(J14/F14,"") | T14: =IFERROR(K14/F14,"") | U14: ='Price Book'!R14 | V14: ='Price Book'!AG14
A15: ='Price Book'!A15 | B15: ='Price Book'!B15 | C15: ='Price Book'!C15 | D15: ='Price Book'!D15 | E15: ='Price Book'!G15 | F15: ='Price Book'!I15 | G15: ='Price Book'!J15 | H15: ='Price Book'!K15 | I15: =IFERROR(H15*(1-L15),"") | J15: =IFERROR(H15*(1-M15),"") | K15: =IFERROR(H15*(1-N15),"") | L15: =IF(D15="Start",'Partner Tiers'!$D$5,IF(D15="Pro",'Partner Tiers'!$E$5,IF(D15="Business",'Partner Tiers'!$F$5,IF(D15="Enterprise",'Partner Tiers'!$G$5,"")))) | M15: =IF(D15="Start",'Partner Tiers'!$D$6,IF(D15="Pro",'Partner Tiers'!$E$6,IF(D15="Business",'Partner Tiers'!$F$6,IF(D15="Enterprise",'Partner Tiers'!$G$6,"")))) | N15: =IF(D15="Start",'Partner Tiers'!$D$7,IF(D15="Pro",'Partner Tiers'!$E$7,IF(D15="Business",'Partner Tiers'!$F$7,IF(D15="Enterprise",'Partner Tiers'!$G$7,"")))) | O15: ='Price Book'!M15 | P15: ='Price Book'!N15 | Q15: ='Price Book'!O15 | R15: =IFERROR(I15/F15,"") | S15: =IFERROR(J15/F15,"") | T15: =IFERROR(K15/F15,"") | U15: ='Price Book'!R15 | V15: ='Price Book'!AG15
A16: ='Price Book'!A16 | B16: ='Price Book'!B16 | C16: ='Price Book'!C16 | D16: ='Price Book'!D16 | E16: ='Price Book'!G16 | F16: ='Price Book'!I16 | G16: ='Price Book'!J16 | H16: ='Price Book'!K16 | I16: =IFERROR(H16*(1-L16),"") | J16: =IFERROR(H16*(1-M16),"") | K16: =IFERROR(H16*(1-N16),"") | L16: =IF(D16="Start",'Partner Tiers'!$D$5,IF(D16="Pro",'Partner Tiers'!$E$5,IF(D16="Business",'Partner Tiers'!$F$5,IF(D16="Enterprise",'Partner Tiers'!$G$5,"")))) | M16: =IF(D16="Start",'Partner Tiers'!$D$6,IF(D16="Pro",'Partner Tiers'!$E$6,IF(D16="Business",'Partner Tiers'!$F$6,IF(D16="Enterprise",'Partner Tiers'!$G$6,"")))) | N16: =IF(D16="Start",'Partner Tiers'!$D$7,IF(D16="Pro",'Partner Tiers'!$E$7,IF(D16="Business",'Partner Tiers'!$F$7,IF(D16="Enterprise",'Partner Tiers'!$G$7,"")))) | O16: ='Price Book'!M16 | P16: ='Price Book'!N16 | Q16: ='Price Book'!O16 | R16: =IFERROR(I16/F16,"") | S16: =IFERROR(J16/F16,"") | T16: =IFERROR(K16/F16,"") | U16: ='Price Book'!R16 | V16: ='Price Book'!AG16
... A114: ='Price Book'!A114 | B114: ='Price Book'!B114 | C114: ='Price Book'!C114 | D114: ='Price Book'!D114 | E114: ='Price Book'!G114 | F114: ='Price Book'!I114 | G114: ='Price Book'!J114 | H114: ='Price Book'!K114 | I114: =IFERROR(H114*(1-L114),"") | J114: =IFERROR(H114*(1-M114),"") | K114: =IFERROR(H114*(1-N114),"") | L114: =IF(D114="Start",'Partner Tiers'!$D$5,IF(D114="Pro",'Partner Tiers'!$E$5,IF(D114="Business",'Partner Tiers'!$F$5,IF(D114="Enterprise",'Partner Tiers'!$G$5,"")))) | M114: =IF(D114="Start",'Partner Tiers'!$D$6,IF(D114="Pro",'Partner Tiers'!$E$6,IF(D114="Business",'Partner Tiers'!$F$6,IF(D114="Enterprise",'Partner Tiers'!$G$6,"")))) | N114: =IF(D114="Start",'Partner Tiers'!$D$7,IF(D114="Pro",'Partner Tiers'!$E$7,IF(D114="Business",'Partner Tiers'!$F$7,IF(D114="Enterprise",'Partner Tiers'!$G$7,"")))) | O114: ='Price Book'!M114 | P114: ='Price Book'!N114 | Q114: ='Price Book'!O114 | R114: =IFERROR(I114/F114,"") | S114: =IFERROR(J114/F114,"") | T114: =IFERROR(K114/F114,"") | U114: ='Price Book'!R114 | V114: ='Price Book'!AG114

Sheet Discount Approval Matrix
A1: Discount Approval Matrix
A2: Customer discount governance aligned to the Special Pricing Matrix.
A4: Discount Range | B4: Approval Required | C4: Applies To | D4: Partner Discretion | E4: Deal Registration Required | F4: Special Pricing Required | G4: CSO Approval Required | H4: Notes
A5: 0–10% | B5: Automatic | C5: All standard partner deals | D5: Yes | E5: No | F5: No | G5: No | H5: Standard authority.
A6: >10–20% | B6: Reported and tracked | C6: All plans | D6: Yes | E6: Recommended | F6: No | G6: No | H6: Monitor realization.
A7: >20–35% | B7: Sales leadership | C7: Standard program | D7: No | E7: Yes | F7: Yes | G7: No | H7: Special pricing required.
A8: >35–50% | B8: CSO | C8: Strategic exceptions | D8: No | E8: Yes | F8: Yes | G8: Yes | H8: Exceptional only.
A9: >50% | B9: CEO or prohibited | C9: Outside standard program | D9: No | E9: Yes | F9: Exceptional only | G9: Yes | H9: Escalate before commitment.

Sheet Price Book History
A1: Price Book History
A2: Version control and approval history.
A4: Version | B4: Status | C4: Effective From | D4: Effective To | E4: Created By | F4: Approved By | G4: Approval Date | H4: Summary of Changes | I4: Notes
A5: FY2027-Q1 | B5: Draft | C5: 46388 | D5: 46477 | E5: Commercial Operations | H5: Initial Commercial Pricing Engine workbook. | I5: Pending commercial approval.
A6: FY2027-Q2 | B6: Planned | C6: 46478 | D6: 46568 | E6: Commercial Operations | H6: Planned quarterly refresh. | I6: Not started.

Sheet Price Realization
A1: Circularo Price Realization
A2: Finance KPI: Partner Buy Price ÷ MSRP. Portfolio KPIs are value-weighted, never simple averages.
A5: Total MSRP Value | B5: =SUM(L12:L121)
A6: Total Standard Partner Buy Price Value | B6: =SUM(M12:M121)
A7: Weighted Standard Circularo Price Realization | B7: =IFERROR(B6/B5,"")
A8: Total Commercial Floor Value | B8: =IF(COUNT(N12:N121)=0,"",SUM(N12:N121))
A9: Weighted Floor Circularo Price Realization | B9: =IFERROR(B8/B5,"")
A11: Price Book Version | B11: SKU | C11: Product | D11: Plan | E11: Price Basis | F11: MSRP | G11: Standard Partner Buy Price | H11: Commercial Floor Price | I11: Standard Circularo Price Realization | J11: Floor Circularo Price Realization | K11: Quantity / Volume | L11: MSRP Value | M11: Partner Buy Price Value | N11: Commercial Floor Value | O11: Notes
A12: ='Price Book'!A5 | B12: ='Price Book'!B5 | C12: ='Price Book'!C5 | D12: ='Price Book'!D5 | E12: ='Price Book'!G5 | F12: ='Price Book'!I5 | G12: ='Price Book'!L5 | H12: ='Price Book'!M5 | I12: ='Price Book'!Q5 | J12: ='Price Book'!R5 | K12: 1 | L12: =IFERROR(F12*K12,"") | M12: =IFERROR(G12*K12,"") | N12: =IF(H12="","",H12*K12) | O12: ='Price Book'!AG5
A13: ='Price Book'!A6 | B13: ='Price Book'!B6 | C13: ='Price Book'!C6 | D13: ='Price Book'!D6 | E13: ='Price Book'!G6 | F13: ='Price Book'!I6 | G13: ='Price Book'!L6 | H13: ='Price Book'!M6 | I13: ='Price Book'!Q6 | J13: ='Price Book'!R6 | K13: 1 | L13: =IFERROR(F13*K13,"") | M13: =IFERROR(G13*K13,"") | N13: =IF(H13="","",H13*K13) | O13: ='Price Book'!AG6
A14: ='Price Book'!A7 | B14: ='Price Book'!B7 | C14: ='Price Book'!C7 | D14: ='Price Book'!D7 | E14: ='Price Book'!G7 | F14: ='Price Book'!I7 | G14: ='Price Book'!L7 | H14: ='Price Book'!M7 | I14: ='Price Book'!Q7 | J14: ='Price Book'!R7 | K14: 1 | L14: =IFERROR(F14*K14,"") | M14: =IFERROR(G14*K14,"") | N14: =IF(H14="","",H14*K14) | O14: ='Price Book'!AG7
A15: ='Price Book'!A8 | B15: ='Price Book'!B8 | C15: ='Price Book'!C8 | D15: ='Price Book'!D8 | E15: ='Price Book'!G8 | F15: ='Price Book'!I8 | G15: ='Price Book'!L8 | H15: ='Price Book'!M8 | I15: ='Price Book'!Q8 | J15: ='Price Book'!R8 | K15: 1 | L15: =IFERROR(F15*K15,"") | M15: =IFERROR(G15*K15,"") | N15: =IF(H15="","",H15*K15) | O15: ='Price Book'!AG8
A16: ='Price Book'!A9 | B16: ='Price Book'!B9 | C16: ='Price Book'!C9 | D16: ='Price Book'!D9 | E16: ='Price Book'!G9 | F16: ='Price Book'!I9 | G16: ='Price Book'!L9 | H16: ='Price Book'!M9 | I16: ='Price Book'!Q9 | J16: ='Price Book'!R9 | K16: 1 | L16: =IFERROR(F16*K16,"") | M16: =IFERROR(G16*K16,"") | N16: =IF(H16="","",H16*K16) | O16: ='Price Book'!AG9
A17: ='Price Book'!A10 | B17: ='Price Book'!B10 | C17: ='Price Book'!C10 | D17: ='Price Book'!D10 | E17: ='Price Book'!G10 | F17: ='Price Book'!I10 | G17: ='Price Book'!L10 | H17: ='Price Book'!M10 | I17: ='Price Book'!Q10 | J17: ='Price Book'!R10 | K17: 1 | L17: =IFERROR(F17*K17,"") | M17: =IFERROR(G17*K17,"") | N17: =IF(H17="","",H17*K17) | O17: ='Price Book'!AG10
A18: ='Price Book'!A11 | B18: ='Price Book'!B11 | C18: ='Price Book'!C11 | D18: ='Price Book'!D11 | E18: ='Price Book'!G11 | F18: ='Price Book'!I11 | G18: ='Price Book'!L11 | H18: ='Price Book'!M11 | I18: ='Price Book'!Q11 | J18: ='Price Book'!R11 | K18: 1 | L18: =IFERROR(F18*K18,"") | M18: =IFERROR(G18*K18,"") | N18: =IF(H18="","",H18*K18) | O18: ='Price Book'!AG11
A19: ='Price Book'!A12 | B19: ='Price Book'!B12 | C19: ='Price Book'!C12 | D19: ='Price Book'!D12 | E19: ='Price Book'!G12 | F19: ='Price Book'!I12 | G19: ='Price Book'!L12 | H19: ='Price Book'!M12 | I19: ='Price Book'!Q12 | J19: ='Price Book'!R12 | K19: 1 | L19: =IFERROR(F19*K19,"") | M19: =IFERROR(G19*K19,"") | N19: =IF(H19="","",H19*K19) | O19: ='Price Book'!AG12
A20: ='Price Book'!A13 | B20: ='Price Book'!B13 | C20: ='Price Book'!C13 | D20: ='Price Book'!D13 | E20: ='Price Book'!G13 | F20: ='Price Book'!I13 | G20: ='Price Book'!L13 | H20: ='Price Book'!M13 | I20: ='Price Book'!Q13 | J20: ='Price Book'!R13 | K20: 1 | L20: =IFERROR(F20*K20,"") | M20: =IFERROR(G20*K20,"") | N20: =IF(H20="","",H20*K20) | O20: ='Price Book'!AG13
A21: ='Price Book'!A14 | B21: ='Price Book'!B14 | C21: ='Price Book'!C14 | D21: ='Price Book'!D14 | E21: ='Price Book'!G14 | F21: ='Price Book'!I14 | G21: ='Price Book'!L14 | H21: ='Price Book'!M14 | I21: ='Price Book'!Q14 | J21: ='Price Book'!R14 | K21: 1 | L21: =IFERROR(F21*K21,"") | M21: =IFERROR(G21*K21,"") | N21: =IF(H21="","",H21*K21) | O21: ='Price Book'!AG14
A22: ='Price Book'!A15 | B22: ='Price Book'!B15 | C22: ='Price Book'!C15 | D22: ='Price Book'!D15 | E22: ='Price Book'!G15 | F22: ='Price Book'!I15 | G22: ='Price Book'!L15 | H22: ='Price Book'!M15 | I22: ='Price Book'!Q15 | J22: ='Price Book'!R15 | K22: 1 | L22: =IFERROR(F22*K22,"") | M22: =IFERROR(G22*K22,"") | N22: =IF(H22="","",H22*K22) | O22: ='Price Book'!AG15
A23: ='Price Book'!A16 | B23: ='Price Book'!B16 | C23: ='Price Book'!C16 | D23: ='Price Book'!D16 | E23: ='Price Book'!G16 | F23: ='Price Book'!I16 | G23: ='Price Book'!L16 | H23: ='Price Book'!M16 | I23: ='Price Book'!Q16 | J23: ='Price Book'!R16 | K23: 1 | L23: =IFERROR(F23*K23,"") | M23: =IFERROR(G23*K23,"") | N23: =IF(H23="","",H23*K23) | O23: ='Price Book'!AG16
... A121: ='Price Book'!A114 | B121: ='Price Book'!B114 | C121: ='Price Book'!C114 | D121: ='Price Book'!D114 | E121: ='Price Book'!G114 | F121: ='Price Book'!I114 | G121: ='Price Book'!L114 | H121: ='Price Book'!M114 | I121: ='Price Book'!Q114 | J121: ='Price Book'!R114 | K121: 1 | L121: =IFERROR(F121*K121,"") | M121: =IFERROR(G121*K121,"") | N121: =IF(H121="","",H121*K121) | O121: ='Price Book'!AG114
