Workbook

Sheet dda departments
A1: # | B1: Company Name | C1: Status | D1: License Volume as of 2026 | E1: Recurring
A2: 1 | B2: Central Grievance Committee
A3: 2 | B3: Community Development Authority | C3: In progress
A4: 3 | B4: Dubai Courts | C4: In progress
A5: 4 | B5: Department of Economic Development
A6: 5 | B6: Department of Economy and Tourism
A7: 6 | B7: Department of Finance | C7: In progress
A8: 7 | B8: Department of Tourism and Commerce Marketing
A9: 8 | B9: Digital Dubai Authority | C9: Customer | D9: VIP Project (50 users) | E9: VIP Project - 163,201.60 (Subscription) + 63,397.00 AED (Support Services)
B10: Digital Dubai Authority | C10: Customer | D10: Shared Sign (100 users) | E10: Shared Sign - 293,444.33 (Subscription) + 75,000.00 (Support Services)
A11: 9 | B11: Directorate General of Dubai Civil Defense
A12: 10 | B12: Dubai Academic Health Corporation
A13: 11 | B13: Dubai Air Navigation Services
A14: 12 | B14: Dubai Airport Freezone
A15: 13 | B15: Dubai Airports
A16: 14 | B16: Dubai Chambers
A17: 15 | B17: Dubai Civil Aviaition Authority
A18: 16 | B18: Dubai Civil Defence
A19: 17 | B19: Dubai Corporation for Ambulances Services | C19: Customer | D19: Business, 10k transactions (while having 275 registered users) | E19: 147,268.13 AED (end user)
A20: 18 | B20: Dubai Corporation for Aviation Engineering Projects | C20: In progress
A21: 19 | B21: Dubai Culture & Arts Authority | C21: Customer | D21: DigiSign, 25 users | E21: 110,988.75 AED
A22: 20 | B22: Dubai Customs | C22: In progress
A23: 21 | B23: Dubai Duty Free
A24: 22 | B24: Dubai Economy and Tourism | C24: Lost
A25: 23 | B25: Dubai Electricity & Water Authority (DEWA) | C25: In progress
A26: 24 | B26: Dubai Electronic Security Center | C26: Customer | D26: Ultimate, 60 users | E26: 234,635.43 AED
A27: 25 | B27: Dubai Export Development Coroporation
A28: 26 | B28: Dubai Financial Market (DFM)
A29: 27 | B29: Dubai Foundation for Women and Children
A30: 28 | B30: Dubai Future Foundation
A31: 29 | B31: Dubai Government Human Resource Department
A32: 30 | B32: Dubai Government Workshop
A33: 31 | B33: Dubai Health | C33: In progress
A34: 32 | B34: Dubai Health Authority (DHA) | C34: In progress
A35: 33 | B35: Dubai International Financial Centre (DIFC) | C35: Docusign
A36: 34 | B36: Dubai Islamic Economy Development Centre
A37: 35 | B37: Dubai Judicial Institute
A38: 36 | B38: Dubai Land Department (DLD) | C38: important
A39: 37 | B39: Dubai Maritime City Authority
A40: 38 | B40: Dubai Media Council
...

Sheet pricing
C1: DDA Shared Service Special Discount | D1: DDA Shared Service Discount Tier Discount
C2: 20,00% | D2: 5,00% | E2: 5,00% | F2: 10,00% | G2: 10,00% | H2: 15,00%
C3: Total Discount | D3: 25,00% | E3: 30,00% | F3: 40,00% | G3: 50,00% | H3: 60,00%
D4: Tier 1 | E4: Tier 2 | F4: Tier 3 | G4: Tier 4 | H4: Tier 5
B5: End Discounted User Price (Annual Subscription) | C5: Enteprise DDA Shared Service Price | D5: Min 100 users up to 499 users | E5: Min 500 users up to 999 users | F5: Min 1000 users up to 1999 users | G5: Min 2000 users up to 2999 users | H5: Min 3000 users
A6: Regular Users (unlimited transactions) price per user per year in AED | B6: AED 2 950 | C6: AED 2 360 | D6: AED 2 213 | E6: AED 2 065 | F6: AED 1 770 | G6: AED 1 475 | H6: =2950*0.4 -> 1180
D14: Min 10 000 transactions up to 39 999 transactions | E14: Min 40 000 transactions up to 99 999 transactions | F14: Min 100 000 transactions up to 299 999 transactions | G14: Min 300 000 transactions up to 799 999 transactions | H14: Min 800 000 transactions
A15: API Transaction price in AED | B15: AED 10,50 | C15: AED 8,40 | D15: AED 7,88 | E15: AED 7,35 | F15: AED 6,30 | G15: AED 5,25 | H15: AED 3,68
A18: Supporting Hours | C18: Min. annual support costs
A19: Plus Support Plan 8x5: 8 hours (8:30 am to 4:30 pm Central European Time) 5 days (Monday to Friday, excluding Non-Support Days) | C19: AED 55 000 | D19: AED 55 000 | E19: AED 144 550 | F19: AED 247 800 | G19: AED 413 000 | H19: AED 433 650
A20: Plus Support Plan 24x7: 24 hours excluding Non-Support Days | C20: AED 75 000 | D20: AED 75 000 | E20: AED 206 500 | F20: AED 354 000 | G20: AED 590 000 | H20: AED 619 500
A22: One time onboarding fees per organisation | C22: AED 25 000
A24: Other modules available : | B24: DMS, eCorrespondence
B26: Sample Calculation | C26: Purchased Users | D26: Purchase Price
B27: 1st Purchase Order - 150 Users | C27: 150 | D27: AED 331 875
B28: 2nd Purchase Order 550 User | C28: 550 | D28: AED 1 135 750
B29: Total Subscription Value | C29: 700 | D29: AED 1 467 625
B31: Note: Renewals are calculated based on total subscription value at the time of initial purchase as shown above

Sheet Sheet4

Sheet survey 2026
A1: # | B1: Survey Question | C1: Response | D1: Responses | E1: %
A2: 1 | B2: Does your organization currently use a digital/electronic signature system? | C2: Yes | D2: 21 | E2: 0.5526
C3: No | D3: 10 | E3: 0.2632
C4: Under planning | D4: 6 | E4: 0.1579
C5: Under implementation | D5: 1 | E5: 0.0263
C6: Total | D6: 38 | E6: 1
A7: 2 | B7: Which digital signature system is currently used / being implemented? | C7: Circularo Digital Sign | D7: 6 | E7: 0.2727
C8: Adobe Sign | D8: 5 | E8: 0.2273
C9: DocuSign | D9: 2 | E9: 0.0909
C10: Other | D10: 9 | E10: 0.4091
C11: Total | D11: 22 | E11: 1
A12: 2a | B12: Other systems specified | C12: d2tick | D12: 2 | E12: —
C13: signeasy | D13: 2 | E13: —
C14: Ascertia SigningHub | D14: 1 | E14: —
C15: DocuSign & Adobe Sign | D15: 1 | E15: —
C16: emSigner | D16: 1 | E16: —
C17: Kofax SignDoc | D17: 1 | E17: —
C18: Tungsten (Kofax) SignDoc | D18: 1 | E18: —
A19: 3 | B19: Current / expected number of digital signature users when implementation is complete | C19: 1–50 users | D19: 6 | E19: 0.2727
C20: 51–100 users | D20: 4 | E20: 0.1818
C21: 101–500 users | D21: 7 | E21: 0.3182
C22: More than 1,000 users | D22: 4 | E22: 0.1818
C23: Other | D23: 1 | E23: 0.0455
C24: Total | D24: 22 | E24: 1
A25: 4 | B25: Approximate annual cost of the current / expected digital signature system | C25: Less than AED 50,000 | D25: 7 | E25: 0.3182
C26: AED 50,001–100,000 | D26: 6 | E26: 0.2727
C27: AED 100,001–250,000 | D27: 6 | E27: 0.2727
C28: AED 250,001–500,000 | D28: 1 | E28: 0.0455
C29: More than AED 2,000,000 | D29: 1 | E29: 0.0455
C30: Not available / unknown | D30: 1 | E30: 0.0455
C31: Total | D31: 22 | E31: 1
A32: 5 | B32: Do you expect digital signature usage to increase in the future? | C32: Yes – moderate increase expected | D32: 11 | E32: 0.5
C33: Yes – significant increase expected | D33: 6 | E33: 0.2727
C34: Unsure / to be determined | D34: 1 | E34: 0.0455
C35: No – expected to remain approximately the same | D35: 4 | E35: 0.1818
C36: Total | D36: 22 | E36: 1
A37: 6 | B37: What factors are expected to drive this increase? | C37: Increase in number of users | D37: 13 | E37: 0.7647
C38: Expansion to additional departments | D38: 10 | E38: 0.5882
C39: Increased external signing with suppliers, partners, customers/public | D39: 10 | E39: 0.5882
C40: New document types / new use cases | D40: 9 | E40: 0.5294
...

Sheet Executive Summary
A1: Digital Dubai – Central Digital Signature Licensing Model
A3: Entities in master list | B3: 91
A4: Estimated employees | B4: ='91 Entities Model'!D93 -> 165227
A5: Estimated potential digital-sign users | B5: ='91 Entities Model'!G93 -> 61482
A6: Central Tier 5 price / user | B6: 1180
A7: Annual fragmented license cost | B7: ='91 Entities Model'!K93 -> 102939175
A8: Annual central Tier 5 cost | B8: ='91 Entities Model'!L93 -> 72548760
A9: Annual saving | B9: ='91 Entities Model'!M93 -> 30390415
A10: 5-year saving vs fragmented tiers | B10: ='91 Entities Model'!N93 -> 151952075
A11: 5-year saving vs AED 2,950 regular price | B11: ='91 Entities Model'!O93 -> 362743800
A13: Investor revenue opportunity (eSign + adjacent products) | B13: Potential Value
A14: Potential annual eSign revenue | B14: ='Investor Deal Potential'!B9 -> 72548760
A15: Additional storage + collaboration + AI revenue (~50%) | B15: ='Investor Deal Potential'!B11 -> 36274380
A16: Potential annual total revenue | B16: ='Investor Deal Potential'!B12 -> 108823140
A17: Potential 5-year total deal value | B17: ='Investor Deal Potential'!B15 -> 544115700
A19: Product opportunity: eSign is the core subscription. Secure document storage, collaboration and AI can add approximately 50% revenue on top of eSign, creating a broader sovereign digital-workspace opportunity. The 50% uplift is an illustrative commercial assumption for investor sizing, not committed revenue.
A22: Important: employee counts marked as planning estimates should be validated before external/client use. The model is designed for management sizing and can be updated as official figures are confirmed.

Sheet Investor Deal Potential
A1: Digital Dubai – Investor Deal Potential
A2: Potential 5-year revenue opportunity across the 91-entity Dubai Government portfolio
A4: Portfolio sizing | B4: Value | C4: Notes
A5: Entities in addressable portfolio | B5: ='Executive Summary'!B3 -> 91 | C5: 91 entities in current master list
A6: Estimated employees | B6: ='91 Entities Model'!D93 -> 165227 | C6: Planning estimate / published figures where available
A7: Potential eSign users | B7: ='91 Entities Model'!G93 -> 61482 | C7: Addressable digital-signature users from current model
A8: eSign price per user / year | B8: ='Pricing & Assumptions'!B9 -> 1180 | C8: Tier 5 centralized DDA shared-service price
A9: Potential annual eSign revenue | B9: =B7*B8 -> 72548760 | C9: Core eSign subscription
A10: Adjacent product revenue uplift | B10: 0.5 | C10: Secure document storage + collaboration + AI
A11: Potential annual adjacent revenue | B11: =B9*B10 -> 36274380 | C11: Approx. 50% additional revenue opportunity
A12: Potential annual total revenue | B12: =B9+B11 -> 108823140 | C12: eSign + adjacent products
A13: Potential 5-year eSign revenue | B13: =B9*5 -> 362743800 | C13: Before inflation / expansion
A14: Potential 5-year adjacent revenue | B14: =B11*5 -> 181371900 | C14: Storage + collaboration + AI
A15: Potential 5-year total deal value | B15: =B12*5 -> 544115700 | C15: Illustrative revenue opportunity
A18: Scale illustration
A19: Potential Users | B19: Annual eSign Revenue | C19: Adjacent Products (+50%) | D19: Annual Total Revenue | E19: 5-Year Total Revenue
A20: 3000 | B20: =A20*$B$8 -> 3540000 | C20: =B20*$B$10 -> 1770000 | D20: =B20+C20 -> 5310000 | E20: =D20*5 -> 26550000
A21: 5000 | B21: =A21*$B$8 -> 5900000 | C21: =B21*$B$10 -> 2950000 | D21: =B21+C21 -> 8850000 | E21: =D21*5 -> 44250000
A22: 10000 | B22: =A22*$B$8 -> 11800000 | C22: =B22*$B$10 -> 5900000 | D22: =B22+C22 -> 17700000 | E22: =D22*5 -> 88500000
A23: 25000 | B23: =A23*$B$8 -> 29500000 | C23: =B23*$B$10 -> 14750000 | D23: =B23+C23 -> 44250000 | E23: =D23*5 -> 221250000
A24: Current model potential | B24: =A24*$B$8 -> #VALUE! | C24: =B24*$B$10 -> #VALUE! | D24: =B24+C24 -> #VALUE! | E24: =D24*5 -> #VALUE!
A27: Investor framing: eSign is the core product. Secure document storage, collaboration and AI represent an estimated additional revenue opportunity of approximately 50% on top of eSign revenue. This is an illustrative commercial sizing assumption, not committed revenue, and excludes implementation, support, VAT, inflation and future user growth.

Sheet 91 Entities Model
A1: # | B1: Entity | C1: Status | D1: Estimated Employees | E1: Employee Figure Basis | F1: Potential Sign Users % | G1: Potential Digital Sign Users | H1: Known Current Users | I1: Current Fragmented Price / User (AED) | J1: Central Tier 5 Price / User (AED) | K1: Annual Cost - Fragmented (AED) | L1: Annual Cost - Central Tier 5 (AED) | M1: Annual Saving (AED) | N1: 5-Year Saving (AED) | O1: 5-Year Saving vs Regular AED 2,950 | P1: Source / Note
A2: 1 | B2: Central Grievance Committee | D2: 80 | E2: Planning estimate – validate with entity | F2: 0.5 | G2: =ROUND(D2*F2,0) -> 40 | I2: =IF(G2<100,2950,IF(G2<500,2213,IF(G2<1000,2065,IF(G2<2000,1770,IF(G2<3000,1475,1180))))) -> 2950 | J2: ='Pricing & Assumptions'!$B$9 -> 1180 | K2: =G2*I2 -> 118000 | L2: =G2*J2 -> 47200 | M2: =K2-L2 -> 70800 | N2: =M2*5 -> 354000 | O2: =G2*('Pricing & Assumptions'!$B$3-'Pricing & Assumptions'!$B$9)*5 -> 236000 | P2: Indicative planning estimate; replace with official headcount when available
A3: 2 | B3: Community Development Authority | C3: In progress | D3: 500 | E3: Planning estimate – validate with entity | F3: 0.5 | G3: =ROUND(D3*F3,0) -> 250 | I3: =IF(G3<100,2950,IF(G3<500,2213,IF(G3<1000,2065,IF(G3<2000,1770,IF(G3<3000,1475,1180))))) -> 2213 | J3: ='Pricing & Assumptions'!$B$9 -> 1180 | K3: =G3*I3 -> 553250 | L3: =G3*J3 -> 295000 | M3: =K3-L3 -> 258250 | N3: =M3*5 -> 1291250 | O3: =G3*('Pricing & Assumptions'!$B$3-'Pricing & Assumptions'!$B$9)*5 -> 1475000 | P3: Indicative planning estimate; replace with official headcount when available
A4: 3 | B4: Dubai Courts | C4: In progress | D4: 1410 | E4: Planning estimate – validate with entity | F4: 0.7 | G4: =ROUND(D4*F4,0) -> 987 | I4: =IF(G4<100,2950,IF(G4<500,2213,IF(G4<1000,2065,IF(G4<2000,1770,IF(G4<3000,1475,1180))))) -> 2065 | J4: ='Pricing & Assumptions'!$B$9 -> 1180 | K4: =G4*I4 -> 2038155 | L4: =G4*J4 -> 1164660 | M4: =K4-L4 -> 873495 | N4: =M4*5 -> 4367475 | O4: =G4*('Pricing & Assumptions'!$B$3-'Pricing & Assumptions'!$B$9)*5 -> 5823300 | P4: Indicative planning estimate; replace with official headcount when available
A5: 4 | B5: Department of Economic Development | D5: 900 | E5: Planning estimate – validate with entity | F5: 0.5 | G5: =ROUND(D5*F5,0) -> 450 | I5: =IF(G5<100,2950,IF(G5<500,2213,IF(G5<1000,2065,IF(G5<2000,1770,IF(G5<3000,1475,1180))))) -> 2213 | J5: ='Pricing & Assumptions'!$B$9 -> 1180 | K5: =G5*I5 -> 995850 | L5: =G5*J5 -> 531000 | M5: =K5-L5 -> 464850 | N5: =M5*5 -> 2324250 | O5: =G5*('Pricing & Assumptions'!$B$3-'Pricing & Assumptions'!$B$9)*5 -> 2655000 | P5: Indicative planning estimate; replace with official headcount when available
A6: 5 | B6: Department of Economy and Tourism | D6: 1200 | E6: Planning estimate – validate with entity | F6: 0.5 | G6: =ROUND(D6*F6,0) -> 600 | I6: =IF(G6<100,2950,IF(G6<500,2213,IF(G6<1000,2065,IF(G6<2000,1770,IF(G6<3000,1475,1180))))) -> 2065 | J6: ='Pricing & Assumptions'!$B$9 -> 1180 | K6: =G6*I6 -> 1239000 | L6: =G6*J6 -> 708000 | M6: =K6-L6 -> 531000 | N6: =M6*5 -> 2655000 | O6: =G6*('Pricing & Assumptions'!$B$3-'Pricing & Assumptions'!$B$9)*5 -> 3540000 | P6: Indicative planning estimate; replace with official headcount when available
A7: 6 | B7: Department of Finance | C7: In progress | D7: 350 | E7: Planning estimate – validate with entity | F7: 0.7 | G7: =ROUND(D7*F7,0) -> 245 | I7: =IF(G7<100,2950,IF(G7<500,2213,IF(G7<1000,2065,IF(G7<2000,1770,IF(G7<3000,1475,1180))))) -> 2213 | J7: ='Pricing & Assumptions'!$B$9 -> 1180 | K7: =G7*I7 -> 542185 | L7: =G7*J7 -> 289100 | M7: =K7-L7 -> 253085 | N7: =M7*5 -> 1265425 | O7: =G7*('Pricing & Assumptions'!$B$3-'Pricing & Assumptions'!$B$9)*5 -> 1445500 | P7: Indicative planning estimate; replace with official headcount when available
A8: 7 | B8: Department of Tourism and Commerce Marketing | D8: 600 | E8: Planning estimate – validate with entity | F8: 0.5 | G8: =ROUND(D8*F8,0) -> 300 | I8: =IF(G8<100,2950,IF(G8<500,2213,IF(G8<1000,2065,IF(G8<2000,1770,IF(G8<3000,1475,1180))))) -> 2213 | J8: ='Pricing & Assumptions'!$B$9 -> 1180 | K8: =G8*I8 -> 663900 | L8: =G8*J8 -> 354000 | M8: =K8-L8 -> 309900 | N8: =M8*5 -> 1549500 | O8: =G8*('Pricing & Assumptions'!$B$3-'Pricing & Assumptions'!$B$9)*5 -> 1770000 | P8: Indicative planning estimate; replace with official headcount when available
A9: 8 | B9: Digital Dubai Authority | C9: Customer | D9: 700 | E9: Planning estimate – validate with entity | F9: 0.7 | G9: =ROUND(D9*F9,0) -> 490 | H9: 150 | I9: =IF(G9<100,2950,IF(G9<500,2213,IF(G9<1000,2065,IF(G9<2000,1770,IF(G9<3000,1475,1180))))) -> 2213 | J9: ='Pricing & Assumptions'!$B$9 -> 1180 | K9: =G9*I9 -> 1084370 | L9: =G9*J9 -> 578200 | M9: =K9-L9 -> 506170 | N9: =M9*5 -> 2530850 | O9: =G9*('Pricing & Assumptions'!$B$3-'Pricing & Assumptions'!$B$9)*5 -> 2891000 | P9: Indicative planning estimate; replace with official headcount when available
A10: 9 | B10: Directorate General of Dubai Civil Defense | D10: 3000 | E10: Planning estimate – validate with entity | F10: 0.3 | G10: =ROUND(D10*F10,0) -> 900 | I10: =IF(G10<100,2950,IF(G10<500,2213,IF(G10<1000,2065,IF(G10<2000,1770,IF(G10<3000,1475,1180))))) -> 2065 | J10: ='Pricing & Assumptions'!$B$9 -> 1180 | K10: =G10*I10 -> 1858500 | L10: =G10*J10 -> 1062000 | M10: =K10-L10 -> 796500 | N10: =M10*5 -> 3982500 | O10: =G10*('Pricing & Assumptions'!$B$3-'Pricing & Assumptions'!$B$9)*5 -> 5310000 | P10: Indicative planning estimate; replace with official headcount when available
A11: 10 | B11: Dubai Academic Health Corporation | D11: 12000 | E11: Planning estimate – validate with entity | F11: 0.3 | G11: =ROUND(D11*F11,0) -> 3600 | I11: =IF(G11<100,2950,IF(G11<500,2213,IF(G11<1000,2065,IF(G11<2000,1770,IF(G11<3000,1475,1180))))) -> 1180 | J11: ='Pricing & Assumptions'!$B$9 -> 1180 | K11: =G11*I11 -> 4248000 | L11: =G11*J11 -> 4248000 | M11: =K11-L11 -> 0 | N11: =M11*5 -> 0 | O11: =G11*('Pricing & Assumptions'!$B$3-'Pricing & Assumptions'!$B$9)*5 -> 21240000 | P11: Indicative planning estimate; replace with official headcount when available
A12: 11 | B12: Dubai Air Navigation Services | D12: 1500 | E12: Planning estimate – validate with entity | F12: 0.5 | G12: =ROUND(D12*F12,0) -> 750 | I12: =IF(G12<100,2950,IF(G12<500,2213,IF(G12<1000,2065,IF(G12<2000,1770,IF(G12<3000,1475,1180))))) -> 2065 | J12: ='Pricing & Assumptions'!$B$9 -> 1180 | K12: =G12*I12 -> 1548750 | L12: =G12*J12 -> 885000 | M12: =K12-L12 -> 663750 | N12: =M12*5 -> 3318750 | O12: =G12*('Pricing & Assumptions'!$B$3-'Pricing & Assumptions'!$B$9)*5 -> 4425000 | P12: Indicative planning estimate; replace with official headcount when available
A13: 12 | B13: Dubai Airport Freezone | D13: 700 | E13: Planning estimate – validate with entity | F13: 0.5 | G13: =ROUND(D13*F13,0) -> 350 | I13: =IF(G13<100,2950,IF(G13<500,2213,IF(G13<1000,2065,IF(G13<2000,1770,IF(G13<3000,1475,1180))))) -> 2213 | J13: ='Pricing & Assumptions'!$B$9 -> 1180 | K13: =G13*I13 -> 774550 | L13: =G13*J13 -> 413000 | M13: =K13-L13 -> 361550 | N13: =M13*5 -> 1807750 | O13: =G13*('Pricing & Assumptions'!$B$3-'Pricing & Assumptions'!$B$9)*5 -> 2065000 | P13: Indicative planning estimate; replace with official headcount when available
A14: 13 | B14: Dubai Airports | D14: 3000 | E14: Published profile (older) | F14: 0.3 | G14: =ROUND(D14*F14,0) -> 900 | I14: =IF(G14<100,2950,IF(G14<500,2213,IF(G14<1000,2065,IF(G14<2000,1770,IF(G14<3000,1475,1180))))) -> 2065 | J14: ='Pricing & Assumptions'!$B$9 -> 1180 | K14: =G14*I14 -> 1858500 | L14: =G14*J14 -> 1062000 | M14: =K14-L14 -> 796500 | N14: =M14*5 -> 3982500 | O14: =G14*('Pricing & Assumptions'!$B$3-'Pricing & Assumptions'!$B$9)*5 -> 5310000 | P14: https://summit-events.com/assets/files/PDS19_Programme_FINAL_UPDATE.pdf
A15: 14 | B15: Dubai Chambers | D15: 500 | E15: Planning estimate – validate with entity | F15: 0.7 | G15: =ROUND(D15*F15,0) -> 350 | I15: =IF(G15<100,2950,IF(G15<500,2213,IF(G15<1000,2065,IF(G15<2000,1770,IF(G15<3000,1475,1180))))) -> 2213 | J15: ='Pricing & Assumptions'!$B$9 -> 1180 | K15: =G15*I15 -> 774550 | L15: =G15*J15 -> 413000 | M15: =K15-L15 -> 361550 | N15: =M15*5 -> 1807750 | O15: =G15*('Pricing & Assumptions'!$B$3-'Pricing & Assumptions'!$B$9)*5 -> 2065000 | P15: Indicative planning estimate; replace with official headcount when available
A16: 15 | B16: Dubai Civil Aviaition Authority | D16: 500 | E16: Planning estimate – validate with entity | F16: 0.5 | G16: =ROUND(D16*F16,0) -> 250 | I16: =IF(G16<100,2950,IF(G16<500,2213,IF(G16<1000,2065,IF(G16<2000,1770,IF(G16<3000,1475,1180))))) -> 2213 | J16: ='Pricing & Assumptions'!$B$9 -> 1180 | K16: =G16*I16 -> 553250 | L16: =G16*J16 -> 295000 | M16: =K16-L16 -> 258250 | N16: =M16*5 -> 1291250 | O16: =G16*('Pricing & Assumptions'!$B$3-'Pricing & Assumptions'!$B$9)*5 -> 1475000 | P16: Indicative planning estimate; replace with official headcount when available
A17: 16 | B17: Dubai Civil Defence | D17: 3000 | E17: Planning estimate – validate with entity | F17: 0.3 | G17: =ROUND(D17*F17,0) -> 900 | I17: =IF(G17<100,2950,IF(G17<500,2213,IF(G17<1000,2065,IF(G17<2000,1770,IF(G17<3000,1475,1180))))) -> 2065 | J17: ='Pricing & Assumptions'!$B$9 -> 1180 | K17: =G17*I17 -> 1858500 | L17: =G17*J17 -> 1062000 | M17: =K17-L17 -> 796500 | N17: =M17*5 -> 3982500 | O17: =G17*('Pricing & Assumptions'!$B$3-'Pricing & Assumptions'!$B$9)*5 -> 5310000 | P17: Indicative planning estimate; replace with official headcount when available
A18: 17 | B18: Dubai Corporation for Ambulances Services | C18: Customer | D18: 1400 | E18: Planning estimate – validate with entity | F18: 0.3 | G18: =ROUND(D18*F18,0) -> 420 | H18: 275 | I18: =IF(G18<100,2950,IF(G18<500,2213,IF(G18<1000,2065,IF(G18<2000,1770,IF(G18<3000,1475,1180))))) -> 2213 | J18: ='Pricing & Assumptions'!$B$9 -> 1180 | K18: =G18*I18 -> 929460 | L18: =G18*J18 -> 495600 | M18: =K18-L18 -> 433860 | N18: =M18*5 -> 2169300 | O18: =G18*('Pricing & Assumptions'!$B$3-'Pricing & Assumptions'!$B$9)*5 -> 2478000 | P18: Indicative planning estimate; replace with official headcount when available
A19: 18 | B19: Dubai Corporation for Aviation Engineering Projects | C19: In progress | D19: 500 | E19: Planning estimate – validate with entity | F19: 0.5 | G19: =ROUND(D19*F19,0) -> 250 | I19: =IF(G19<100,2950,IF(G19<500,2213,IF(G19<1000,2065,IF(G19<2000,1770,IF(G19<3000,1475,1180))))) -> 2213 | J19: ='Pricing & Assumptions'!$B$9 -> 1180 | K19: =G19*I19 -> 553250 | L19: =G19*J19 -> 295000 | M19: =K19-L19 -> 258250 | N19: =M19*5 -> 1291250 | O19: =G19*('Pricing & Assumptions'!$B$3-'Pricing & Assumptions'!$B$9)*5 -> 1475000 | P19: Indicative planning estimate; replace with official headcount when available
A20: 19 | B20: Dubai Culture & Arts Authority | C20: Customer | D20: 500 | E20: Planning estimate – validate with entity | F20: 0.7 | G20: =ROUND(D20*F20,0) -> 350 | H20: 25 | I20: =IF(G20<100,2950,IF(G20<500,2213,IF(G20<1000,2065,IF(G20<2000,1770,IF(G20<3000,1475,1180))))) -> 2213 | J20: ='Pricing & Assumptions'!$B$9 -> 1180 | K20: =G20*I20 -> 774550 | L20: =G20*J20 -> 413000 | M20: =K20-L20 -> 361550 | N20: =M20*5 -> 1807750 | O20: =G20*('Pricing & Assumptions'!$B$3-'Pricing & Assumptions'!$B$9)*5 -> 2065000 | P20: Indicative planning estimate; replace with official headcount when available
A21: 20 | B21: Dubai Customs | C21: In progress | D21: 2880 | E21: Published | F21: 0.5 | G21: =ROUND(D21*F21,0) -> 1440 | I21: =IF(G21<100,2950,IF(G21<500,2213,IF(G21<1000,2065,IF(G21<2000,1770,IF(G21<3000,1475,1180))))) -> 1770 | J21: ='Pricing & Assumptions'!$B$9 -> 1180 | K21: =G21*I21 -> 2548800 | L21: =G21*J21 -> 1699200 | M21: =K21-L21 -> 849600 | N21: =M21*5 -> 4248000 | O21: =G21*('Pricing & Assumptions'!$B$3-'Pricing & Assumptions'!$B$9)*5 -> 8496000 | P21: https://www.dubaicustoms.gov.ae/en/SocialResponsibility/Csr/OurEmployees/Pages/default.aspx
A22: 21 | B22: Dubai Duty Free | D22: 5800 | E22: Published 2025 | F22: 0.3 | G22: =ROUND(D22*F22,0) -> 1740 | I22: =IF(G22<100,2950,IF(G22<500,2213,IF(G22<1000,2065,IF(G22<2000,1770,IF(G22<3000,1475,1180))))) -> 1770 | J22: ='Pricing & Assumptions'!$B$9 -> 1180 | K22: =G22*I22 -> 3079800 | L22: =G22*J22 -> 2053200 | M22: =K22-L22 -> 1026600 | N22: =M22*5 -> 5133000 | O22: =G22*('Pricing & Assumptions'!$B$3-'Pricing & Assumptions'!$B$9)*5 -> 10266000 | P22: https://icd.gov.ae/wp-content/uploads/2025/11/ICD-AR2025-Full-Report-2.pdf
A23: 22 | B23: Dubai Economy and Tourism | C23: Lost | D23: 1200 | E23: Planning estimate – validate with entity | F23: 0.5 | G23: =ROUND(D23*F23,0) -> 600 | I23: =IF(G23<100,2950,IF(G23<500,2213,IF(G23<1000,2065,IF(G23<2000,1770,IF(G23<3000,1475,1180))))) -> 2065 | J23: ='Pricing & Assumptions'!$B$9 -> 1180 | K23: =G23*I23 -> 1239000 | L23: =G23*J23 -> 708000 | M23: =K23-L23 -> 531000 | N23: =M23*5 -> 2655000 | O23: =G23*('Pricing & Assumptions'!$B$3-'Pricing & Assumptions'!$B$9)*5 -> 3540000 | P23: Indicative planning estimate; replace with official headcount when available
A24: 23 | B24: Dubai Electricity & Water Authority (DEWA) | C24: In progress | D24: 10722 | E24: Published 2024 | F24: 0.3 | G24: =ROUND(D24*F24,0) -> 3217 | I24: =IF(G24<100,2950,IF(G24<500,2213,IF(G24<1000,2065,IF(G24<2000,1770,IF(G24<3000,1475,1180))))) -> 1180 | J24: ='Pricing & Assumptions'!$B$9 -> 1180 | K24: =G24*I24 -> 3796060 | L24: =G24*J24 -> 3796060 | M24: =K24-L24 -> 0 | N24: =M24*5 -> 0 | O24: =G24*('Pricing & Assumptions'!$B$3-'Pricing & Assumptions'!$B$9)*5 -> 18980300 | P24: https://www.dewa.gov.ae/-/media/Images/Investor-Relations/Integrated-reports/Integrated_report_for_the_year_2024.ashx
A25: 24 | B25: Dubai Electronic Security Center | C25: Customer | D25: 250 | E25: Planning estimate – validate with entity | F25: 0.7 | G25: =ROUND(D25*F25,0) -> 175 | H25: 60 | I25: =IF(G25<100,2950,IF(G25<500,2213,IF(G25<1000,2065,IF(G25<2000,1770,IF(G25<3000,1475,1180))))) -> 2213 | J25: ='Pricing & Assumptions'!$B$9 -> 1180 | K25: =G25*I25 -> 387275 | L25: =G25*J25 -> 206500 | M25: =K25-L25 -> 180775 | N25: =M25*5 -> 903875 | O25: =G25*('Pricing & Assumptions'!$B$3-'Pricing & Assumptions'!$B$9)*5 -> 1032500 | P25: Indicative planning estimate; replace with official headcount when available
A26: 25 | B26: Dubai Export Development Coroporation | D26: 150 | E26: Planning estimate – validate with entity | F26: 0.5 | G26: =ROUND(D26*F26,0) -> 75 | I26: =IF(G26<100,2950,IF(G26<500,2213,IF(G26<1000,2065,IF(G26<2000,1770,IF(G26<3000,1475,1180))))) -> 2950 | J26: ='Pricing & Assumptions'!$B$9 -> 1180 | K26: =G26*I26 -> 221250 | L26: =G26*J26 -> 88500 | M26: =K26-L26 -> 132750 | N26: =M26*5 -> 663750 | O26: =G26*('Pricing & Assumptions'!$B$3-'Pricing & Assumptions'!$B$9)*5 -> 442500 | P26: Indicative planning estimate; replace with official headcount when available
A27: 26 | B27: Dubai Financial Market (DFM) | D27: 500 | E27: Planning estimate – validate with entity | F27: 0.7 | G27: =ROUND(D27*F27,0) -> 350 | I27: =IF(G27<100,2950,IF(G27<500,2213,IF(G27<1000,2065,IF(G27<2000,1770,IF(G27<3000,1475,1180))))) -> 2213 | J27: ='Pricing & Assumptions'!$B$9 -> 1180 | K27: =G27*I27 -> 774550 | L27: =G27*J27 -> 413000 | M27: =K27-L27 -> 361550 | N27: =M27*5 -> 1807750 | O27: =G27*('Pricing & Assumptions'!$B$3-'Pricing & Assumptions'!$B$9)*5 -> 2065000 | P27: Indicative planning estimate; replace with official headcount when available
A28: 27 | B28: Dubai Foundation for Women and Children | D28: 300 | E28: Planning estimate – validate with entity | F28: 0.5 | G28: =ROUND(D28*F28,0) -> 150 | I28: =IF(G28<100,2950,IF(G28<500,2213,IF(G28<1000,2065,IF(G28<2000,1770,IF(G28<3000,1475,1180))))) -> 2213 | J28: ='Pricing & Assumptions'!$B$9 -> 1180 | K28: =G28*I28 -> 331950 | L28: =G28*J28 -> 177000 | M28: =K28-L28 -> 154950 | N28: =M28*5 -> 774750 | O28: =G28*('Pricing & Assumptions'!$B$3-'Pricing & Assumptions'!$B$9)*5 -> 885000 | P28: Indicative planning estimate; replace with official headcount when available
A29: 28 | B29: Dubai Future Foundation | D29: 500 | E29: Planning estimate – validate with entity | F29: 0.7 | G29: =ROUND(D29*F29,0) -> 350 | I29: =IF(G29<100,2950,IF(G29<500,2213,IF(G29<1000,2065,IF(G29<2000,1770,IF(G29<3000,1475,1180))))) -> 2213 | J29: ='Pricing & Assumptions'!$B$9 -> 1180 | K29: =G29*I29 -> 774550 | L29: =G29*J29 -> 413000 | M29: =K29-L29 -> 361550 | N29: =M29*5 -> 1807750 | O29: =G29*('Pricing & Assumptions'!$B$3-'Pricing & Assumptions'!$B$9)*5 -> 2065000 | P29: Indicative planning estimate; replace with official headcount when available
A30: 29 | B30: Dubai Government Human Resource Department | D30: 400 | E30: Planning estimate – validate with entity | F30: 0.7 | G30: =ROUND(D30*F30,0) -> 280 | I30: =IF(G30<100,2950,IF(G30<500,2213,IF(G30<1000,2065,IF(G30<2000,1770,IF(G30<3000,1475,1180))))) -> 2213 | J30: ='Pricing & Assumptions'!$B$9 -> 1180 | K30: =G30*I30 -> 619640 | L30: =G30*J30 -> 330400 | M30: =K30-L30 -> 289240 | N30: =M30*5 -> 1446200 | O30: =G30*('Pricing & Assumptions'!$B$3-'Pricing & Assumptions'!$B$9)*5 -> 1652000 | P30: Indicative planning estimate; replace with official headcount when available
A31: 30 | B31: Dubai Government Workshop | D31: 1200 | E31: Planning estimate – validate with entity | F31: 0.3 | G31: =ROUND(D31*F31,0) -> 360 | I31: =IF(G31<100,2950,IF(G31<500,2213,IF(G31<1000,2065,IF(G31<2000,1770,IF(G31<3000,1475,1180))))) -> 2213 | J31: ='Pricing & Assumptions'!$B$9 -> 1180 | K31: =G31*I31 -> 796680 | L31: =G31*J31 -> 424800 | M31: =K31-L31 -> 371880 | N31: =M31*5 -> 1859400 | O31: =G31*('Pricing & Assumptions'!$B$3-'Pricing & Assumptions'!$B$9)*5 -> 2124000 | P31: Indicative planning estimate; replace with official headcount when available
A32: 31 | B32: Dubai Health | C32: In progress | D32: 15000 | E32: Planning estimate – validate with entity | F32: 0.3 | G32: =ROUND(D32*F32,0) -> 4500 | I32: =IF(G32<100,2950,IF(G32<500,2213,IF(G32<1000,2065,IF(G32<2000,1770,IF(G32<3000,1475,1180))))) -> 1180 | J32: ='Pricing & Assumptions'!$B$9 -> 1180 | K32: =G32*I32 -> 5310000 | L32: =G32*J32 -> 5310000 | M32: =K32-L32 -> 0 | N32: =M32*5 -> 0 | O32: =G32*('Pricing & Assumptions'!$B$3-'Pricing & Assumptions'!$B$9)*5 -> 26550000 | P32: Indicative planning estimate; replace with official headcount when available
A33: 32 | B33: Dubai Health Authority (DHA) | C33: In progress | D33: 2500 | E33: Planning estimate – validate with entity | F33: 0.3 | G33: =ROUND(D33*F33,0) -> 750 | I33: =IF(G33<100,2950,IF(G33<500,2213,IF(G33<1000,2065,IF(G33<2000,1770,IF(G33<3000,1475,1180))))) -> 2065 | J33: ='Pricing & Assumptions'!$B$9 -> 1180 | K33: =G33*I33 -> 1548750 | L33: =G33*J33 -> 885000 | M33: =K33-L33 -> 663750 | N33: =M33*5 -> 3318750 | O33: =G33*('Pricing & Assumptions'!$B$3-'Pricing & Assumptions'!$B$9)*5 -> 4425000 | P33: Indicative planning estimate; replace with official headcount when available
A34: 33 | B34: Dubai International Financial Centre (DIFC) | C34: DocuSign | D34: 700 | E34: Planning estimate – validate with entity | F34: 0.7 | G34: =ROUND(D34*F34,0) -> 490 | I34: =IF(G34<100,2950,IF(G34<500,2213,IF(G34<1000,2065,IF(G34<2000,1770,IF(G34<3000,1475,1180))))) -> 2213 | J34: ='Pricing & Assumptions'!$B$9 -> 1180 | K34: =G34*I34 -> 1084370 | L34: =G34*J34 -> 578200 | M34: =K34-L34 -> 506170 | N34: =M34*5 -> 2530850 | O34: =G34*('Pricing & Assumptions'!$B$3-'Pricing & Assumptions'!$B$9)*5 -> 2891000 | P34: Indicative planning estimate; replace with official headcount when available
A35: 34 | B35: Dubai Islamic Economy Development Centre | D35: 120 | E35: Planning estimate – validate with entity | F35: 0.5 | G35: =ROUND(D35*F35,0) -> 60 | I35: =IF(G35<100,2950,IF(G35<500,2213,IF(G35<1000,2065,IF(G35<2000,1770,IF(G35<3000,1475,1180))))) -> 2950 | J35: ='Pricing & Assumptions'!$B$9 -> 1180 | K35: =G35*I35 -> 177000 | L35: =G35*J35 -> 70800 | M35: =K35-L35 -> 106200 | N35: =M35*5 -> 531000 | O35: =G35*('Pricing & Assumptions'!$B$3-'Pricing & Assumptions'!$B$9)*5 -> 354000 | P35: Indicative planning estimate; replace with official headcount when available
A36: 35 | B36: Dubai Judicial Institute | D36: 150 | E36: Planning estimate – validate with entity | F36: 0.7 | G36: =ROUND(D36*F36,0) -> 105 | I36: =IF(G36<100,2950,IF(G36<500,2213,IF(G36<1000,2065,IF(G36<2000,1770,IF(G36<3000,1475,1180))))) -> 2213 | J36: ='Pricing & Assumptions'!$B$9 -> 1180 | K36: =G36*I36 -> 232365 | L36: =G36*J36 -> 123900 | M36: =K36-L36 -> 108465 | N36: =M36*5 -> 542325 | O36: =G36*('Pricing & Assumptions'!$B$3-'Pricing & Assumptions'!$B$9)*5 -> 619500 | P36: Indicative planning estimate; replace with official headcount when available
A37: 36 | B37: Dubai Land Department (DLD) | C37: Important | D37: 1000 | E37: Planning estimate – validate with entity | F37: 0.7 | G37: =ROUND(D37*F37,0) -> 700 | I37: =IF(G37<100,2950,IF(G37<500,2213,IF(G37<1000,2065,IF(G37<2000,1770,IF(G37<3000,1475,1180))))) -> 2065 | J37: ='Pricing & Assumptions'!$B$9 -> 1180 | K37: =G37*I37 -> 1445500 | L37: =G37*J37 -> 826000 | M37: =K37-L37 -> 619500 | N37: =M37*5 -> 3097500 | O37: =G37*('Pricing & Assumptions'!$B$3-'Pricing & Assumptions'!$B$9)*5 -> 4130000 | P37: Indicative planning estimate; replace with official headcount when available
A38: 37 | B38: Dubai Maritime City Authority | D38: 250 | E38: Planning estimate – validate with entity | F38: 0.5 | G38: =ROUND(D38*F38,0) -> 125 | I38: =IF(G38<100,2950,IF(G38<500,2213,IF(G38<1000,2065,IF(G38<2000,1770,IF(G38<3000,1475,1180))))) -> 2213 | J38: ='Pricing & Assumptions'!$B$9 -> 1180 | K38: =G38*I38 -> 276625 | L38: =G38*J38 -> 147500 | M38: =K38-L38 -> 129125 | N38: =M38*5 -> 645625 | O38: =G38*('Pricing & Assumptions'!$B$3-'Pricing & Assumptions'!$B$9)*5 -> 737500 | P38: Indicative planning estimate; replace with official headcount when available
A39: 38 | B39: Dubai Media Council | D39: 200 | E39: Planning estimate – validate with entity | F39: 0.7 | G39: =ROUND(D39*F39,0) -> 140 | I39: =IF(G39<100,2950,IF(G39<500,2213,IF(G39<1000,2065,IF(G39<2000,1770,IF(G39<3000,1475,1180))))) -> 2213 | J39: ='Pricing & Assumptions'!$B$9 -> 1180 | K39: =G39*I39 -> 309820 | L39: =G39*J39 -> 165200 | M39: =K39-L39 -> 144620 | N39: =M39*5 -> 723100 | O39: =G39*('Pricing & Assumptions'!$B$3-'Pricing & Assumptions'!$B$9)*5 -> 826000 | P39: Indicative planning estimate; replace with official headcount when available
A40: 39 | B40: Dubai Media Inc | D40: 2500 | E40: Planning estimate – validate with entity | F40: 0.5 | G40: =ROUND(D40*F40,0) -> 1250 | I40: =IF(G40<100,2950,IF(G40<500,2213,IF(G40<1000,2065,IF(G40<2000,1770,IF(G40<3000,1475,1180))))) -> 1770 | J40: ='Pricing & Assumptions'!$B$9 -> 1180 | K40: =G40*I40 -> 2212500 | L40: =G40*J40 -> 1475000 | M40: =K40-L40 -> 737500 | N40: =M40*5 -> 3687500 | O40: =G40*('Pricing & Assumptions'!$B$3-'Pricing & Assumptions'!$B$9)*5 -> 7375000 | P40: Indicative planning estimate; replace with official headcount when available
...

Sheet Pricing & Assumptions
A1: Pricing / Model Assumption | B1: AED per user/year
A2: Regular Basic Price | B2: 2950
A3: DDA Shared Service Price (20% off) | B3: 2360
A4: Tier 1 - 100 to 499 | B4: 2213
A5: Tier 2 - 500 to 999 | B5: 2065
A6: Tier 3 - 1,000 to 1,999 | B6: 1770
A7: Tier 4 - 2,000 to 2,999 | B7: 1475
A8: Tier 5 - 3,000+ | B8: 1180
A9: Central Tier 5 Used in Model | B9: 1180
A11: Methodology
A12: Potential digital-signature users are planning estimates, not survey-reported headcounts.
A13: Published employee counts are used where a credible public figure was found. All other employee counts are explicitly flagged as planning estimates requiring validation.
A14: Potential users = estimated employees × addressable-user ratio. Knowledge/administrative entities use 70%; general entities 50%; field/operational entities 30%.
A15: Fragmented price assumes each entity purchases independently at the tier corresponding to its own potential user count. Central scenario applies Tier 5 AED 1,180 to all users through DDA shared service.
A16: The 5-year comparison excludes inflation, implementation/support, transaction-based products and VAT. It is a license-subscription comparison only.
A17: A second 5-year saving column compares Tier 5 directly with the AED 2,950 regular/basic price, useful as the maximum list-price saving case.
A19: Investor Upsell Assumption
A20: Adjacent products revenue uplift vs eSign | B20: 0.5
A21: Adjacent products | B21: Secure document storage, collaboration and AI
A22: Treatment | B22: Illustrative potential revenue assumption; not committed revenue
