Workbook

Sheet Summary
C2: DDA central procurement — savings and adoption
C4: Annual commitment — edit E4 | E4: 8000 | G4: Enter 5,000, 8,000 or 10,000 users.
C5: Seats beyond existing users + Year 1 growth | E5: =Potential!E65 -> 6428 | G5: Survey share of this gap | I5: =Potential!E77 -> 0.76555694
C6: A1 uses current subscriptions; A2 shows expected Year 1 user growth. B/C are modeled opportunities. Support is separate.
C8: Savings source | D8: Year 1 users | E8: Year 1 benchmark AED | F8: Year 1 central AED | G8: Year 1 saving AED | H8: Five-year saving AED
C9: =Potential!C87 -> A1. Existing customers — current users | D9: =Potential!D87 -> 1310 | E9: =Potential!E87 -> 1929169.8 | F9: =Potential!F87 -> 1739025 | G9: =Potential!G87 -> 190144.75 | H9: =Potential!H87 -> 1051118.2
C10: =Potential!C88 -> A2. Existing customers — Year 1 growth | D10: =Potential!D88 -> 262 | E10: =Potential!E88 -> 385833.95 | F10: =Potential!F88 -> 347805 | G10: =Potential!G88 -> 38028.95 | H10: =Potential!H88 -> 210223.65
C11: =Potential!C89 -> B. Survey-based opportunity | D11: =Potential!D89 -> 4921 | E11: =Potential!E89 -> 14516950 | F11: =Potential!F89 -> 6532627.5 | G11: =Potential!G89 -> 7984322.5 | H11: =Potential!H89 -> 44115775
C12: =Potential!C90 -> C. Other departments — adoption target | D12: =Potential!D90 -> 1507 | E12: =Potential!E90 -> 4445650 | F12: =Potential!F90 -> 2000542.5 | G12: =Potential!G90 -> 2445107.5 | H12: =Potential!H90 -> 13507312
C13: =Potential!C91 -> Selected commitment total | D13: =Potential!D91 -> 8000 | E13: =Potential!E91 -> 21277604 | F13: =Potential!F91 -> 10620000 | G13: =Potential!G91 -> 10657604 | H13: =Potential!H91 -> 58884429
C14: B uses the numerical survey minimum by default. B/C compare with list price until matched costs are supplied.
C15: Per user instruction, survey counts are added without an existing-user deduction. This is a modeling assumption.
C17: Survey user counts — current / expected usage
C18: Survey user band | D18: Responses | E18: Minimum users per entity | F18: Minimum total users | G18: Illustrative average | H18: Illustrative total users
C19: =Survey!C22 -> 1–50 users | D19: =Survey!D22 -> 6 | E19: =Survey!E22 -> 1 | F19: =Survey!H22 -> 6 | G19: =Survey!F22 -> 25.5 | H19: =Survey!G22 -> 153
C20: =Survey!C23 -> 51–100 users | D20: =Survey!D23 -> 4 | E20: =Survey!E23 -> 51 | F20: =Survey!H23 -> 204 | G20: =Survey!F23 -> 75.5 | H20: =Survey!G23 -> 302
C21: =Survey!C24 -> 101–500 users | D21: =Survey!D24 -> 7 | E21: =Survey!E24 -> 101 | F21: =Survey!H24 -> 707 | G21: =Survey!F24 -> 300.5 | H21: =Survey!G24 -> 2103.5
C22: =Survey!C25 -> More than 1,000 users | D22: =Survey!D25 -> 4 | E22: =Survey!E25 -> 1001 | F22: =Survey!H25 -> 4004 | G22: =Survey!F25 -> 2000 | H22: =Survey!G25 -> 8000
C23: 21 quantified responses | D23: =SUM(D19:D22) -> 21 | F23: =SUM(F19:F22) -> 4921 | H23: =SUM(H19:H22) -> 10558.5
C25: Illustration uses band midpoints and 2,000 users for each >1,000 response. It is not an observed user total.
C26: The 16 entities expressing demand add no extra quantified users here. Their user counts are not supplied.
C28: Path to the commitment and breadth of opportunity
C29: Existing customer users today | E29: =Potential!E14 -> 1310 | G29: Total entities | I29: =Setup!E54 -> 92
C30: ="Existing growth — Year 1 ("&TEXT(Setup!E67,"0%")&")" -> Existing growth — Year 1 (20%) | E30: =Potential!E23 -> 262 | G30: Entities surveyed | I30: =Survey!E54 -> 38
C31: Survey users in the Year 1 plan | E31: =Potential!E71 -> 4921 | G31: Entities not surveyed | I31: =Survey!E66 -> 54
C32: Covered by existing + growth + survey | E32: =SUM(Potential!D87:D89)/Setup!E5 -> 0.811625 | G32: Already use digital signatures | I32: =Survey!E55 -> 21
C33: Other-department users required | E33: =Potential!E72 -> 1507 | G33: Additional demand entities | I33: =Survey!E58 -> 16
C34: Users per unsurveyed entity (rounded up) | E34: =ROUNDUP(Potential!E76,0) -> 28 | G34: Expect usage growth | I34: =Survey!E61 -> 0.77272727
C35: Employee-based potential users | E35: =Potential!E11 -> 15200 | G35: Growth driven by more users | I35: =Survey!E64 -> 0.76470588
C37: Demand: 10 current requirements + 6 future needs. Growth: 17/22 organizations; more users: 13/17 growth respondents.
C38: Separate annual support fee — AED | E38: =Potential!D41 -> 1699200
C39: ="Years 2–5: "&TEXT(Setup!E68,"0%")&" annual user growth, paid at the locked unit price. Full-year billing assumed; support remains separate." -> Years 2–5: 5% annual user growth, paid at the locked unit price. Full-year billing assumed; support remains separate.
C58: Chart data | D58: Current subscription | E58: Central subscription
C59: Existing customers | D59: ='Existing customers'!G16 -> 1929169.8 | E59: ='Existing customers'!H16 -> 1739025
C61: Adoption source | D61: Users
C62: Existing | D62: =Potential!E14 -> 1310
C63: Existing growth (Year 1) | D63: =Potential!E23 -> 262
C64: Survey | D64: =Potential!E71 -> 4921
C65: Other | D65: =Potential!E72 -> 1507
C66: Unused | D66: =Potential!E73 -> 0

Sheet Setup
C2: Commitment, pricing and assumptions
C5: Annual commitment — from Summary | E5: =Summary!E4 -> 8000 | G5: Edit Summary E4 to change the commitment.
C6: Capacity check | E6: =IF(E5<ROUND('Existing customers'!D16*(1+E67),0),"Below existing users","Ready") -> Ready
C8: Regular Basic Price | E8: 2950 | G8: V2-S03. Subscription benchmark, not actual spending.
C9: Comparison period — years | E9: 5 | G9: Five years, billed annually. Paid users grow from Year 2.
C10: Employee population | E10: 76000 | G10: V2-S05. User-supplied planning population.
C11: Potential adoption share | E11: 0.2 | G11: V2-S05. Assumption; includes existing users.
C12: Baseline annual price escalation | E12: 0 | G12: Optional assumption. Central unit prices stay fixed.
C13: Additional seats used beyond Year 1 existing | E13: 1 | G13: Usage of remaining capacity after existing-customer growth.
C15: Selected tier | E15: =MATCH(E5,D27:D33,1) -> 5
C16: Subscription discount | E16: =INDEX(F27:F33,E15) -> 0.55
C17: Support rate | E17: =INDEX(G27:G33,E15) -> 0.16
C18: Subscription AED/user/year | E18: =INDEX(H27:H33,E15) -> 1327.5
C19: Separate support AED/user/year | E19: =INDEX(I27:I33,E15) -> 212.4
C21: Amber cells are editable assumptions. Blue numbers are inputs; green formulas link sheets.
C22: Existing-customer savings exclude support. Central support is added separately to the budget.
C23: Survey adoption is modeled explicitly. Savings against reported costs require matched respondents.
C26: Tier | D26: Minimum users | E26: Maximum users | F26: Discount | G26: Support rate | H26: Subscription AED/user | I26: Separate support AED/user
C27: 1 | D27: 1 | E27: 1000 | F27: 0.25 | G27: 0.25 | H27: =$E$8*(1-F27) -> 2212.5 | I27: =H27*G27 -> 553.125
C28: 2 | D28: 1001 | E28: 1999 | F28: 0.3 | G28: 0.22 | H28: =$E$8*(1-F28) -> 2065 | I28: =H28*G28 -> 454.3
C29: 3 | D29: 2000 | E29: 4999 | F29: 0.4 | G29: 0.2 | H29: =$E$8*(1-F29) -> 1770 | I29: =H29*G29 -> 354
C30: 4 | D30: 5000 | E30: 7999 | F30: 0.5 | G30: 0.18 | H30: =$E$8*(1-F30) -> 1475 | I30: =H30*G30 -> 265.5
C31: 5 | D31: 8000 | E31: 9999 | F31: 0.55 | G31: 0.16 | H31: =$E$8*(1-F31) -> 1327.5 | I31: =H31*G31 -> 212.4
C32: 6 | D32: 10000 | E32: 12000 | F32: 0.6 | G32: 0.14 | H32: =$E$8*(1-F32) -> 1180 | I32: =H32*G32 -> 165.2
C33: 7 | D33: 12001 | F33: 0.65 | G33: 0.12 | H33: =$E$8*(1-F33) -> 1032.5 | I33: =H33*G33 -> 123.9
C35: Pricing source: V2-P04 accepted for this workbook by the user; endpoints from V2-S07.
C36: Above 12,000 starts at 12,001. A tier rate applies to the full committed pool, not marginal bands.
C37: Full-pool discounts create price drops at thresholds. Review the better commitment near each boundary.
C40: Scope and source notes
C42: All savings compare subscriptions only. Support is a separate charge; onboarding, tax and optional services are excluded.
C43: No deployment-specific support override is applied in this simplified tier model.
C44: Current support fees are not supplied. No all-in savings or complete project ROI is claimed.
C45: Employee scale context: DDA, GITEX Europe announcement, May 2025; over 76,000 Smart Employee users.
C46: https://www.digitaldubai.ae/newsroom/news/dubai-to-make-presence-felt-at-gitex-europe-x-ai-everything-2025-with-a-joint-pavilion-featuring-12-government-and-private-entities
C48: Change Summary E4 for 10K, 8K or 5K. Rates, customer savings, budget and charts update together.
C49: Workforce percentage is a planning assumption. Entity names do not establish user allocations.
C52: Adoption planning assumptions
C54: Total entities in scope | E54: 92 | G54: User-supplied scope count; raw list has repeated rows.
C55: Existing Circularo entities | E55: 6 | G55: Six distinct entities across seven supplied projects.
C56: Existing users deducted from survey — share | E56: 0 | G56: User instruction: use full survey counts, no deduction.
...

Sheet Existing customers
C2: Existing customers — subscription savings
C4: Annual commitment selected | E4: =Setup!E5 -> 8000
C6: Source: user-supplied subscriptions (V2-S01) plus Rulers Court addition (V2-S12). Support is separate.
C8: Customer / project | D8: Users | E8: Current AED/user | F8: Central AED/user | G8: Current annual AED | H8: Central annual AED | I8: Annual saving AED | J8: Five-year saving AED | K8: Saving % | L8: Central support AED
C9: Digital Dubai Authority (VIP Project) | D9: 50 | E9: 1850.94 | F9: =Setup!$E$18 -> 1327.5 | G9: =D9*E9 -> 92547 | H9: =D9*F9 -> 66375 | I9: =G9-H9 -> 26172 | J9: =I9*Setup!$E$9 -> 130860 | K9: =IF(G9=0,"n.a.",I9/G9) -> 0.28279685 | L9: =H9*Setup!$E$17 -> 10620
C10: Digital Dubai Authority | D10: 100 | E10: 2212.5 | F10: =Setup!$E$18 -> 1327.5 | G10: =D10*E10 -> 221250 | H10: =D10*F10 -> 132750 | I10: =G10-H10 -> 88500 | J10: =I10*Setup!$E$9 -> 442500 | K10: =IF(G10=0,"n.a.",I10/G10) -> 0.4 | L10: =H10*Setup!$E$17 -> 21240
C11: Dubai Culture & Arts Authority | D11: 25 | E11: 2212.48 | F11: =Setup!$E$18 -> 1327.5 | G11: =D11*E11 -> 55312 | H11: =D11*F11 -> 33187.5 | I11: =G11-H11 -> 22124.5 | J11: =I11*Setup!$E$9 -> 110622.5 | K11: =IF(G11=0,"n.a.",I11/G11) -> 0.39999458 | L11: =H11*Setup!$E$17 -> 5310
C12: Dubai Electronic Security Center | D12: 60 | E12: 2507.5 | F12: =Setup!$E$18 -> 1327.5 | G12: =D12*E12 -> 150450 | H12: =D12*F12 -> 79650 | I12: =G12-H12 -> 70800 | J12: =I12*Setup!$E$9 -> 354000 | K12: =IF(G12=0,"n.a.",I12/G12) -> 0.47058824 | L12: =H12*Setup!$E$17 -> 12744
C13: Ports, Customs and Free Zone Corporation (PCFC) | D13: 25 | E13: 2159.43 | F13: =Setup!$E$18 -> 1327.5 | G13: =D13*E13 -> 53985.75 | H13: =D13*F13 -> 33187.5 | I13: =G13-H13 -> 20798.25 | J13: =I13*Setup!$E$9 -> 103991.25 | K13: =IF(G13=0,"n.a.",I13/G13) -> 0.38525444 | L13: =H13*Setup!$E$17 -> 5310
C14: Roads and Transport Authority (RTA) | D14: 1000 | E14: 1245 | F14: =Setup!$E$18 -> 1327.5 | G14: =D14*E14 -> 1245000 | H14: =D14*F14 -> 1327500 | I14: =G14-H14 -> -82500 | J14: =I14*Setup!$E$9 -> -412500 | K14: =IF(G14=0,"n.a.",I14/G14) -> -0.06626506 | L14: =H14*Setup!$E$17 -> 212400
C15: His Highness the Rulers Court | D15: 50 | E15: 2212.5 | F15: =Setup!$E$18 -> 1327.5 | G15: =D15*E15 -> 110625 | H15: =D15*F15 -> 66375 | I15: =G15-H15 -> 44250 | J15: =I15*Setup!$E$9 -> 221250 | K15: =IF(G15=0,"n.a.",I15/G15) -> 0.4 | L15: =H15*Setup!$E$17 -> 10620
C16: Existing customer total | D16: =SUM(D9:D15) -> 1310 | G16: =SUM(G9:G15) -> 1929169.8 | H16: =SUM(H9:H15) -> 1739025 | I16: =SUM(I9:I15) -> 190144.75 | J16: =SUM(J9:J15) -> 950723.75 | K16: =I16/G16 -> 0.098562996 | L16: =SUM(L9:L15) -> 278244
C18: Positive savings = lower subscription fees. Negative values show a subscription increase.
C19: Central support is shown separately. Current support is unknown and excluded from the savings comparison.
C20: These costs allocate the central rate to existing users; DDA still pays for the full annual commitment.
C21: Five-year savings hold current subscription prices and existing user counts flat.
C22: Entity #92 added by user: Rulers Court. Transaction limits not supplied; the original six projects are unlimited.
C24: Subscription comparison for charts
C25: Measure | D25: Current subscriptions | E25: Central subscriptions
C26: Existing customers | D26: =G16 -> 1929169.8 | E26: =H16 -> 1739025

Sheet Survey
C2: Survey — demand, costs and new customers
C4: Annual commitment selected | E4: =Setup!E5 -> 8000
C6: Source: DDA internal survey, supplied by the user. Cost and user bands are unpaired current/expected responses.
C8: Annual system cost band | D8: Responses | E8: Lower bound AED | F8: Assumed average AED | G8: Estimated total AED | H8: Lower-bound total AED
C9: Less than AED 50,000 | D9: 7 | E9: 0 | F9: 25000 | G9: =D9*F9 -> 175000 | H9: =D9*E9 -> 0
C10: AED 50,001–100,000 | D10: 6 | E10: 50001 | F10: 75000.5 | G10: =D10*F10 -> 450003 | H10: =D10*E10 -> 300006
C11: AED 100,001–250,000 | D11: 6 | E11: 100001 | F11: 175000.5 | G11: =D11*F11 -> 1050003 | H11: =D11*E11 -> 600006
C12: AED 250,001–500,000 | D12: 1 | E12: 250001 | F12: 375000.5 | G12: =D12*F12 -> 375000.5 | H12: =D12*E12 -> 250001
C13: More than AED 2,000,000 | D13: 1 | E13: 2000001 | F13: 2500000 | G13: =D13*F13 -> 2500000 | H13: =D13*E13 -> 2000001
C14: Not available / unknown | D14: 1
C15: Total responses / quantified costs | D15: =SUM(D9:D14) -> 22 | G15: =SUM(G9:G14) -> 4550006.5 | H15: =SUM(H9:H14) -> 3150014
C17: Selected averages are assumptions. The open band has no reported ceiling; AED 2.5m is an editable illustration.
C18: The unknown response is from the earlier full survey. Quantified costs cover 21 of 22 responses.
C21: Digital signature user band | D21: Responses | E21: Minimum users | F21: Assumed average users | G21: Estimated users | H21: Minimum total users
C22: 1–50 users | D22: 6 | E22: 1 | F22: 25.5 | G22: =D22*F22 -> 153 | H22: =D22*E22 -> 6
C23: 51–100 users | D23: 4 | E23: 51 | F23: 75.5 | G23: =D23*F23 -> 302 | H23: =D23*E23 -> 204
C24: 101–500 users | D24: 7 | E24: 101 | F24: 300.5 | G24: =D24*F24 -> 2103.5 | H24: =D24*E24 -> 707
C25: More than 1,000 users | D25: 4 | E25: 1001 | F25: 2000 | G25: =D25*F25 -> 8000 | H25: =D25*E25 -> 4004
C26: Other / unspecified | D26: 1
C27: Total responses / quantified users | D27: =SUM(D22:D26) -> 22 | G27: =SUM(G22:G26) -> 10558.5 | H27: =SUM(H22:H26) -> 4921
C29: Midpoints are estimates. The open user band uses 2,000 as an editable assumption; the unknown is excluded.
C30: Summary adds full survey user counts as instructed. Unpaired reported cost totals are not used to claim subscription savings.
C32: Identified new-customer comparison
C34: Comparable new entities | E34: =COUNTIFS(Respondents!K9:K46,"Ready") -> 0
C35: Comparable new users | E35: =SUMIFS(Respondents!E9:E46,Respondents!K9:K46,"Ready") -> 0
C36: Current / expected subscriptions AED | E36: =IF(E34=0,"n.a.",SUMIFS(Respondents!G9:G46,Respondents!K9:K46,"Ready")) -> n.a.
C37: Central subscriptions AED | E37: =IF(E34=0,"n.a.",SUMIFS(Respondents!I9:I46,Respondents!K9:K46,"Ready")) -> n.a.
C38: Annual subscription saving AED | E38: =IF(E34=0,"n.a.",E36-E37) -> n.a.
C39: Subscription saving % | E39: =IF(OR(E34=0,E36=0),"n.a.",E38/E36) -> n.a.
C40: Five-year subscription saving AED | E40: =IF(E34=0,"n.a.",E38*Setup!E9) -> n.a.
C42: Entities with current costs | E42: =COUNTIFS(Respondents!K9:K46,"Ready",Respondents!H9:H46,"Current") -> 0
C43: Entities with expected costs | E43: =COUNTIFS(Respondents!K9:K46,"Ready",Respondents!H9:H46,"Expected") -> 0
C44: Data status | E44: =IF(E34=0,"Awaiting respondent data","Matched rows only") -> Awaiting respondent data
C47: New-customer savings use matched subscription costs, explicit non-customer status and no duplicate entity names.
C48: Survey estimates are neither confirmed new demand nor a funded allocation of the annual commitment.
C49: Current/expected system costs may include support, transactions or other services. Scope must be matched first.
C52: Survey reach and demand signals
C54: Entities surveyed | E54: 38
C55: Already use digital signatures | E55: 21
C56: Current requirement — additional entities | E56: 10
...

Sheet Potential
C2: Overall potential and commitment economics
C4: Annual commitment selected | E4: =Setup!E5 -> 8000
C6: The employee-based potential includes existing and survey users. It is not an additional cohort to add to them.
C8: Demand and capacity
C9: Employee planning population | E9: =Setup!E10 -> 76000
C10: Assumed adoption share | E10: =Setup!E11 -> 0.2
C11: Potential signature users | E11: =ROUND(E9*E10,0) -> 15200
C13: Annual committed users | E13: =Setup!E5 -> 8000
C14: Existing customer users | E14: ='Existing customers'!D16 -> 1310
C15: Matched new-customer users | E15: =Survey!E35 -> 0
C16: Known / expected users including growth | E16: =SUM(E14:E15)+E23 -> 1572
C17: Commitment still to allocate | E17: =MAX(0,E13-E16) -> 6428 | G17: Capacity / usage check | I17: =IF(E16>E13,"Over capacity",IF(E15>E22,"Review usage","Ready")) -> Ready
C18: Identified users above commitment | E18: =MAX(0,E16-E13) -> 0
C19: Commitment / estimated potential | E19: =IF(E11=0,"n.a.",E13/E11) -> 0.52631579
C20: Potential beyond commitment | E20: =MAX(0,E11-E13) -> 7200
C21: Capacity beyond Year 1 existing | E21: =MAX(0,E13-E14-E23) -> 6428
C22: Additional seats assumed in use | E22: =ROUND(E21*Setup!E13,0) -> 6428
C23: Existing growth — additional Year 1 users | E23: =ROUND(E14*Setup!E67,0) -> 262
C25: Selected commitment — users and AED | D25: Year 1 | E25: Year 2 | F25: Year 3 | G25: Year 4 | H25: Year 5 | I25: Five-year AED total
C26: Existing users — growth rate | D26: =Setup!E67 -> 0.2 | E26: =Setup!E68 -> 0.05 | F26: =Setup!E68 -> 0.05 | G26: =Setup!E68 -> 0.05 | H26: =Setup!E68 -> 0.05
C27: Survey / Other — growth rate | D27: =0 -> 0 | E27: =Setup!E68 -> 0.05 | F27: =Setup!E68 -> 0.05 | G27: =Setup!E68 -> 0.05 | H27: =Setup!E68 -> 0.05
C28: Existing users including growth | D28: =$E$14+$E$23 -> 1572 | E28: =ROUND(D28*(1+E26),0) -> 1651 | F28: =ROUND(E28*(1+F26),0) -> 1734 | G28: =ROUND(F28*(1+G26),0) -> 1821 | H28: =ROUND(G28*(1+H26),0) -> 1912
C29: Survey users | D29: =$E$71 -> 4921 | E29: =ROUND(D29*(1+E27),0) -> 5167 | F29: =ROUND(E29*(1+F27),0) -> 5425 | G29: =ROUND(F29*(1+G27),0) -> 5696 | H29: =ROUND(G29*(1+H27),0) -> 5981
C30: Other users | D30: =$E$72 -> 1507 | E30: =ROUND(D30*(1+E27),0) -> 1582 | F30: =ROUND(E30*(1+F27),0) -> 1661 | G30: =ROUND(F30*(1+G27),0) -> 1744 | H30: =ROUND(G30*(1+H27),0) -> 1831
C31: Total users in use | D31: =SUM(D28:D30) -> 8000 | E31: =SUM(E28:E30) -> 8400 | F31: =SUM(F28:F30) -> 8820 | G31: =SUM(G28:G30) -> 9261 | H31: =SUM(H28:H30) -> 9724
C32: Paid subscription users | D32: =MAX($E$13,D31) -> 8000 | E32: =MAX($E$13,E31) -> 8400 | F32: =MAX($E$13,F31) -> 8820 | G32: =MAX($E$13,G31) -> 9261 | H32: =MAX($E$13,H31) -> 9724
C33: Locked subscription AED/user/year | D33: =Setup!$E$18 -> 1327.5 | E33: =Setup!$E$18 -> 1327.5 | F33: =Setup!$E$18 -> 1327.5 | G33: =Setup!$E$18 -> 1327.5 | H33: =Setup!$E$18 -> 1327.5
C35: Existing — subscription benchmark AED | D35: =IF($E$14=0,0,'Existing customers'!$G$16*D28/$E$14)*(1+Setup!$E$12)^0 -> 2315003.7 | E35: =IF($E$14=0,0,'Existing customers'!$G$16*E28/$E$14)*(1+Setup!$E$12)^1 -> 2431342.9 | F35: =IF($E$14=0,0,'Existing customers'!$G$16*F28/$E$14)*(1+Setup!$E$12)^2 -> 2553572.8 | G35: =IF($E$14=0,0,'Existing customers'!$G$16*G28/$E$14)*(1+Setup!$E$12)^3 -> 2681693.2 | H35: =IF($E$14=0,0,'Existing customers'!$G$16*H28/$E$14)*(1+Setup!$E$12)^4 -> 2815704.2 | I35: =IF(COUNT(D35:H35)=5,SUM(D35:H35),"n.a.") -> 12797317
C36: Survey — subscription benchmark AED | D36: =IF($E$79="Modeled adoption",IF($D$29=0,0,($E$83+($D$29-$E$80)*Setup!$E$8)*D29/$D$29)*(1+Setup!$E$12)^0,"n.a.") -> 14516950 | E36: =IF($E$79="Modeled adoption",IF($D$29=0,0,($E$83+($D$29-$E$80)*Setup!$E$8)*E29/$D$29)*(1+Setup!$E$12)^1,"n.a.") -> 15242650 | F36: =IF($E$79="Modeled adoption",IF($D$29=0,0,($E$83+($D$29-$E$80)*Setup!$E$8)*F29/$D$29)*(1+Setup!$E$12)^2,"n.a.") -> 16003750 | G36: =IF($E$79="Modeled adoption",IF($D$29=0,0,($E$83+($D$29-$E$80)*Setup!$E$8)*G29/$D$29)*(1+Setup!$E$12)^3,"n.a.") -> 16803200 | H36: =IF($E$79="Modeled adoption",IF($D$29=0,0,($E$83+($D$29-$E$80)*Setup!$E$8)*H29/$D$29)*(1+Setup!$E$12)^4,"n.a.") -> 17643950 | I36: =IF(COUNT(D36:H36)=5,SUM(D36:H36),"n.a.") -> 80210500
C37: Other — subscription benchmark AED | D37: =IF($E$79="Modeled adoption",IF($D$30=0,0,(IF(Survey!$E$34=0,0,Survey!$E$36)-$E$83+($D$30-$E$82)*Setup!$E$8)*D30/$D$30)*(1+Setup!$E$12)^0,"n.a.") -> 4445650 | E37: =IF($E$79="Modeled adoption",IF($D$30=0,0,(IF(Survey!$E$34=0,0,Survey!$E$36)-$E$83+($D$30-$E$82)*Setup!$E$8)*E30/$D$30)*(1+Setup!$E$12)^1,"n.a.") -> 4666900 | F37: =IF($E$79="Modeled adoption",IF($D$30=0,0,(IF(Survey!$E$34=0,0,Survey!$E$36)-$E$83+($D$30-$E$82)*Setup!$E$8)*F30/$D$30)*(1+Setup!$E$12)^2,"n.a.") -> 4899950 | G37: =IF($E$79="Modeled adoption",IF($D$30=0,0,(IF(Survey!$E$34=0,0,Survey!$E$36)-$E$83+($D$30-$E$82)*Setup!$E$8)*G30/$D$30)*(1+Setup!$E$12)^3,"n.a.") -> 5144800 | H37: =IF($E$79="Modeled adoption",IF($D$30=0,0,(IF(Survey!$E$34=0,0,Survey!$E$36)-$E$83+($D$30-$E$82)*Setup!$E$8)*H30/$D$30)*(1+Setup!$E$12)^4,"n.a.") -> 5401450 | I37: =IF(COUNT(D37:H37)=5,SUM(D37:H37),"n.a.") -> 24558750
C38: Combined subscription benchmark AED | D38: =IF(AND($I$17="Ready",COUNT(D35:D37)=3),SUM(D35:D37),"n.a.") -> 21277604 | E38: =IF(AND($I$17="Ready",COUNT(E35:E37)=3),SUM(E35:E37),"n.a.") -> 22340893 | F38: =IF(AND($I$17="Ready",COUNT(F35:F37)=3),SUM(F35:F37),"n.a.") -> 23457273 | G38: =IF(AND($I$17="Ready",COUNT(G35:G37)=3),SUM(G35:G37),"n.a.") -> 24629693 | H38: =IF(AND($I$17="Ready",COUNT(H35:H37)=3),SUM(H35:H37),"n.a.") -> 25861104 | I38: =IF(COUNT(D38:H38)=5,SUM(D38:H38),"n.a.") -> 1.1756657e+08
C39: Central subscription AED | D39: =D32*D33 -> 10620000 | E39: =E32*E33 -> 11151000 | F39: =F32*F33 -> 11708550 | G39: =G32*G33 -> 12293978 | H39: =H32*H33 -> 12908610 | I39: =IF(COUNT(D39:H39)=5,SUM(D39:H39),"n.a.") -> 58682138
C40: Subscription savings AED | D40: =IF(ISNUMBER(D38),D38-D39,"n.a.") -> 10657604 | E40: =IF(ISNUMBER(E38),E38-E39,"n.a.") -> 11189893 | F40: =IF(ISNUMBER(F38),F38-F39,"n.a.") -> 11748723 | G40: =IF(ISNUMBER(G38),G38-G39,"n.a.") -> 12335716 | H40: =IF(ISNUMBER(H38),H38-H39,"n.a.") -> 12952494 | I40: =IF(COUNT(D40:H40)=5,SUM(D40:H40),"n.a.") -> 58884429
C41: Separate support AED — not compared | D41: =D39*Setup!$E$17 -> 1699200 | E41: =E39*Setup!$E$17 -> 1784160 | F41: =F39*Setup!$E$17 -> 1873368 | G41: =G39*Setup!$E$17 -> 1967036.4 | H41: =H39*Setup!$E$17 -> 2065377.6 | I41: =IF(COUNT(D41:H41)=5,SUM(D41:H41),"n.a.") -> 9389142
C43: At full estimated potential — separate scale illustration
C45: Potential users | E45: =E11 -> 15200
C46: Applicable subscription discount | E46: =IF(E45=0,0,INDEX(Setup!F27:F33,MATCH(E45,Setup!D27:D33,1))) -> 0.65
C47: Subscription AED/user/year | E47: =Setup!E8*(1-E46) -> 1032.5
C48: Separate support rate | E48: =IF(E45=0,0,INDEX(Setup!G27:G33,MATCH(E45,Setup!D27:D33,1))) -> 0.12
C49: Annual subscription AED | E49: =E45*E47 -> 15694000
...

Sheet Respondents
C2: Survey respondents — comparable subscription inputs
C4: Annual commitment selected | E4: =Setup!E5 -> 8000
C6: Enter each entity once. Only rows marked Ready and Existing Circularo? = No feed new-customer savings.
C8: Entity | D8: Existing Circularo? | E8: Users | F8: Reported system cost AED/year | G8: Comparable subscription AED/year | H8: Cost basis | I8: Central subscription AED/year | J8: Annual saving AED | K8: Input status | L8: Source / cost scope | M8: Demand cohort
I9: =IF(K9="Ready",E9*Setup!$E$18,"") | J9: =IF(K9="Ready",G9-I9,"") | K9: =IF(C9="","",IF(D9="Yes","Existing - excluded",IF(D9<>"No","Check overlap",IF(OR(NOT(ISNUMBER(E9)),E9<=0),"Enter users",IF(NOT(ISNUMBER(G9)),"Enter subscription",IF(G9<0,"Check cost",IF(AND(H9<>"Current",H9<>"Expected"),"Select cost basis",IF(AND(M9<>"Survey respondents",M9<>"Other departments"),"Select demand cohort",IF(COUNTIFS($C$9:$C$46,C9)>1,"Duplicate entity","Ready")))))))))
I10: =IF(K10="Ready",E10*Setup!$E$18,"") | J10: =IF(K10="Ready",G10-I10,"") | K10: =IF(C10="","",IF(D10="Yes","Existing - excluded",IF(D10<>"No","Check overlap",IF(OR(NOT(ISNUMBER(E10)),E10<=0),"Enter users",IF(NOT(ISNUMBER(G10)),"Enter subscription",IF(G10<0,"Check cost",IF(AND(H10<>"Current",H10<>"Expected"),"Select cost basis",IF(AND(M10<>"Survey respondents",M10<>"Other departments"),"Select demand cohort",IF(COUNTIFS($C$9:$C$46,C10)>1,"Duplicate entity","Ready")))))))))
I11: =IF(K11="Ready",E11*Setup!$E$18,"") | J11: =IF(K11="Ready",G11-I11,"") | K11: =IF(C11="","",IF(D11="Yes","Existing - excluded",IF(D11<>"No","Check overlap",IF(OR(NOT(ISNUMBER(E11)),E11<=0),"Enter users",IF(NOT(ISNUMBER(G11)),"Enter subscription",IF(G11<0,"Check cost",IF(AND(H11<>"Current",H11<>"Expected"),"Select cost basis",IF(AND(M11<>"Survey respondents",M11<>"Other departments"),"Select demand cohort",IF(COUNTIFS($C$9:$C$46,C11)>1,"Duplicate entity","Ready")))))))))
I12: =IF(K12="Ready",E12*Setup!$E$18,"") | J12: =IF(K12="Ready",G12-I12,"") | K12: =IF(C12="","",IF(D12="Yes","Existing - excluded",IF(D12<>"No","Check overlap",IF(OR(NOT(ISNUMBER(E12)),E12<=0),"Enter users",IF(NOT(ISNUMBER(G12)),"Enter subscription",IF(G12<0,"Check cost",IF(AND(H12<>"Current",H12<>"Expected"),"Select cost basis",IF(AND(M12<>"Survey respondents",M12<>"Other departments"),"Select demand cohort",IF(COUNTIFS($C$9:$C$46,C12)>1,"Duplicate entity","Ready")))))))))
I13: =IF(K13="Ready",E13*Setup!$E$18,"") | J13: =IF(K13="Ready",G13-I13,"") | K13: =IF(C13="","",IF(D13="Yes","Existing - excluded",IF(D13<>"No","Check overlap",IF(OR(NOT(ISNUMBER(E13)),E13<=0),"Enter users",IF(NOT(ISNUMBER(G13)),"Enter subscription",IF(G13<0,"Check cost",IF(AND(H13<>"Current",H13<>"Expected"),"Select cost basis",IF(AND(M13<>"Survey respondents",M13<>"Other departments"),"Select demand cohort",IF(COUNTIFS($C$9:$C$46,C13)>1,"Duplicate entity","Ready")))))))))
I14: =IF(K14="Ready",E14*Setup!$E$18,"") | J14: =IF(K14="Ready",G14-I14,"") | K14: =IF(C14="","",IF(D14="Yes","Existing - excluded",IF(D14<>"No","Check overlap",IF(OR(NOT(ISNUMBER(E14)),E14<=0),"Enter users",IF(NOT(ISNUMBER(G14)),"Enter subscription",IF(G14<0,"Check cost",IF(AND(H14<>"Current",H14<>"Expected"),"Select cost basis",IF(AND(M14<>"Survey respondents",M14<>"Other departments"),"Select demand cohort",IF(COUNTIFS($C$9:$C$46,C14)>1,"Duplicate entity","Ready")))))))))
I15: =IF(K15="Ready",E15*Setup!$E$18,"") | J15: =IF(K15="Ready",G15-I15,"") | K15: =IF(C15="","",IF(D15="Yes","Existing - excluded",IF(D15<>"No","Check overlap",IF(OR(NOT(ISNUMBER(E15)),E15<=0),"Enter users",IF(NOT(ISNUMBER(G15)),"Enter subscription",IF(G15<0,"Check cost",IF(AND(H15<>"Current",H15<>"Expected"),"Select cost basis",IF(AND(M15<>"Survey respondents",M15<>"Other departments"),"Select demand cohort",IF(COUNTIFS($C$9:$C$46,C15)>1,"Duplicate entity","Ready")))))))))
I16: =IF(K16="Ready",E16*Setup!$E$18,"") | J16: =IF(K16="Ready",G16-I16,"") | K16: =IF(C16="","",IF(D16="Yes","Existing - excluded",IF(D16<>"No","Check overlap",IF(OR(NOT(ISNUMBER(E16)),E16<=0),"Enter users",IF(NOT(ISNUMBER(G16)),"Enter subscription",IF(G16<0,"Check cost",IF(AND(H16<>"Current",H16<>"Expected"),"Select cost basis",IF(AND(M16<>"Survey respondents",M16<>"Other departments"),"Select demand cohort",IF(COUNTIFS($C$9:$C$46,C16)>1,"Duplicate entity","Ready")))))))))
I17: =IF(K17="Ready",E17*Setup!$E$18,"") | J17: =IF(K17="Ready",G17-I17,"") | K17: =IF(C17="","",IF(D17="Yes","Existing - excluded",IF(D17<>"No","Check overlap",IF(OR(NOT(ISNUMBER(E17)),E17<=0),"Enter users",IF(NOT(ISNUMBER(G17)),"Enter subscription",IF(G17<0,"Check cost",IF(AND(H17<>"Current",H17<>"Expected"),"Select cost basis",IF(AND(M17<>"Survey respondents",M17<>"Other departments"),"Select demand cohort",IF(COUNTIFS($C$9:$C$46,C17)>1,"Duplicate entity","Ready")))))))))
I18: =IF(K18="Ready",E18*Setup!$E$18,"") | J18: =IF(K18="Ready",G18-I18,"") | K18: =IF(C18="","",IF(D18="Yes","Existing - excluded",IF(D18<>"No","Check overlap",IF(OR(NOT(ISNUMBER(E18)),E18<=0),"Enter users",IF(NOT(ISNUMBER(G18)),"Enter subscription",IF(G18<0,"Check cost",IF(AND(H18<>"Current",H18<>"Expected"),"Select cost basis",IF(AND(M18<>"Survey respondents",M18<>"Other departments"),"Select demand cohort",IF(COUNTIFS($C$9:$C$46,C18)>1,"Duplicate entity","Ready")))))))))
I19: =IF(K19="Ready",E19*Setup!$E$18,"") | J19: =IF(K19="Ready",G19-I19,"") | K19: =IF(C19="","",IF(D19="Yes","Existing - excluded",IF(D19<>"No","Check overlap",IF(OR(NOT(ISNUMBER(E19)),E19<=0),"Enter users",IF(NOT(ISNUMBER(G19)),"Enter subscription",IF(G19<0,"Check cost",IF(AND(H19<>"Current",H19<>"Expected"),"Select cost basis",IF(AND(M19<>"Survey respondents",M19<>"Other departments"),"Select demand cohort",IF(COUNTIFS($C$9:$C$46,C19)>1,"Duplicate entity","Ready")))))))))
I20: =IF(K20="Ready",E20*Setup!$E$18,"") | J20: =IF(K20="Ready",G20-I20,"") | K20: =IF(C20="","",IF(D20="Yes","Existing - excluded",IF(D20<>"No","Check overlap",IF(OR(NOT(ISNUMBER(E20)),E20<=0),"Enter users",IF(NOT(ISNUMBER(G20)),"Enter subscription",IF(G20<0,"Check cost",IF(AND(H20<>"Current",H20<>"Expected"),"Select cost basis",IF(AND(M20<>"Survey respondents",M20<>"Other departments"),"Select demand cohort",IF(COUNTIFS($C$9:$C$46,C20)>1,"Duplicate entity","Ready")))))))))
... I46: =IF(K46="Ready",E46*Setup!$E$18,"") | J46: =IF(K46="Ready",G46-I46,"") | K46: =IF(C46="","",IF(D46="Yes","Existing - excluded",IF(D46<>"No","Check overlap",IF(OR(NOT(ISNUMBER(E46)),E46<=0),"Enter users",IF(NOT(ISNUMBER(G46)),"Enter subscription",IF(G46<0,"Check cost",IF(AND(H46<>"Current",H46<>"Expected"),"Select cost basis",IF(AND(M46<>"Survey respondents",M46<>"Other departments"),"Select demand cohort",IF(COUNTIFS($C$9:$C$46,C46)>1,"Duplicate entity","Ready")))))))))
C49: Keep reported system costs in column F. Enter column G only when the comparable subscription component is known.
C50: Do not treat support-inclusive costs as subscriptions. Unknown or incomplete rows remain outside savings totals.
C51: Expected costs are forecasts, not actual spend. Both are identified in the Survey summary.
C52: Respondent-level data is pending from the user. Blank cells are missing inputs, not zero-cost customers.
C53: Demand cohort assigns each matched row once to the adoption plan. Cost basis separately identifies actual or expected costs.

Sheet Entities
C2: Potential entities — supplied source list
C4: Annual commitment selected | E4: =Setup!E5 -> 8000
C6: Original source: dda departments, columns A:B only. Entity #92 added from user instruction, V2-S12.
C8: Source # | D8: Source entity name | E8: Addition source
C9: 1 | D9: Central Grievance Committee
C10: 2 | D10: Community Development Authority
C11: 3 | D11: Dubai Courts
C12: 4 | D12: Department of Economic Development
C13: 5 | D13: Department of Economy and Tourism
C14: 6 | D14: Department of Finance
C15: 7 | D15: Department of Tourism and Commerce Marketing
C16: 8 | D16: Digital Dubai Authority
D17: Digital Dubai Authority
C18: 9 | D18: Directorate General of Dubai Civil Defense
C19: 10 | D19: Dubai Academic Health Corporation
C20: 11 | D20: Dubai Air Navigation Services
C21: 12 | D21: Dubai Airport Freezone
C22: 13 | D22: Dubai Airports
C23: 14 | D23: Dubai Chambers
C24: 15 | D24: Dubai Civil Aviaition Authority
C25: 16 | D25: Dubai Civil Defence
C26: 17 | D26: Dubai Corporation for Ambulances Services
C27: 18 | D27: Dubai Corporation for Aviation Engineering Projects
C28: 19 | D28: Dubai Culture & Arts Authority
C29: 20 | D29: Dubai Customs
... C100: 91 | D100: Dubai Healthcare City Authority
C101: 92 | D101: His Highness the Rulers Court | E101: User, 21 Sep 2026 (V2-S12)
C103: Name rows | D103: =COUNTA(D9:D101) -> 93
C105: Raw rows include duplicates/aliases. This list does not establish funded users or a unique eligible entity count.
