Workbook

Sheet Executive
C2: DDA central procurement business case
C4: Case selected | E4: =Assumptions!E5 -> Base
C6: Five-year comparison at matched capacity. Base growth and rollout are planning assumptions. AED, before tax and unpriced services.
C8: Decision metric | E8: Value
C9: Initial annual commitment | E9: ='Cost model'!E8 -> 10000
C10: Year 5 paid capacity | E10: ='Cost model'!I8 -> 12500
C11: Reduction vs DDA baseline | E11: ='Cost model'!E50 -> 0.5
C12: Reference discount vs list | E12: ='Cost model'!E51 -> 0.6
C13: Year 1 central modeled cost | E13: ='Cost model'!E32 -> 13308680
C14: Five-year central modeled cost | E14: ='Cost model'!K32 -> 74475900
C15: Five-year net comparative benefit | E15: ='Cost model'!K34 -> 73035900
C16: Five-year procurement ROI | E16: ='Cost model'!K37 -> 0.98066489
C17: Initial seats awaiting allocation | E17: =Demand!E10 -> 8170
C18: Initial pool five-year recurring cost | E18: ='Cost model'!K54 -> 65643400
C20: Annual costs and benefit | E20: Baseline | F20: Central | G20: Net benefit
C21: Year 1 | E21: ='Cost model'!E23 -> 26257360 | F21: ='Cost model'!E32 -> 13308680 | G21: ='Cost model'!E34 -> 12948680
C22: Year 2 | E22: ='Cost model'!F23 -> 27879860 | F22: ='Cost model'!F32 -> 14047930 | G22: ='Cost model'!F34 -> 13831930
C23: Year 3 | E23: ='Cost model'!G23 -> 29502360 | F23: ='Cost model'!G32 -> 14895180 | G23: ='Cost model'!G34 -> 14607180
C24: Year 4 | E24: ='Cost model'!H23 -> 31124860 | F24: ='Cost model'!H32 -> 15706430 | G24: ='Cost model'!H34 -> 15418430
C25: Year 5 | E25: ='Cost model'!I23 -> 32747360 | F25: ='Cost model'!I32 -> 16517680 | G25: ='Cost model'!I34 -> 16229680
C26: Five years | E26: ='Cost model'!K23 -> 147511800 | F26: ='Cost model'!K32 -> 74475900 | G26: ='Cost model'!K34 -> 73035900
C29: Adoption and price protection | E29: Value
C30: Year 1 break-even deployed users | E30: ='Cost model'!E42 -> 5013
C31: Year 1 deployed users assumed | E31: ='Cost model'!E11 -> 10000
C32: Five-year demand-adjusted benefit | E32: ='Cost model'!K40 -> 73035900
C33: Five-year extra escalation avoided | E33: ='Cost model'!K46 -> 9629286.6
C34: Escalation sensitivity assumption | E34: =Assumptions!E18 -> 0.03
C37: The 50% saving compares identical capacity and support treatment. It does not claim that entities currently spend the baseline total.
C39: Base assumption: 10,000 to 12,500 paid users by Year 5, 1,260 on-premise users retained, 40 new entities onboarded over five years.
C41: Existing customers cover 1,830 project users. Survey demand overlaps are unknown. New entity allocations require validation.
C43: No indexation protects unit prices. Growth increases the annual bill. The 3% escalation illustration is excluded from headline savings.
C45: Procurement ROI = five-year net comparative benefit / central modeled program cost. Unpriced services can reduce this return.
C47: Use Assumptions E4 to select Base, Slower adoption or Earlier growth. Review the amber assumptions before budget approval.
C51: Chart data | D51: Baseline AED | E51: Central AED | F51: Cumulative benefit AED | G51: Paid users | H51: Deployed users
C52: Year 1 | D52: ='Cost model'!E23 -> 26257360 | E52: ='Cost model'!E32 -> 13308680 | F52: ='Cost model'!E35 -> 12948680 | G52: ='Cost model'!E8 -> 10000 | H52: ='Cost model'!E11 -> 10000
C53: Year 2 | D53: ='Cost model'!F23 -> 27879860 | E53: ='Cost model'!F32 -> 14047930 | F53: ='Cost model'!F35 -> 26780610 | G53: ='Cost model'!F8 -> 10625 | H53: ='Cost model'!F11 -> 10625
C54: Year 3 | D54: ='Cost model'!G23 -> 29502360 | E54: ='Cost model'!G32 -> 14895180 | F54: ='Cost model'!G35 -> 41387790 | G54: ='Cost model'!G8 -> 11250 | H54: ='Cost model'!G11 -> 11250
C55: Year 4 | D55: ='Cost model'!H23 -> 31124860 | E55: ='Cost model'!H32 -> 15706430 | F55: ='Cost model'!H35 -> 56806220 | G55: ='Cost model'!H8 -> 11875 | H55: ='Cost model'!H11 -> 11875
C56: Year 5 | D56: ='Cost model'!I23 -> 32747360 | E56: ='Cost model'!I32 -> 16517680 | F56: ='Cost model'!I35 -> 73035900 | G56: ='Cost model'!I8 -> 12500 | H56: ='Cost model'!I11 -> 12500

Sheet Assumptions
C2: Commercial terms and planning assumptions
C4: Case selected | E4: 1 | G4: 1 Base 2 Slower adoption 3 Earlier growth
E5: =CHOOSE(E4,"Base","Slower adoption","Earlier growth") -> Base
C6: Blue numbers are editable. Amber cells are planning assumptions. Green formulas link sheets. Amounts are AED before tax.
C7: Commercial input | D7: Unit | E7: Value
C8: Regular Basic Price | D8: AED/user/year | E8: 2950 | M8: S01. Reference only.
C9: DDA Shared Service baseline | D9: AED/user/year | E9: 2360 | M9: S06. Main comparison baseline, not actual current spending.
C10: Central subscription | D10: AED/user/year | E10: 1180 | M10: S08. Offer for initial 10,000 annual commitment.
C11: Hosted standard support | D11: % of subscription | E11: 0.1 | M11: S08/S09. Same percentage in both comparisons. 8×5 support.
C12: On-premise support | D12: % of subscription | E12: 0.2 | M12: S10. Replaces 10% and old support charges.
C13: Onboarding per new entity | D13: AED once | E13: 18000 | M13: S08. New entities only. Existing customer migration excluded.
C14: Initial annual commitment | D14: Users | E14: 10000 | M14: S07. Includes existing customers and RTA.
C15: Contract duration | D15: Years | E15: 5 | M15: S07. Annual billing with five-year commitment.
C16: Central annual indexation | D16: % | E16: 0 | M16: S07. No indexation for five years.
C17: Baseline annual escalation | D17: % | E17: 0 | M17: Planning assumption. No contractual increase supplied. Headline uses zero.
C18: Illustrative escalation sensitivity | D18: % | E18: 0.03 | M18: Hypothetical 3% alternative. Extra avoided escalation shown separately.
C19: Existing on-premise users | D19: Users | E19: =SUMIF(Customers!$E$8:$E$16,"On-Premise",Customers!$F$8:$F$16) -> 1260 | M19: S03. Sum of four project user counts. Assumed retained on-premise from Year 1.
C20: Existing users included | D20: Users | E20: =SUM(Customers!F8:F16) -> 1830 | M20: S03/S07. Project users, not verified unique active people.
C21: Unit reference denominator | D21: Employees | E21: 76000 | M21: R01. Lower reference point for reported over 76,000 Smart Employee users in May 2025.
C22: Growth-seat price assumption | D22: AED/user/year | E22: 1180 | M22: Planning assumption. Extension of price lock to added seats needs confirmation.
C23: Baseline onboarding allowance | D23: AED/new entity | E23: 0 | M23: Comparison convention only. Unpriced baseline implementation is excluded.
C25: Planning driver | D25: Unit | E25: Year 1 | F25: Year 2 | G25: Year 3 | H25: Year 4 | I25: Year 5
C26: Cumulative purchased-seat growth | D26: % | E26: =IF(ISNUMBER(CHOOSE($E$4,E27,E28,E29)),CHOOSE($E$4,E27,E28,E29),NA()) -> 0 | F26: =IF(ISNUMBER(CHOOSE($E$4,F27,F28,F29)),CHOOSE($E$4,F27,F28,F29),NA()) -> 0.0625 | G26: =IF(ISNUMBER(CHOOSE($E$4,G27,G28,G29)),CHOOSE($E$4,G27,G28,G29),NA()) -> 0.125 | H26: =IF(ISNUMBER(CHOOSE($E$4,H27,H28,H29)),CHOOSE($E$4,H27,H28,H29),NA()) -> 0.1875 | I26: =IF(ISNUMBER(CHOOSE($E$4,I27,I28,I29)),CHOOSE($E$4,I27,I28,I29),NA()) -> 0.25 | M26: 25% cumulative agreed. Linear timing to Year 5 is a planning assumption; earlier growth reaches Year 3.
C27: Base | D27: % | E27: 0 | F27: 0.0625 | G27: 0.125 | H27: 0.1875 | I27: 0.25
C28: Slower adoption | D28: % | E28: 0 | F28: 0.0625 | G28: 0.125 | H28: 0.1875 | I28: 0.25
C29: Earlier growth | D29: % | E29: 0 | F29: 0.125 | G29: 0.25 | H29: 0.25 | I29: 0.25
C32: Deployed share of paid capacity | D32: % | E32: =IF(ISNUMBER(CHOOSE($E$4,E33,E34,E35)),CHOOSE($E$4,E33,E34,E35),NA()) -> 1 | F32: =IF(ISNUMBER(CHOOSE($E$4,F33,F34,F35)),CHOOSE($E$4,F33,F34,F35),NA()) -> 1 | G32: =IF(ISNUMBER(CHOOSE($E$4,G33,G34,G35)),CHOOSE($E$4,G33,G34,G35),NA()) -> 1 | H32: =IF(ISNUMBER(CHOOSE($E$4,H33,H34,H35)),CHOOSE($E$4,H33,H34,H35),NA()) -> 1 | I32: =IF(ISNUMBER(CHOOSE($E$4,I33,I34,I35)),CHOOSE($E$4,I33,I34,I35),NA()) -> 1 | M32: Illustrative adoption only. Base tests matched capacity, not a verified deployment forecast. Slow case tests underuse.
C33: Base | D33: % | E33: 1 | F33: 1 | G33: 1 | H33: 1 | I33: 1
C34: Slower adoption | D34: % | E34: 0.6 | F34: 0.75 | G34: 0.85 | H34: 0.95 | I34: 1
C35: Earlier growth | D35: % | E35: 1 | F35: 1 | G35: 1 | H35: 1 | I35: 1
C38: New entities onboarded in year | D38: Entities | E38: =IF(ISNUMBER(CHOOSE($E$4,E39,E40,E41)),CHOOSE($E$4,E39,E40,E41),NA()) -> 10 | F38: =IF(ISNUMBER(CHOOSE($E$4,F39,F40,F41)),CHOOSE($E$4,F39,F40,F41),NA()) -> 6 | G38: =IF(ISNUMBER(CHOOSE($E$4,G39,G40,G41)),CHOOSE($E$4,G39,G40,G41),NA()) -> 8 | H38: =IF(ISNUMBER(CHOOSE($E$4,H39,H40,H41)),CHOOSE($E$4,H39,H40,H41),NA()) -> 8 | I38: =IF(ISNUMBER(CHOOSE($E$4,I39,I40,I41)),CHOOSE($E$4,I39,I40,I41),NA()) -> 8 | M38: Illustrative schedule, 40 new entities in total. Survey 10 current / 6 future interest does not establish this schedule.
C39: Base | D39: Entities | E39: 10 | F39: 6 | G39: 8 | H39: 8 | I39: 8
C40: Slower adoption | D40: Entities | E40: 6 | F40: 6 | G40: 8 | H40: 10 | I40: 10
C41: Earlier growth | D41: Entities | E41: 16 | F41: 12 | G41: 6 | H41: 3 | I41: 3
C44: Legacy overlap charged in year | D44: Fraction | E44: =IF(ISNUMBER(CHOOSE($E$4,E45,E46,E47)),CHOOSE($E$4,E45,E46,E47),NA()) -> 0 | F44: =IF(ISNUMBER(CHOOSE($E$4,F45,F46,F47)),CHOOSE($E$4,F45,F46,F47),NA()) -> 0 | G44: =IF(ISNUMBER(CHOOSE($E$4,G45,G46,G47)),CHOOSE($E$4,G45,G46,G47),NA()) -> 0 | H44: =IF(ISNUMBER(CHOOSE($E$4,H45,H46,H47)),CHOOSE($E$4,H45,H46,H47),NA()) -> 0 | I44: =IF(ISNUMBER(CHOOSE($E$4,I45,I46,I47)),CHOOSE($E$4,I45,I46,I47),NA()) -> 0 | M44: Zero assumes migration at Year 1 start. Slow case includes one quarter of known reported annual charges. No refund assumed.
C45: Base | D45: Fraction | E45: 0 | F45: 0 | G45: 0 | H45: 0 | I45: 0
C46: Slower adoption | D46: Fraction | E46: 0.25 | F46: 0 | G46: 0 | H46: 0 | I46: 0
C47: Earlier growth | D47: Fraction | E47: 0 | F47: 0 | G47: 0 | H47: 0 | I47: 0
C50: Additional scenario costs included | D50: AED | E50: =IF(ISNUMBER(CHOOSE($E$4,E51,E52,E53)),CHOOSE($E$4,E51,E52,E53),NA()) -> 0 | F50: =IF(ISNUMBER(CHOOSE($E$4,F51,F52,F53)),CHOOSE($E$4,F51,F52,F53),NA()) -> 0 | G50: =IF(ISNUMBER(CHOOSE($E$4,G51,G52,G53)),CHOOSE($E$4,G51,G52,G53),NA()) -> 0 | H50: =IF(ISNUMBER(CHOOSE($E$4,H51,H52,H53)),CHOOSE($E$4,H51,H52,H53),NA()) -> 0 | I50: =IF(ISNUMBER(CHOOSE($E$4,I51,I52,I53)),CHOOSE($E$4,I51,I52,I53),NA()) -> 0 | M50: Zero means no extra allowance included, not that unknown services are free. Enter agreed migration, integration or operating costs.
C51: Base | D51: AED | E51: 0 | F51: 0 | G51: 0 | H51: 0 | I51: 0
...

Sheet Cost model
C2: Five year costs and comparative returns
C4: Case selected | E4: =Assumptions!E5 -> Base
C7: Cost or driver | D7: Unit | E7: Year 1 | F7: Year 2 | G7: Year 3 | H7: Year 4 | I7: Year 5 | K7: Five years
C8: Paid central capacity | D8: Users | E8: =ROUND(Assumptions!$E$14*(1+Assumptions!E26),0) -> 10000 | F8: =ROUND(Assumptions!$E$14*(1+Assumptions!F26),0) -> 10625 | G8: =ROUND(Assumptions!$E$14*(1+Assumptions!G26),0) -> 11250 | H8: =ROUND(Assumptions!$E$14*(1+Assumptions!H26),0) -> 11875 | I8: =ROUND(Assumptions!$E$14*(1+Assumptions!I26),0) -> 12500 | K8: =SUM(E8:I8) -> 56250 | M8: Five-year quantities are user-years, not distinct people. Added seats assumed hosted.
C9: On-premise users | D9: Users | E9: =Assumptions!$E$19 -> 1260 | F9: =Assumptions!$E$19 -> 1260 | G9: =Assumptions!$E$19 -> 1260 | H9: =Assumptions!$E$19 -> 1260 | I9: =Assumptions!$E$19 -> 1260 | K9: =SUM(E9:I9) -> 6300
C10: Hosted paid capacity | D10: Users | E10: =E8-E9 -> 8740 | F10: =F8-F9 -> 9365 | G10: =G8-G9 -> 9990 | H10: =H8-H9 -> 10615 | I10: =I8-I9 -> 11240 | K10: =SUM(E10:I10) -> 49950
C11: Deployed users assumed | D11: Users | E11: =ROUND(E8*Assumptions!E32,0) -> 10000 | F11: =ROUND(F8*Assumptions!F32,0) -> 10625 | G11: =ROUND(G8*Assumptions!G32,0) -> 11250 | H11: =ROUND(H8*Assumptions!H32,0) -> 11875 | I11: =ROUND(I8*Assumptions!I32,0) -> 12500 | K11: =SUM(E11:I11) -> 56250 | M11: Assumed full-year deployment. Existing on-premise allocation remains in all cases.
C12: Unused paid seats | D12: Users | E12: =E8-E11 -> 0 | F12: =F8-F11 -> 0 | G12: =G8-G11 -> 0 | H12: =H8-H11 -> 0 | I12: =I8-I11 -> 0 | K12: =SUM(E12:I12) -> 0
C13: New entities onboarded | D13: Entities | E13: =Assumptions!E38 -> 10 | F13: =Assumptions!F38 -> 6 | G13: =Assumptions!G38 -> 8 | H13: =Assumptions!H38 -> 8 | I13: =Assumptions!I38 -> 8 | K13: =SUM(E13:I13) -> 40
C14: Unit rates
C15: Baseline subscription unit rate | D15: AED/user | E15: =Assumptions!$E$9*(1+Assumptions!$E$17)^0 -> 2360 | F15: =Assumptions!$E$9*(1+Assumptions!$E$17)^1 -> 2360 | G15: =Assumptions!$E$9*(1+Assumptions!$E$17)^2 -> 2360 | H15: =Assumptions!$E$9*(1+Assumptions!$E$17)^3 -> 2360 | I15: =Assumptions!$E$9*(1+Assumptions!$E$17)^4 -> 2360
C16: Initial central unit rate | D16: AED/user | E16: =Assumptions!$E$10*(1+Assumptions!$E$16)^0 -> 1180 | F16: =Assumptions!$E$10*(1+Assumptions!$E$16)^1 -> 1180 | G16: =Assumptions!$E$10*(1+Assumptions!$E$16)^2 -> 1180 | H16: =Assumptions!$E$10*(1+Assumptions!$E$16)^3 -> 1180 | I16: =Assumptions!$E$10*(1+Assumptions!$E$16)^4 -> 1180
C17: Added-seat unit rate | D17: AED/user | E17: =Assumptions!$E$22 -> 1180 | F17: =Assumptions!$E$22 -> 1180 | G17: =Assumptions!$E$22 -> 1180 | H17: =Assumptions!$E$22 -> 1180 | I17: =Assumptions!$E$22 -> 1180
C18: Matched independent purchase baseline
C19: Baseline subscription | D19: AED | E19: =E8*E15 -> 23600000 | F19: =F8*F15 -> 25075000 | G19: =G8*G15 -> 26550000 | H19: =H8*H15 -> 28025000 | I19: =I8*I15 -> 29500000 | K19: =SUM(E19:I19) -> 132750000
C20: Baseline hosted support | D20: AED | E20: =E10*E15*Assumptions!$E$11 -> 2062640 | F20: =F10*F15*Assumptions!$E$11 -> 2210140 | G20: =G10*G15*Assumptions!$E$11 -> 2357640 | H20: =H10*H15*Assumptions!$E$11 -> 2505140 | I20: =I10*I15*Assumptions!$E$11 -> 2652640 | K20: =SUM(E20:I20) -> 11788200
C21: Baseline on-premise support | D21: AED | E21: =E9*E15*Assumptions!$E$12 -> 594720 | F21: =F9*F15*Assumptions!$E$12 -> 594720 | G21: =G9*G15*Assumptions!$E$12 -> 594720 | H21: =H9*H15*Assumptions!$E$12 -> 594720 | I21: =I9*I15*Assumptions!$E$12 -> 594720 | K21: =SUM(E21:I21) -> 2973600
C22: Baseline onboarding allowance | D22: AED | E22: =E13*Assumptions!$E$23 -> 0 | F22: =F13*Assumptions!$E$23 -> 0 | G22: =G13*Assumptions!$E$23 -> 0 | H22: =H13*Assumptions!$E$23 -> 0 | I22: =I13*Assumptions!$E$23 -> 0 | K22: =SUM(E22:I22) -> 0
C23: Matched baseline total | D23: AED | E23: =SUM(E19:E22) -> 26257360 | F23: =SUM(F19:F22) -> 27879860 | G23: =SUM(G19:G22) -> 29502360 | H23: =SUM(H19:H22) -> 31124860 | I23: =SUM(I19:I22) -> 32747360 | K23: =SUM(E23:I23) -> 147511800 | M23: Comparable capacity at the agreed baseline. Does not represent current actual government spending.
C24: Central program
C25: Central subscription | D25: AED | E25: =Assumptions!$E$14*E16+(E8-Assumptions!$E$14)*E17 -> 11800000 | F25: =Assumptions!$E$14*F16+(F8-Assumptions!$E$14)*F17 -> 12537500 | G25: =Assumptions!$E$14*G16+(G8-Assumptions!$E$14)*G17 -> 13275000 | H25: =Assumptions!$E$14*H16+(H8-Assumptions!$E$14)*H17 -> 14012500 | I25: =Assumptions!$E$14*I16+(I8-Assumptions!$E$14)*I17 -> 14750000 | K25: =SUM(E25:I25) -> 66375000
C26: Central hosted support | D26: AED | E26: =((Assumptions!$E$14-E9)*E16+(E8-Assumptions!$E$14)*E17)*Assumptions!$E$11 -> 1031320 | F26: =((Assumptions!$E$14-F9)*F16+(F8-Assumptions!$E$14)*F17)*Assumptions!$E$11 -> 1105070 | G26: =((Assumptions!$E$14-G9)*G16+(G8-Assumptions!$E$14)*G17)*Assumptions!$E$11 -> 1178820 | H26: =((Assumptions!$E$14-H9)*H16+(H8-Assumptions!$E$14)*H17)*Assumptions!$E$11 -> 1252570 | I26: =((Assumptions!$E$14-I9)*I16+(I8-Assumptions!$E$14)*I17)*Assumptions!$E$11 -> 1326320 | K26: =SUM(E26:I26) -> 5894100
C27: Central on-premise support | D27: AED | E27: =E9*E16*Assumptions!$E$12 -> 297360 | F27: =F9*F16*Assumptions!$E$12 -> 297360 | G27: =G9*G16*Assumptions!$E$12 -> 297360 | H27: =H9*H16*Assumptions!$E$12 -> 297360 | I27: =I9*I16*Assumptions!$E$12 -> 297360 | K27: =SUM(E27:I27) -> 1486800
C28: Central recurring cost | D28: AED | E28: =SUM(E25:E27) -> 13128680 | F28: =SUM(F25:F27) -> 13939930 | G28: =SUM(G25:G27) -> 14751180 | H28: =SUM(H25:H27) -> 15562430 | I28: =SUM(I25:I27) -> 16373680 | K28: =SUM(E28:I28) -> 73755900
C29: New-entity onboarding | D29: AED | E29: =E13*Assumptions!$E$13 -> 180000 | F29: =F13*Assumptions!$E$13 -> 108000 | G29: =G13*Assumptions!$E$13 -> 144000 | H29: =H13*Assumptions!$E$13 -> 144000 | I29: =I13*Assumptions!$E$13 -> 144000 | K29: =SUM(E29:I29) -> 720000
C30: Legacy overlap allowance | D30: AED | E30: =Customers!$K$18*Assumptions!E44 -> 0 | F30: =Customers!$K$18*Assumptions!F44 -> 0 | G30: =Customers!$K$18*Assumptions!G44 -> 0 | H30: =Customers!$K$18*Assumptions!H44 -> 0 | I30: =Customers!$K$18*Assumptions!I44 -> 0 | K30: =SUM(E30:I30) -> 0
C31: Other included scenario costs | D31: AED | E31: =Assumptions!E50 -> 0 | F31: =Assumptions!F50 -> 0 | G31: =Assumptions!G50 -> 0 | H31: =Assumptions!H50 -> 0 | I31: =Assumptions!I50 -> 0 | K31: =SUM(E31:I31) -> 0
C32: Central modeled program cost | D32: AED | E32: =SUM(E28:E31) -> 13308680 | F32: =SUM(F28:F31) -> 14047930 | G32: =SUM(G28:G31) -> 14895180 | H32: =SUM(H28:H31) -> 15706430 | I32: =SUM(I28:I31) -> 16517680 | K32: =SUM(E32:I32) -> 74475900 | M32: Modeled costs only. Unpriced services and tax excluded. Legacy allowance uses incomplete historical charges.
C33: Five-year value
C34: Net comparative benefit | D34: AED | E34: =E23-E32 -> 12948680 | F34: =F23-F32 -> 13831930 | G34: =G23-G32 -> 14607180 | H34: =H23-H32 -> 15418430 | I34: =I23-I32 -> 16229680 | K34: =SUM(E34:I34) -> 73035900
C35: Cumulative comparative benefit | D35: AED | E35: =E34 -> 12948680 | F35: =E35+F34 -> 26780610 | G35: =F35+G34 -> 41387790 | H35: =G35+H34 -> 56806220 | I35: =H35+I34 -> 73035900 | K35: =I35 -> 73035900
C36: Net saving as % of baseline | D36: % | E36: =E34/E23 -> 0.49314478 | F36: =F34/F23 -> 0.49612624 | G36: =G34/G23 -> 0.49511903 | H36: =H34/H23 -> 0.49537347 | I36: =I34/I23 -> 0.4956027 | K36: =K34/K23 -> 0.49511903
C37: Procurement ROI on central cost | D37: % | E37: =E34/E32 -> 0.97294998 | F37: =F34/F32 -> 0.98462407 | G37: =G34/G32 -> 0.98066489 | H37: =H34/H32 -> 0.98166356 | I37: =I34/I32 -> 0.98256414 | K37: =K34/K32 -> 0.98066489 | M37: Net comparative benefit / central modeled program cost, undiscounted. Definition proposed for review.
C38: Adoption exposure
C39: Baseline for deployed users only | D39: AED | E39: =E9*E15*(1+Assumptions!$E$12)+(E11-E9)*E15*(1+Assumptions!$E$11)+E22 -> 26257360 | F39: =F9*F15*(1+Assumptions!$E$12)+(F11-F9)*F15*(1+Assumptions!$E$11)+F22 -> 27879860 | G39: =G9*G15*(1+Assumptions!$E$12)+(G11-G9)*G15*(1+Assumptions!$E$11)+G22 -> 29502360 | H39: =H9*H15*(1+Assumptions!$E$12)+(H11-H9)*H15*(1+Assumptions!$E$11)+H22 -> 31124860 | I39: =I9*I15*(1+Assumptions!$E$12)+(I11-I9)*I15*(1+Assumptions!$E$11)+I22 -> 32747360 | K39: =SUM(E39:I39) -> 147511800 | M39: Demand-adjusted benchmark still uses AED 2,360. It is not a reconstruction of actual customer contracts.
C40: Benefit vs deployed-user baseline | D40: AED | E40: =E39-E32 -> 12948680 | F40: =F39-F32 -> 13831930 | G40: =G39-G32 -> 14607180 | H40: =H39-H32 -> 15418430 | I40: =I39-I32 -> 16229680 | K40: =SUM(E40:I40) -> 73035900
C41: Unused subscription and support | D41: AED | E41: =E12*E16*(1+Assumptions!$E$11) -> 0 | F41: =F12*F16*(1+Assumptions!$E$11) -> 0 | G41: =G12*G16*(1+Assumptions!$E$11) -> 0 | H41: =H12*H16*(1+Assumptions!$E$11) -> 0 | I41: =I12*I16*(1+Assumptions!$E$11) -> 0 | K41: =SUM(E41:I41) -> 0 | M41: Unused seats valued at the initial central hosted rate. Added-seat rate differences are excluded from this exposure measure.
C42: Break-even deployed users | D42: Users | E42: =ROUNDUP((E32-E22-E9*E15*(Assumptions!$E$12-Assumptions!$E$11))/(E15*(1+Assumptions!$E$11)),0) -> 5013 | F42: =ROUNDUP((F32-F22-F9*F15*(Assumptions!$E$12-Assumptions!$E$11))/(F15*(1+Assumptions!$E$11)),0) -> 5297 | G42: =ROUNDUP((G32-G22-G9*G15*(Assumptions!$E$12-Assumptions!$E$11))/(G15*(1+Assumptions!$E$11)),0) -> 5624 | H42: =ROUNDUP((H32-H22-H9*H15*(Assumptions!$E$12-Assumptions!$E$11))/(H15*(1+Assumptions!$E$11)),0) -> 5936 | I42: =ROUNDUP((I32-I22-I9*I15*(Assumptions!$E$12-Assumptions!$E$11))/(I15*(1+Assumptions!$E$11)),0) -> 6249 | M42: Minimum deployed users including retained on-premise users, at matched baseline rates and modeled costs.
C43: Separate price-lock sensitivity
C44: Flat baseline recurring cost | D44: AED | E44: =E8*Assumptions!$E$9+E10*Assumptions!$E$9*Assumptions!$E$11+E9*Assumptions!$E$9*Assumptions!$E$12 -> 26257360 | F44: =F8*Assumptions!$E$9+F10*Assumptions!$E$9*Assumptions!$E$11+F9*Assumptions!$E$9*Assumptions!$E$12 -> 27879860 | G44: =G8*Assumptions!$E$9+G10*Assumptions!$E$9*Assumptions!$E$11+G9*Assumptions!$E$9*Assumptions!$E$12 -> 29502360 | H44: =H8*Assumptions!$E$9+H10*Assumptions!$E$9*Assumptions!$E$11+H9*Assumptions!$E$9*Assumptions!$E$12 -> 31124860 | I44: =I8*Assumptions!$E$9+I10*Assumptions!$E$9*Assumptions!$E$11+I9*Assumptions!$E$9*Assumptions!$E$12 -> 32747360 | K44: =SUM(E44:I44) -> 147511800
...

Sheet Customers
C2: Existing customers and proposed subscription
C4: Case selected | E4: =Assumptions!E5 -> Base
C6: S03 user-supplied customer records. Blanks remain unspecified. Reported amounts assumed AED and additive for this comparison.
C7: Source # | D7: Customer | E7: Deployment | F7: Users | G7: Transactions | H7: Annual subscription | I7: Annual support | J7: Current licence | K7: Known charges | L7: Support rate | M7: Central annual cost | N7: Difference vs known
C8: 8 | D8: Digital Dubai Authority | E8: On-Premise | F8: 50 | G8: Unlimited | H8: 163201.6 | I8: 63397 | J8: Subscription | K8: =SUM(H8:I8) -> 226598.6 | L8: =IF(E8="On-Premise",Assumptions!$E$12,Assumptions!$E$11) -> 0.2 | M8: =F8*Assumptions!$E$10*(1+L8) -> 70800 | N8: =M8-K8 -> -155798.6
C9: 8 | D9: Digital Dubai Authority | E9: Shared Service | F9: 100 | G9: Unlimited | H9: 293444.33 | I9: 75000 | J9: Subscription | K9: =SUM(H9:I9) -> 368444.33 | L9: =IF(E9="On-Premise",Assumptions!$E$12,Assumptions!$E$11) -> 0.1 | M9: =F9*Assumptions!$E$10*(1+L9) -> 129800 | N9: =M9-K9 -> -238644.33
C10: 17 | D10: Dubai Corporation for Ambulances Services | E10: SaaS | F10: 275 | G10: 10000 | H10: 147268.13 | J10: Subscription | K10: =SUM(H10:I10) -> 147268.13 | L10: =IF(E10="On-Premise",Assumptions!$E$12,Assumptions!$E$11) -> 0.1 | M10: =F10*Assumptions!$E$10*(1+L10) -> 356950 | N10: =M10-K10 -> 209681.87
C11: 19 | D11: Dubai Culture & Arts Authority | E11: SaaS | F11: 25 | G11: Unlimited | H11: 110988.75 | J11: Subscription | K11: =SUM(H11:I11) -> 110988.75 | L11: =IF(E11="On-Premise",Assumptions!$E$12,Assumptions!$E$11) -> 0.1 | M11: =F11*Assumptions!$E$10*(1+L11) -> 32450 | N11: =M11-K11 -> -78538.75
C12: 24 | D12: Dubai Electronic Security Center | E12: On-Premise | F12: 60 | G12: Unlimited | H12: 234635.43 | J12: Subscription | K12: =SUM(H12:I12) -> 234635.43 | L12: =IF(E12="On-Premise",Assumptions!$E$12,Assumptions!$E$11) -> 0.2 | M12: =F12*Assumptions!$E$10*(1+L12) -> 84960 | N12: =M12-K12 -> -149675.43
C13: 57 | D13: Investment Corporation of Dubai | E13: On-Premise | F13: 150 | G13: Unlimited | H13: 177108 | J13: Subscription | K13: =SUM(H13:I13) -> 177108 | L13: =IF(E13="On-Premise",Assumptions!$E$12,Assumptions!$E$11) -> 0.2 | M13: =F13*Assumptions!$E$10*(1+L13) -> 212400 | N13: =M13-K13 -> 35292
C14: 70 | D14: Ports, Customs and Free Zone Corporation (PCFC) | E14: SaaS | F14: 20 | G14: Unlimited | H14: 116564.92 | J14: Subscription | K14: =SUM(H14:I14) -> 116564.92 | L14: =IF(E14="On-Premise",Assumptions!$E$12,Assumptions!$E$11) -> 0.1 | M14: =F14*Assumptions!$E$10*(1+L14) -> 25960 | N14: =M14-K14 -> -90604.92
C15: 74 | D15: Roads and Transport Authority (RTA) | E15: On-Premise | F15: 1000 | G15: Unlimited | I15: 608000 | J15: CAPEX | K15: =SUM(H15:I15) -> 608000 | L15: =IF(E15="On-Premise",Assumptions!$E$12,Assumptions!$E$11) -> 0.2 | M15: =F15*Assumptions!$E$10*(1+L15) -> 1416000 | N15: =M15-K15 -> 808000
C16: 91 | D16: Dubai Healthcare City Authority | E16: SaaS | F16: 150 | G16: 5000 | H16: 57627.5 | J16: Subscription | K16: =SUM(H16:I16) -> 57627.5 | L16: =IF(E16="On-Premise",Assumptions!$E$12,Assumptions!$E$11) -> 0.1 | M16: =F16*Assumptions!$E$10*(1+L16) -> 194700 | N16: =M16-K16 -> 137072.5
D18: Total reported project users / charges | F18: =SUM(F8:F16) -> 1830 | H18: =SUM(H8:H16) -> 1300838.7 | I18: =SUM(I8:I16) -> 746397 | K18: =SUM(K8:K16) -> 2047235.7 | M18: =SUM(M8:M16) -> 2524020 | N18: =SUM(N8:N16) -> 476784.34
C21: Positive difference means a higher central charge than the reported known amount. Missing support limits the comparison.
C23: RTA converts from CAPEX to subscription: AED 1,416,000 annual central cost versus AED 608,000 reported support.
C24: The conditional AED 808,000 increase is included here. Historic CAPEX is not a recurring saving.
C26: All four SaaS customers qualify for charge cessation upon migration. DDA Shared Service charges also cease.
C27: On-premise support becomes 20% of allocated subscription and replaces old support. Deployment still benefits from the lower user price.
C29: Nine projects represent eight customer entities. Current charges are not the DDA benchmark for an expanded 10,000-user service.

Sheet Demand
C2: Demand evidence and adoption analysis
C4: Case selected | E4: =Assumptions!E5 -> Base
C7: Demand evidence | D7: Unit | E7: Value
C8: Existing reported project users | D8: Users | E8: =Assumptions!E20 -> 1830
C9: Initial central commitment | D9: Users | E9: =Assumptions!E14 -> 10000
C10: Initial seats awaiting allocation | D10: Users | E10: =E9-E8 -> 8170
C11: Numerical survey minimum | D11: Users | E11: =G28 -> 4921 | M11: Q3 minimum is current/expected demand across 21 numerical answers. Unknown overlap prevents adding existing users.
C12: Q3 numerical responses | D12: Responses | E12: =SUM(D23:D26) -> 21
C13: Q3 other response | D13: Responses | E13: =D27 -> 1
C14: Growth expected | D14: Share | E14: =(E65+E66)/E69 -> 0.77272727 | M14: 17 of 22 expect moderate or significant growth. Survey does not establish 25% growth or its timing.
C15: Interest with current requirement | D15: Entities | E15: =E75 -> 10
C16: Interest with future requirement | D16: Entities | E16: =E76 -> 6
C17: Initial pool / workforce reference | D17: Share | E17: =E9/Assumptions!E21 -> 0.13157895 | M17: R01 reports over 76,000 Smart Employee users. Workforce scale is not paid-signature demand.
C18: Source population rows | D18: Rows | E18: 92 | M18: 92 source-name rows, 91 numbered. Duplicates and aliases prevent asserting 92 unique eligible entities.
C21: Survey user-band sensitivity
C22: Q3 band | D22: Responses | E22: Lower endpoint | F22: Midpoint / assumption | G22: Minimum users | H22: Scenario users | M22: S04 Q3. Midpoints and 2,000 users for the open band are sensitivity assumptions, not observed averages.
C23: 1–50 | D23: =E52 -> 6 | E23: 1 | F23: 25.5 | G23: =D23*E23 -> 6 | H23: =D23*F23 -> 153
C24: 51–100 | D24: =E53 -> 4 | E24: 51 | F24: 75.5 | G24: =D24*E24 -> 204 | H24: =D24*F24 -> 302
C25: 101–500 | D25: =E54 -> 7 | E25: 101 | F25: 300.5 | G25: =D25*E25 -> 707 | H25: =D25*F25 -> 2103.5
C26: More than 1,000 | D26: =E55 -> 4 | E26: 1001 | F26: 2000 | G26: =D26*E26 -> 4004 | H26: =D26*F26 -> 8000
C27: Other | D27: =E56 -> 1
C28: Numerical responses total | G28: =SUM(G23:G26) -> 4921 | H28: =SUM(H23:H26) -> 10558.5
C30: The 10,558.5-user midpoint illustration excludes the unknown answer. Do not round it into confirmed demand.
C33: DDA internal survey supplied responses
C34: Question | D34: Response | E34: Responses | F34: Supplied percentage | M34: S04: user-supplied DDA internal survey. Date, invitation count and respondent mapping not supplied.
C35: Q1. Does your organization currently use a digital/electronic signature system? | D35: Yes | E35: 21 | F35: 0.5526 | M35: Q1/Q8 N=38; Q2–Q5 N=22; Q7 N=16. Preserve separate populations.
C36: Q1. Does your organization currently use a digital/electronic signature system? | D36: No | E36: 10 | F36: 0.2632 | M36: Q6 inferred denominator 17, multiple selections. 42 selections are not 42 entities.
C37: Q1. Does your organization currently use a digital/electronic signature system? | D37: Under planning | E37: 6 | F37: 0.1579 | M37: Q2a breaks down the nine Other responses. No extra respondents.
C38: Q1. Does your organization currently use a digital/electronic signature system? | D38: Under implementation | E38: 1 | F38: 0.0263 | M38: Missing user/cost bands are not zero. Annual cost bands mix current and expected spending.
C39: Q1. Does your organization currently use a digital/electronic signature system? | D39: Total | E39: 38 | F39: 1
C40: Q2. Which digital signature system is currently used / being implemented? | D40: Circularo Digital Sign | E40: 6 | F40: 0.2727
C41: Q2. Which digital signature system is currently used / being implemented? | D41: Adobe Sign | E41: 5 | F41: 0.2273
C42: Q2. Which digital signature system is currently used / being implemented? | D42: DocuSign | E42: 2 | F42: 0.0909
C43: Q2. Which digital signature system is currently used / being implemented? | D43: Other | E43: 9 | F43: 0.4091
C44: Q2. Which digital signature system is currently used / being implemented? | D44: Total | E44: 22 | F44: 1
C45: Q2a. Other systems specified | D45: d2tick | E45: 2
C46: Q2a. Other systems specified | D46: signeasy | E46: 2
C47: Q2a. Other systems specified | D47: Ascertia SigningHub | E47: 1
C48: Q2a. Other systems specified | D48: DocuSign & Adobe Sign | E48: 1
C49: Q2a. Other systems specified | D49: emSigner | E49: 1
...

Sheet Entity scope
C2: Potential entity intake and scope review
C4: Case selected | E4: =Assumptions!E5 -> Base
C6: S02: dda departments columns A:B only. Other workbook tabs and columns supply no facts to this model.
C7: Excel row | D7: Source # | E7: Source company name | F7: Workforce evidence | G7: Existing users | H7: Proposed new seats | I7: Scope / research note
C8: 2 | D8: 1 | E8: Central Grievance Committee | F8: — | I8: Entity-specific workforce and paid-user demand remain unestablished.
C9: 3 | D9: 2 | E9: Community Development Authority | F9: — | I9: Entity-specific workforce and paid-user demand remain unestablished.
C10: 4 | D10: 3 | E10: Dubai Courts | F10: R09: 1,275 (2024), candidate; PDF layout unverified | I10: Entity-specific workforce and paid-user demand remain unestablished.
C11: 5 | D11: 4 | E11: Department of Economic Development | F11: — | I11: R11: DET predecessor; resolve group before counting.
C12: 6 | D12: 5 | E12: Department of Economy and Tourism | F12: — | I12: R11: current DET name; overlaps rows 5, 8, 24.
C13: 7 | D13: 6 | E13: Department of Finance | F13: — | I13: Entity-specific workforce and paid-user demand remain unestablished.
C14: 8 | D14: 7 | E14: Department of Tourism and Commerce Marketing | F14: — | I14: R11: DET predecessor; resolve group before counting.
C15: 9 | D15: 8 | E15: Digital Dubai Authority | F15: — | G15: 50 | I15: S03: On-Premise project; same entity as row 10.
C16: 10 | E16: Digital Dubai Authority | F16: — | G16: 100 | I16: S03: Shared Service project; same entity as row 9.
C17: 11 | D17: 9 | E17: Directorate General of Dubai Civil Defense | F17: — | I17: Civil Defence alias candidate with row 18.
C18: 12 | D18: 10 | E18: Dubai Academic Health Corporation | F18: R03: 11,000 (2024); shared population with row 33 | I18: R03: Dubai Health brand; same workforce as row 33.
C19: 13 | D19: 11 | E19: Dubai Air Navigation Services | F19: — | I19: Entity-specific workforce and paid-user demand remain unestablished.
C20: 14 | D20: 12 | E20: Dubai Airport Freezone | F20: — | I20: R14: DIEZ zone; exclude tenant-company workforce.
C21: 15 | D21: 13 | E21: Dubai Airports | F21: — | I21: R16: 45,000 airport-community trainees are not entity headcount.
C22: 16 | D22: 14 | E22: Dubai Chambers | F22: — | I22: Entity-specific workforce and paid-user demand remain unestablished.
C23: 17 | D23: 15 | E23: Dubai Civil Aviaition Authority | F23: — | I23: Entity-specific workforce and paid-user demand remain unestablished.
C24: 18 | D24: 16 | E24: Dubai Civil Defence | F24: — | I24: Civil Defence alias candidate with row 11.
C25: 19 | D25: 17 | E25: Dubai Corporation for Ambulances Services | F25: R07: 1,375 personnel (2023), operational scope | G25: 275 | I25: R07: operational-team scope, not verified total headcount.
C26: 20 | D26: 18 | E26: Dubai Corporation for Aviation Engineering Projects | F26: — | I26: Entity-specific workforce and paid-user demand remain unestablished.
C27: 21 | D27: 19 | E27: Dubai Culture & Arts Authority | F27: — | G27: 25 | I27: Entity-specific workforce and paid-user demand remain unestablished.
C28: 22 | D28: 20 | E28: Dubai Customs | F28: R06: 2,880, undated; current count unverified | I28: Entity-specific workforce and paid-user demand remain unestablished.
C29: 23 | D29: 21 | E29: Dubai Duty Free | F29: R05: 5,800+ (2025), indexed primary report | I29: Entity-specific workforce and paid-user demand remain unestablished.
C30: 24 | D30: 22 | E30: Dubai Economy and Tourism | F30: — | I30: R11: DET alias candidate; do not sum independently.
C31: 25 | D31: 23 | E31: Dubai Electricity & Water Authority (DEWA) | F31: R02: 10,764 (2025), indexed primary report | I31: Entity-specific workforce and paid-user demand remain unestablished.
C32: 26 | D32: 24 | E32: Dubai Electronic Security Center | F32: — | G32: 60 | I32: Entity-specific workforce and paid-user demand remain unestablished.
C33: 27 | D33: 25 | E33: Dubai Export Development Coroporation | F33: — | I33: Entity-specific workforce and paid-user demand remain unestablished.
C34: 28 | D34: 26 | E34: Dubai Financial Market (DFM) | F34: — | I34: Listed-market operator workforce needed; exclude listed companies.
C35: 29 | D35: 27 | E35: Dubai Foundation for Women and Children | F35: — | I35: Entity-specific workforce and paid-user demand remain unestablished.
C36: 30 | D36: 28 | E36: Dubai Future Foundation | F36: — | I36: Entity-specific workforce and paid-user demand remain unestablished.
C37: 31 | D37: 29 | E37: Dubai Government Human Resource Department | F37: — | I37: Human Resources alias candidate with row 82.
C38: 32 | D38: 30 | E38: Dubai Government Workshop | F38: — | I38: Entity-specific workforce and paid-user demand remain unestablished.
C39: 33 | D39: 31 | E39: Dubai Health | F39: R03: 11,000 (2024); shared population with row 12 | I39: R03: Dubai Health; same workforce as row 12.
C40: 34 | D40: 32 | E40: Dubai Health Authority (DHA) | F40: — | I40: R03: DHA regulator distinct from Dubai Health; current scope required.
C41: 35 | D41: 33 | E41: Dubai International Financial Centre (DIFC) | F41: — | I41: Entity-specific workforce and paid-user demand remain unestablished.
C42: 36 | D42: 34 | E42: Dubai Islamic Economy Development Centre | F42: — | I42: Entity-specific workforce and paid-user demand remain unestablished.
C43: 37 | D43: 35 | E43: Dubai Judicial Institute | F43: — | I43: Entity-specific workforce and paid-user demand remain unestablished.
...

Sheet Research
C2: External research and evidence limits
C4: Case selected | E4: =Assumptions!E5 -> Base
C6: External research as recorded on 20 September 2026. Scope and evidence limits remain attached to each source.
C7: Source | D7: Finding | E7: Evidence limits | F7: Primary URL
C8: R01 | D8: Smart Employee served over 76,000 employees across 76 government entities. | E8: Strong first-party scale benchmark. Do not add entity headcounts to this aggregate or treat HR self-service users as paid signature users. | F8: https://www.digitaldubai.ae/newsroom/news/dubai-to-make-presence-felt-at-gitex-europe-x-ai-everything-2025-with-a-joint-pavilion-featuring-12-government-and-private-entities
C9: R02 | D9: 10,764 employees reported for 2025. | E9: Workforce context for DEWA. Primary search-index extracts corroborate the total; full DEWA PDF retrieval exceeded tool size limit. Operational workers are not automatically paid sign users. | F9: https://www.dewa.gov.ae/-/media/Files/Investor-Relations-Files/Integrated-report-for-the-year-2025.ashx
C10: R03 | D10: More than 11,000 professionals in the 2023 announcement; 2024 entity announcement describes 11,000 employees. Dubai Academic Health Corporation operates as Dubai Health. DHA has a separate regulatory role. | E10: Historical workforce scale; one delivery-system population, not two. Do not reuse historic DHA headcounts without accounting for restructuring, or assume all clinicians need Circularo seats. | F10: https://mediaoffice.ae/en/news/2023/November/11-11/Dubai-Health
C11: R04 | D11: 2,687 total employees. | E11: Entity/corporate workforce context, subject to procurement-scope confirmation. The sustainability report introduction identifies 2025, but its GRI index contains a 2024 period statement; retain this source inconsistency. Annual-report search extract corroborates the number. | F11: https://investors.du.ae/static-files/db00b561-a6f2-41e5-a0de-c73bbad518d2
C12: R05 | D12: Dubai Duty Free reports 5,800+ employees supporting operations. | E12: Search-index evidence; full PDF retrieval failed. Do not turn this rounded floor into an exact count, or count it again inside ICD-wide workforce. | F12: https://icd.gov.ae/wp-content/uploads/2025/11/ICD-AR2025-Full-Report-2.pdf
C13: R06 | D13: The entity page states 2,880 personnel. | E13: Reported but undated; not accepted as a current 2026 count. A recent crawl does not establish a recent underlying observation. | F13: https://www.dubaicustoms.gov.ae/en/SocialResponsibility/Csr/OurEmployees/Pages/default.aspx
C14: R07 | D14: Describes 1,375 personnel managing and operating specialized ambulance services. | E14: Operational-team scope, not established total entity headcount; use only as contextual evidence. S03's 275 licensed users remains the direct current-customer input. | F14: https://www.mediaoffice.ae/en/news/2024/april/04-04/dubai-ambulance-responds-to-over
C15: R08 | D15: An employee-category table includes a 2024 total of 3,259. | E15: Candidate only: text extraction and search rendering differ in language/layout; screenshot retrieval failed. Confirm table purpose and population before using this as workforce or an adoption denominator. Keep S03's 1,000 users. | F15: https://www.rta.ae/wps/wcm/connect/rta/b7653aa3-5dbc-436f-90a3-8dd1aeb270d0/RTA%2BSustainability%2BReport%2B2024-%2BFinal.pdf?MOD=AJPERES
C16: R09 | D16: Search extract places 1,275 beside total employees, with separate administrative and judicial metrics. | E16: Candidate only: full retrieval failed and visual association was not verified. Do not use 1,275 in a base-case calculation until the source page is confirmed. | F16: https://www.dc.gov.ae/publicservices/websitefiles/Annual_Report/Annual-Report-2024-En.pdf
C17: R10 | D17: Profile states 11,000 employees in 34 departments. | E17: Undated self-description; similar figures appear in much older coverage. Lower confidence than a dated annual report; do not treat as current verified workforce. | F17: https://www.linkedin.com/company/dubai-municipality
C18: R11 | D18: Dubai Economy and Dubai Tourism merged into the Department of Economy and Tourism. | E18: Supports predecessor/alias review. No workforce count is supplied; do not sum their historic workforces with DET. | F18: https://pddportalstg.dubai.gov.ae/en/media-listing/news-events/mohammed-bin-rashid-issues-decision-to-merge-dubai-economy-dubai-tourism-to-become-dubai-s-department-of-economy-and-tourism/
... C25: R18 | D25: Official name and remit of the Supreme Legislation Committee. | E25: Supports alias review for the two SLC names in the supplied list. | F25: https://slc.dubai.gov.ae/en/
C28: Workforce references are context only. No workforce percentage from 91 Entities Model enters the central demand forecast.

Sheet Checks
C2: Model checks and unresolved inputs
C4: Case selected | E4: =Assumptions!E5 -> Base
C7: Check | D7: Unit | E7: Result
C8: Source-name rows | D8: Rows | E8: =COUNTA('Entity scope'!E8:E99) -> 92 | M8: Expected raw count 92, not unique eligible entities.
C9: Existing users total | D9: Users | E9: =SUM(Customers!F8:F16) -> 1830 | M9: Expected 1,830.
C10: Existing on-premise users | D10: Users | E10: =Assumptions!E19 -> 1260 | M10: Expected 1,260.
C11: Source rows missing new allocations | D11: Rows | E11: =COUNTBLANK('Entity scope'!H8:H99) -> 92
C12: Initial allocation gap after proposals | D12: Users | E12: =Assumptions!E14-SUM('Entity scope'!G8:H99) -> 8170 | M12: Positive gap means more named allocation is needed. Duplicate proposals require review.
C13: Missing reported support amounts | D13: Rows | E13: =COUNTBLANK(Customers!I8:I16) -> 6 | M13: Missing means unknown, not free or zero.
C14: Central recurring cost reconciliation | D14: AED | E14: ='Cost model'!K28-SUM('Cost model'!E25:I27) -> 0
C15: Benefit reconciliation | D15: AED | E15: ='Cost model'!K34-('Cost model'!K23-'Cost model'!K32) -> 0
C16: Deployed users exceed paid capacity | D16: Periods | E16: =COUNTIF('Cost model'!E12:I12,"<0") -> 0
C17: New onboarding entities total | D17: Entities | E17: =SUM('Cost model'!E13:I13) -> 40
C18: Selected driver input errors | D18: Cells | E18: =SUMPRODUCT(--ISERROR(Assumptions!E26:I26))+SUMPRODUCT(--ISERROR(Assumptions!E32:I32))+SUMPRODUCT(--ISERROR(Assumptions!E38:I38)) -> 0
C23: Review before external use
C25: Map survey respondents to entities and remove overlap with current customers.
C27: Confirm distinct eligible entities and funded user allocations for the 10,000 commitment.
C29: Confirm added-seat price lock, migration dates, contract cessations and any credits.
C31: Price additional services and establish tax, current-charge scope and missing support amounts.
C33: Confirm the ROI definition, onboarding schedule and adoption assumptions with DDA.
